WARNING 2025-10-03 03:42:24,344 log 43483 140679020135872 Forbidden: /api/products/
WARNING 2025-10-03 03:42:25,196 log 43483 140679020135872 Forbidden: /api/users/
ERROR 2025-10-03 03:45:25,142 log 43705 140405514356160 Internal Server Error: /api/products/
Traceback (most recent call last):
  File "/home/pete/DjangoDev/django_bp_start/.venv/lib/python3.13/site-packages/django/db/backends/utils.py", line 105, in _execute
    return self.cursor.execute(sql, params)
           ~~~~~~~~~~~~~~~~~~~^^^^^^^^^^^^^
  File "/home/pete/DjangoDev/django_bp_start/.venv/lib/python3.13/site-packages/psycopg/cursor.py", line 97, in execute
    raise ex.with_traceback(None)
psycopg.errors.NotNullViolation: null value in column "created_by_id" of relation "products_product" violates not-null constraint
DETAIL:  Failing row contains (9, New Product, 20.00, null).

The above exception was the direct cause of the following exception:

Traceback (most recent call last):
  File "/home/pete/DjangoDev/django_bp_start/.venv/lib/python3.13/site-packages/django/core/handlers/exception.py", line 55, in inner
    response = get_response(request)
  File "/home/pete/DjangoDev/django_bp_start/.venv/lib/python3.13/site-packages/django/core/handlers/base.py", line 197, in _get_response
    response = wrapped_callback(request, *callback_args, **callback_kwargs)
  File "/home/pete/DjangoDev/django_bp_start/.venv/lib/python3.13/site-packages/django/views/decorators/csrf.py", line 65, in _view_wrapper
    return view_func(request, *args, **kwargs)
  File "/home/pete/DjangoDev/django_bp_start/.venv/lib/python3.13/site-packages/rest_framework/viewsets.py", line 125, in view
    return self.dispatch(request, *args, **kwargs)
           ~~~~~~~~~~~~~^^^^^^^^^^^^^^^^^^^^^^^^^^
  File "/home/pete/DjangoDev/django_bp_start/.venv/lib/python3.13/site-packages/rest_framework/views.py", line 515, in dispatch
    response = self.handle_exception(exc)
  File "/home/pete/DjangoDev/django_bp_start/.venv/lib/python3.13/site-packages/rest_framework/views.py", line 475, in handle_exception
    self.raise_uncaught_exception(exc)
    ~~~~~~~~~~~~~~~~~~~~~~~~~~~~~^^^^^
  File "/home/pete/DjangoDev/django_bp_start/.venv/lib/python3.13/site-packages/rest_framework/views.py", line 486, in raise_uncaught_exception
    raise exc
  File "/home/pete/DjangoDev/django_bp_start/.venv/lib/python3.13/site-packages/rest_framework/views.py", line 512, in dispatch
    response = handler(request, *args, **kwargs)
  File "/home/pete/DjangoDev/django_bp_start/.venv/lib/python3.13/site-packages/rest_framework/mixins.py", line 19, in create
    self.perform_create(serializer)
    ~~~~~~~~~~~~~~~~~~~^^^^^^^^^^^^
  File "/home/pete/DjangoDev/django_bp_start/.venv/lib/python3.13/site-packages/rest_framework/mixins.py", line 24, in perform_create
    serializer.save()
    ~~~~~~~~~~~~~~~^^
  File "/home/pete/DjangoDev/django_bp_start/.venv/lib/python3.13/site-packages/rest_framework/serializers.py", line 210, in save
    self.instance = self.create(validated_data)
                    ~~~~~~~~~~~^^^^^^^^^^^^^^^^
  File "/home/pete/DjangoDev/django_bp_start/.venv/lib/python3.13/site-packages/rest_framework/serializers.py", line 991, in create
    instance = ModelClass._default_manager.create(**validated_data)
  File "/home/pete/DjangoDev/django_bp_start/.venv/lib/python3.13/site-packages/django/db/models/manager.py", line 87, in manager_method
    return getattr(self.get_queryset(), name)(*args, **kwargs)
           ~~~~~~~~~~~~~~~~~~~~~~~~~~~~~~~~~~^^^^^^^^^^^^^^^^^
  File "/home/pete/DjangoDev/django_bp_start/.venv/lib/python3.13/site-packages/django/db/models/query.py", line 663, in create
    obj.save(force_insert=True, using=self.db)
    ~~~~~~~~^^^^^^^^^^^^^^^^^^^^^^^^^^^^^^^^^^
  File "/home/pete/DjangoDev/django_bp_start/.venv/lib/python3.13/site-packages/django/db/models/base.py", line 902, in save
    self.save_base(
    ~~~~~~~~~~~~~~^
        using=using,
        ^^^^^^^^^^^^
    ...<2 lines>...
        update_fields=update_fields,
        ^^^^^^^^^^^^^^^^^^^^^^^^^^^^
    )
    ^
  File "/home/pete/DjangoDev/django_bp_start/.venv/lib/python3.13/site-packages/django/db/models/base.py", line 1008, in save_base
    updated = self._save_table(
        raw,
    ...<4 lines>...
        update_fields,
    )
  File "/home/pete/DjangoDev/django_bp_start/.venv/lib/python3.13/site-packages/django/db/models/base.py", line 1169, in _save_table
    results = self._do_insert(
        cls._base_manager, using, fields, returning_fields, raw
    )
  File "/home/pete/DjangoDev/django_bp_start/.venv/lib/python3.13/site-packages/django/db/models/base.py", line 1210, in _do_insert
    return manager._insert(
           ~~~~~~~~~~~~~~~^
        [self],
        ^^^^^^^
    ...<3 lines>...
        raw=raw,
        ^^^^^^^^
    )
    ^
  File "/home/pete/DjangoDev/django_bp_start/.venv/lib/python3.13/site-packages/django/db/models/manager.py", line 87, in manager_method
    return getattr(self.get_queryset(), name)(*args, **kwargs)
           ~~~~~~~~~~~~~~~~~~~~~~~~~~~~~~~~~~^^^^^^^^^^^^^^^^^
  File "/home/pete/DjangoDev/django_bp_start/.venv/lib/python3.13/site-packages/django/db/models/query.py", line 1868, in _insert
    return query.get_compiler(using=using).execute_sql(returning_fields)
           ~~~~~~~~~~~~~~~~~~~~~~~~~~~~~~~~~~~~~~~~~~~^^^^^^^^^^^^^^^^^^
  File "/home/pete/DjangoDev/django_bp_start/.venv/lib/python3.13/site-packages/django/db/models/sql/compiler.py", line 1882, in execute_sql
    cursor.execute(sql, params)
    ~~~~~~~~~~~~~~^^^^^^^^^^^^^
  File "/home/pete/DjangoDev/django_bp_start/.venv/lib/python3.13/site-packages/django/db/backends/utils.py", line 79, in execute
    return self._execute_with_wrappers(
           ~~~~~~~~~~~~~~~~~~~~~~~~~~~^
        sql, params, many=False, executor=self._execute
        ^^^^^^^^^^^^^^^^^^^^^^^^^^^^^^^^^^^^^^^^^^^^^^^
    )
    ^
  File "/home/pete/DjangoDev/django_bp_start/.venv/lib/python3.13/site-packages/django/db/backends/utils.py", line 92, in _execute_with_wrappers
    return executor(sql, params, many, context)
  File "/home/pete/DjangoDev/django_bp_start/.venv/lib/python3.13/site-packages/django/db/backends/utils.py", line 100, in _execute
    with self.db.wrap_database_errors:
         ^^^^^^^^^^^^^^^^^^^^^^^^^^^^
  File "/home/pete/DjangoDev/django_bp_start/.venv/lib/python3.13/site-packages/django/db/utils.py", line 91, in __exit__
    raise dj_exc_value.with_traceback(traceback) from exc_value
  File "/home/pete/DjangoDev/django_bp_start/.venv/lib/python3.13/site-packages/django/db/backends/utils.py", line 105, in _execute
    return self.cursor.execute(sql, params)
           ~~~~~~~~~~~~~~~~~~~^^^^^^^^^^^^^
  File "/home/pete/DjangoDev/django_bp_start/.venv/lib/python3.13/site-packages/psycopg/cursor.py", line 97, in execute
    raise ex.with_traceback(None)
django.db.utils.IntegrityError: null value in column "created_by_id" of relation "products_product" violates not-null constraint
DETAIL:  Failing row contains (9, New Product, 20.00, null).
WARNING 2025-10-03 03:45:25,292 log 43705 140405514356160 Forbidden: /api/products/
WARNING 2025-10-03 03:45:26,002 log 43705 140405514356160 Forbidden: /api/users/
ERROR 2025-10-03 03:48:05,206 log 43817 139890854262208 Internal Server Error: /api/products/
Traceback (most recent call last):
  File "/home/pete/DjangoDev/django_bp_start/.venv/lib/python3.13/site-packages/django/db/backends/utils.py", line 105, in _execute
    return self.cursor.execute(sql, params)
           ~~~~~~~~~~~~~~~~~~~^^^^^^^^^^^^^
  File "/home/pete/DjangoDev/django_bp_start/.venv/lib/python3.13/site-packages/psycopg/cursor.py", line 97, in execute
    raise ex.with_traceback(None)
psycopg.errors.NotNullViolation: null value in column "created_by_id" of relation "products_product" violates not-null constraint
DETAIL:  Failing row contains (9, New Product, 20.00, null).

The above exception was the direct cause of the following exception:

Traceback (most recent call last):
  File "/home/pete/DjangoDev/django_bp_start/.venv/lib/python3.13/site-packages/django/core/handlers/exception.py", line 55, in inner
    response = get_response(request)
  File "/home/pete/DjangoDev/django_bp_start/.venv/lib/python3.13/site-packages/django/core/handlers/base.py", line 197, in _get_response
    response = wrapped_callback(request, *callback_args, **callback_kwargs)
  File "/home/pete/DjangoDev/django_bp_start/.venv/lib/python3.13/site-packages/django/views/decorators/csrf.py", line 65, in _view_wrapper
    return view_func(request, *args, **kwargs)
  File "/home/pete/DjangoDev/django_bp_start/.venv/lib/python3.13/site-packages/rest_framework/viewsets.py", line 125, in view
    return self.dispatch(request, *args, **kwargs)
           ~~~~~~~~~~~~~^^^^^^^^^^^^^^^^^^^^^^^^^^
  File "/home/pete/DjangoDev/django_bp_start/.venv/lib/python3.13/site-packages/rest_framework/views.py", line 515, in dispatch
    response = self.handle_exception(exc)
  File "/home/pete/DjangoDev/django_bp_start/.venv/lib/python3.13/site-packages/rest_framework/views.py", line 475, in handle_exception
    self.raise_uncaught_exception(exc)
    ~~~~~~~~~~~~~~~~~~~~~~~~~~~~~^^^^^
  File "/home/pete/DjangoDev/django_bp_start/.venv/lib/python3.13/site-packages/rest_framework/views.py", line 486, in raise_uncaught_exception
    raise exc
  File "/home/pete/DjangoDev/django_bp_start/.venv/lib/python3.13/site-packages/rest_framework/views.py", line 512, in dispatch
    response = handler(request, *args, **kwargs)
  File "/home/pete/DjangoDev/django_bp_start/.venv/lib/python3.13/site-packages/rest_framework/mixins.py", line 19, in create
    self.perform_create(serializer)
    ~~~~~~~~~~~~~~~~~~~^^^^^^^^^^^^
  File "/home/pete/DjangoDev/django_bp_start/.venv/lib/python3.13/site-packages/rest_framework/mixins.py", line 24, in perform_create
    serializer.save()
    ~~~~~~~~~~~~~~~^^
  File "/home/pete/DjangoDev/django_bp_start/.venv/lib/python3.13/site-packages/rest_framework/serializers.py", line 210, in save
    self.instance = self.create(validated_data)
                    ~~~~~~~~~~~^^^^^^^^^^^^^^^^
  File "/home/pete/DjangoDev/django_bp_start/.venv/lib/python3.13/site-packages/rest_framework/serializers.py", line 991, in create
    instance = ModelClass._default_manager.create(**validated_data)
  File "/home/pete/DjangoDev/django_bp_start/.venv/lib/python3.13/site-packages/django/db/models/manager.py", line 87, in manager_method
    return getattr(self.get_queryset(), name)(*args, **kwargs)
           ~~~~~~~~~~~~~~~~~~~~~~~~~~~~~~~~~~^^^^^^^^^^^^^^^^^
  File "/home/pete/DjangoDev/django_bp_start/.venv/lib/python3.13/site-packages/django/db/models/query.py", line 663, in create
    obj.save(force_insert=True, using=self.db)
    ~~~~~~~~^^^^^^^^^^^^^^^^^^^^^^^^^^^^^^^^^^
  File "/home/pete/DjangoDev/django_bp_start/.venv/lib/python3.13/site-packages/django/db/models/base.py", line 902, in save
    self.save_base(
    ~~~~~~~~~~~~~~^
        using=using,
        ^^^^^^^^^^^^
    ...<2 lines>...
        update_fields=update_fields,
        ^^^^^^^^^^^^^^^^^^^^^^^^^^^^
    )
    ^
  File "/home/pete/DjangoDev/django_bp_start/.venv/lib/python3.13/site-packages/django/db/models/base.py", line 1008, in save_base
    updated = self._save_table(
        raw,
    ...<4 lines>...
        update_fields,
    )
  File "/home/pete/DjangoDev/django_bp_start/.venv/lib/python3.13/site-packages/django/db/models/base.py", line 1169, in _save_table
    results = self._do_insert(
        cls._base_manager, using, fields, returning_fields, raw
    )
  File "/home/pete/DjangoDev/django_bp_start/.venv/lib/python3.13/site-packages/django/db/models/base.py", line 1210, in _do_insert
    return manager._insert(
           ~~~~~~~~~~~~~~~^
        [self],
        ^^^^^^^
    ...<3 lines>...
        raw=raw,
        ^^^^^^^^
    )
    ^
  File "/home/pete/DjangoDev/django_bp_start/.venv/lib/python3.13/site-packages/django/db/models/manager.py", line 87, in manager_method
    return getattr(self.get_queryset(), name)(*args, **kwargs)
           ~~~~~~~~~~~~~~~~~~~~~~~~~~~~~~~~~~^^^^^^^^^^^^^^^^^
  File "/home/pete/DjangoDev/django_bp_start/.venv/lib/python3.13/site-packages/django/db/models/query.py", line 1868, in _insert
    return query.get_compiler(using=using).execute_sql(returning_fields)
           ~~~~~~~~~~~~~~~~~~~~~~~~~~~~~~~~~~~~~~~~~~~^^^^^^^^^^^^^^^^^^
  File "/home/pete/DjangoDev/django_bp_start/.venv/lib/python3.13/site-packages/django/db/models/sql/compiler.py", line 1882, in execute_sql
    cursor.execute(sql, params)
    ~~~~~~~~~~~~~~^^^^^^^^^^^^^
  File "/home/pete/DjangoDev/django_bp_start/.venv/lib/python3.13/site-packages/django/db/backends/utils.py", line 79, in execute
    return self._execute_with_wrappers(
           ~~~~~~~~~~~~~~~~~~~~~~~~~~~^
        sql, params, many=False, executor=self._execute
        ^^^^^^^^^^^^^^^^^^^^^^^^^^^^^^^^^^^^^^^^^^^^^^^
    )
    ^
  File "/home/pete/DjangoDev/django_bp_start/.venv/lib/python3.13/site-packages/django/db/backends/utils.py", line 92, in _execute_with_wrappers
    return executor(sql, params, many, context)
  File "/home/pete/DjangoDev/django_bp_start/.venv/lib/python3.13/site-packages/django/db/backends/utils.py", line 100, in _execute
    with self.db.wrap_database_errors:
         ^^^^^^^^^^^^^^^^^^^^^^^^^^^^
  File "/home/pete/DjangoDev/django_bp_start/.venv/lib/python3.13/site-packages/django/db/utils.py", line 91, in __exit__
    raise dj_exc_value.with_traceback(traceback) from exc_value
  File "/home/pete/DjangoDev/django_bp_start/.venv/lib/python3.13/site-packages/django/db/backends/utils.py", line 105, in _execute
    return self.cursor.execute(sql, params)
           ~~~~~~~~~~~~~~~~~~~^^^^^^^^^^^^^
  File "/home/pete/DjangoDev/django_bp_start/.venv/lib/python3.13/site-packages/psycopg/cursor.py", line 97, in execute
    raise ex.with_traceback(None)
django.db.utils.IntegrityError: null value in column "created_by_id" of relation "products_product" violates not-null constraint
DETAIL:  Failing row contains (9, New Product, 20.00, null).
WARNING 2025-10-03 03:48:05,356 log 43817 139890854262208 Forbidden: /api/products/
WARNING 2025-10-03 03:48:06,064 log 43817 139890854262208 Forbidden: /api/users/
WARNING 2025-10-03 03:50:42,268 log 43957 139903703127488 Forbidden: /api/products/
WARNING 2025-10-03 03:50:51,245 log 43989 140374505080256 Forbidden: /api/products/
WARNING 2025-10-03 03:50:51,958 log 43989 140374505080256 Forbidden: /api/users/
WARNING 2025-10-03 03:52:07,273 log 44058 139847067448768 Forbidden: /api/products/
WARNING 2025-10-03 03:52:07,987 log 44058 139847067448768 Forbidden: /api/users/
INFO 2025-10-03 04:32:21,136 autoreload 47483 139650056619456 Watching for file changes with StatReloader
ERROR 2025-10-03 04:32:24,498 log 47483 139649956701888 Internal Server Error: /
Traceback (most recent call last):
  File "/home/pete/DjangoDev/django_bp_start/.venv/lib/python3.13/site-packages/django/core/handlers/exception.py", line 55, in inner
    response = get_response(request)
  File "/home/pete/DjangoDev/django_bp_start/config/middleware.py", line 9, in __call__
    if request.user.is_authenticated and request.user.tenant:
                                         ^^^^^^^^^^^^^^^^^^^
  File "/home/pete/DjangoDev/django_bp_start/.venv/lib/python3.13/site-packages/django/utils/functional.py", line 253, in inner
    return func(_wrapped, *args)
AttributeError: 'CustomUser' object has no attribute 'tenant'
ERROR 2025-10-03 04:32:24,500 basehttp 47483 139649956701888 "GET / HTTP/1.1" 500 72500
ERROR 2025-10-03 04:32:24,567 log 47483 139649956701888 Internal Server Error: /favicon.ico
Traceback (most recent call last):
  File "/home/pete/DjangoDev/django_bp_start/.venv/lib/python3.13/site-packages/django/core/handlers/exception.py", line 55, in inner
    response = get_response(request)
  File "/home/pete/DjangoDev/django_bp_start/config/middleware.py", line 9, in __call__
    if request.user.is_authenticated and request.user.tenant:
                                         ^^^^^^^^^^^^^^^^^^^
  File "/home/pete/DjangoDev/django_bp_start/.venv/lib/python3.13/site-packages/django/utils/functional.py", line 253, in inner
    return func(_wrapped, *args)
AttributeError: 'CustomUser' object has no attribute 'tenant'
ERROR 2025-10-03 04:32:39,542 log 47483 139649956701888 Internal Server Error: /admin/
Traceback (most recent call last):
  File "/home/pete/DjangoDev/django_bp_start/.venv/lib/python3.13/site-packages/django/core/handlers/exception.py", line 55, in inner
    response = get_response(request)
  File "/home/pete/DjangoDev/django_bp_start/config/middleware.py", line 9, in __call__
    if request.user.is_authenticated and request.user.tenant:
                                         ^^^^^^^^^^^^^^^^^^^
  File "/home/pete/DjangoDev/django_bp_start/.venv/lib/python3.13/site-packages/django/utils/functional.py", line 253, in inner
    return func(_wrapped, *args)
AttributeError: 'CustomUser' object has no attribute 'tenant'
ERROR 2025-10-03 04:32:39,542 basehttp 47483 139649956701888 "GET /admin/ HTTP/1.1" 500 72664
INFO 2025-10-03 04:34:46,711 autoreload 47483 139650056619456 /home/pete/DjangoDev/django_bp_start/apps/users/models.py changed, reloading.
INFO 2025-10-03 04:34:47,018 autoreload 47794 140098532881856 Watching for file changes with StatReloader
INFO 2025-10-03 04:34:51,182 autoreload 47794 140098532881856 /home/pete/DjangoDev/django_bp_start/apps/users/models.py changed, reloading.
INFO 2025-10-03 04:34:51,485 autoreload 47805 139754402837952 Watching for file changes with StatReloader
INFO 2025-10-03 04:35:41,655 autoreload 47921 140277438313920 Watching for file changes with StatReloader
ERROR 2025-10-03 04:35:54,848 log 47921 140277338597056 Internal Server Error: /admin/
Traceback (most recent call last):
  File "/home/pete/DjangoDev/django_bp_start/.venv/lib/python3.13/site-packages/django/db/backends/utils.py", line 105, in _execute
    return self.cursor.execute(sql, params)
           ~~~~~~~~~~~~~~~~~~~^^^^^^^^^^^^^
  File "/home/pete/DjangoDev/django_bp_start/.venv/lib/python3.13/site-packages/psycopg/cursor.py", line 97, in execute
    raise ex.with_traceback(None)
psycopg.errors.UndefinedColumn: column users_customuser.tenant_id does not exist
LINE 1: ...r"."is_active", "users_customuser"."date_joined", "users_cus...
                                                             ^

The above exception was the direct cause of the following exception:

Traceback (most recent call last):
  File "/home/pete/DjangoDev/django_bp_start/.venv/lib/python3.13/site-packages/django/core/handlers/exception.py", line 55, in inner
    response = get_response(request)
  File "/home/pete/DjangoDev/django_bp_start/config/middleware.py", line 9, in __call__
    if request.user.is_authenticated and request.user.tenant:
       ^^^^^^^^^^^^^^^^^^^^^^^^^^^^^
  File "/home/pete/DjangoDev/django_bp_start/.venv/lib/python3.13/site-packages/django/utils/functional.py", line 251, in inner
    self._setup()
    ~~~~~~~~~~~^^
  File "/home/pete/DjangoDev/django_bp_start/.venv/lib/python3.13/site-packages/django/utils/functional.py", line 404, in _setup
    self._wrapped = self._setupfunc()
                    ~~~~~~~~~~~~~~~^^
  File "/home/pete/DjangoDev/django_bp_start/.venv/lib/python3.13/site-packages/django/contrib/auth/middleware.py", line 40, in <lambda>
    request.user = SimpleLazyObject(lambda: get_user(request))
                                            ~~~~~~~~^^^^^^^^^
  File "/home/pete/DjangoDev/django_bp_start/.venv/lib/python3.13/site-packages/django/contrib/auth/middleware.py", line 20, in get_user
    request._cached_user = auth.get_user(request)
                           ~~~~~~~~~~~~~^^^^^^^^^
  File "/home/pete/DjangoDev/django_bp_start/.venv/lib/python3.13/site-packages/django/contrib/auth/__init__.py", line 311, in get_user
    user = backend.get_user(user_id)
  File "/home/pete/DjangoDev/django_bp_start/.venv/lib/python3.13/site-packages/django/contrib/auth/backends.py", line 232, in get_user
    user = UserModel._default_manager.get(pk=user_id)
  File "/home/pete/DjangoDev/django_bp_start/.venv/lib/python3.13/site-packages/django/db/models/manager.py", line 87, in manager_method
    return getattr(self.get_queryset(), name)(*args, **kwargs)
           ~~~~~~~~~~~~~~~~~~~~~~~~~~~~~~~~~~^^^^^^^^^^^^^^^^^
  File "/home/pete/DjangoDev/django_bp_start/.venv/lib/python3.13/site-packages/django/db/models/query.py", line 629, in get
    num = len(clone)
  File "/home/pete/DjangoDev/django_bp_start/.venv/lib/python3.13/site-packages/django/db/models/query.py", line 366, in __len__
    self._fetch_all()
    ~~~~~~~~~~~~~~~^^
  File "/home/pete/DjangoDev/django_bp_start/.venv/lib/python3.13/site-packages/django/db/models/query.py", line 1949, in _fetch_all
    self._result_cache = list(self._iterable_class(self))
                         ~~~~^^^^^^^^^^^^^^^^^^^^^^^^^^^^
  File "/home/pete/DjangoDev/django_bp_start/.venv/lib/python3.13/site-packages/django/db/models/query.py", line 91, in __iter__
    results = compiler.execute_sql(
        chunked_fetch=self.chunked_fetch, chunk_size=self.chunk_size
    )
  File "/home/pete/DjangoDev/django_bp_start/.venv/lib/python3.13/site-packages/django/db/models/sql/compiler.py", line 1623, in execute_sql
    cursor.execute(sql, params)
    ~~~~~~~~~~~~~~^^^^^^^^^^^^^
  File "/home/pete/DjangoDev/django_bp_start/.venv/lib/python3.13/site-packages/django/db/backends/utils.py", line 122, in execute
    return super().execute(sql, params)
           ~~~~~~~~~~~~~~~^^^^^^^^^^^^^
  File "/home/pete/DjangoDev/django_bp_start/.venv/lib/python3.13/site-packages/django/db/backends/utils.py", line 79, in execute
    return self._execute_with_wrappers(
           ~~~~~~~~~~~~~~~~~~~~~~~~~~~^
        sql, params, many=False, executor=self._execute
        ^^^^^^^^^^^^^^^^^^^^^^^^^^^^^^^^^^^^^^^^^^^^^^^
    )
    ^
  File "/home/pete/DjangoDev/django_bp_start/.venv/lib/python3.13/site-packages/django/db/backends/utils.py", line 92, in _execute_with_wrappers
    return executor(sql, params, many, context)
  File "/home/pete/DjangoDev/django_bp_start/.venv/lib/python3.13/site-packages/django/db/backends/utils.py", line 100, in _execute
    with self.db.wrap_database_errors:
         ^^^^^^^^^^^^^^^^^^^^^^^^^^^^
  File "/home/pete/DjangoDev/django_bp_start/.venv/lib/python3.13/site-packages/django/db/utils.py", line 91, in __exit__
    raise dj_exc_value.with_traceback(traceback) from exc_value
  File "/home/pete/DjangoDev/django_bp_start/.venv/lib/python3.13/site-packages/django/db/backends/utils.py", line 105, in _execute
    return self.cursor.execute(sql, params)
           ~~~~~~~~~~~~~~~~~~~^^^^^^^^^^^^^
  File "/home/pete/DjangoDev/django_bp_start/.venv/lib/python3.13/site-packages/psycopg/cursor.py", line 97, in execute
    raise ex.with_traceback(None)
django.db.utils.ProgrammingError: column users_customuser.tenant_id does not exist
LINE 1: ...r"."is_active", "users_customuser"."date_joined", "users_cus...
                                                             ^
ERROR 2025-10-03 04:35:54,852 basehttp 47921 140277338597056 "GET /admin/ HTTP/1.1" 500 172082
ERROR 2025-10-03 04:35:54,946 log 47921 140277338597056 Internal Server Error: /favicon.ico
Traceback (most recent call last):
  File "/home/pete/DjangoDev/django_bp_start/.venv/lib/python3.13/site-packages/django/db/backends/utils.py", line 105, in _execute
    return self.cursor.execute(sql, params)
           ~~~~~~~~~~~~~~~~~~~^^^^^^^^^^^^^
  File "/home/pete/DjangoDev/django_bp_start/.venv/lib/python3.13/site-packages/psycopg/cursor.py", line 97, in execute
    raise ex.with_traceback(None)
psycopg.errors.UndefinedColumn: column users_customuser.tenant_id does not exist
LINE 1: ...r"."is_active", "users_customuser"."date_joined", "users_cus...
                                                             ^

The above exception was the direct cause of the following exception:

Traceback (most recent call last):
  File "/home/pete/DjangoDev/django_bp_start/.venv/lib/python3.13/site-packages/django/core/handlers/exception.py", line 55, in inner
    response = get_response(request)
  File "/home/pete/DjangoDev/django_bp_start/config/middleware.py", line 9, in __call__
    if request.user.is_authenticated and request.user.tenant:
       ^^^^^^^^^^^^^^^^^^^^^^^^^^^^^
  File "/home/pete/DjangoDev/django_bp_start/.venv/lib/python3.13/site-packages/django/utils/functional.py", line 251, in inner
    self._setup()
    ~~~~~~~~~~~^^
  File "/home/pete/DjangoDev/django_bp_start/.venv/lib/python3.13/site-packages/django/utils/functional.py", line 404, in _setup
    self._wrapped = self._setupfunc()
                    ~~~~~~~~~~~~~~~^^
  File "/home/pete/DjangoDev/django_bp_start/.venv/lib/python3.13/site-packages/django/contrib/auth/middleware.py", line 40, in <lambda>
    request.user = SimpleLazyObject(lambda: get_user(request))
                                            ~~~~~~~~^^^^^^^^^
  File "/home/pete/DjangoDev/django_bp_start/.venv/lib/python3.13/site-packages/django/contrib/auth/middleware.py", line 20, in get_user
    request._cached_user = auth.get_user(request)
                           ~~~~~~~~~~~~~^^^^^^^^^
  File "/home/pete/DjangoDev/django_bp_start/.venv/lib/python3.13/site-packages/django/contrib/auth/__init__.py", line 311, in get_user
    user = backend.get_user(user_id)
  File "/home/pete/DjangoDev/django_bp_start/.venv/lib/python3.13/site-packages/django/contrib/auth/backends.py", line 232, in get_user
    user = UserModel._default_manager.get(pk=user_id)
  File "/home/pete/DjangoDev/django_bp_start/.venv/lib/python3.13/site-packages/django/db/models/manager.py", line 87, in manager_method
    return getattr(self.get_queryset(), name)(*args, **kwargs)
           ~~~~~~~~~~~~~~~~~~~~~~~~~~~~~~~~~~^^^^^^^^^^^^^^^^^
  File "/home/pete/DjangoDev/django_bp_start/.venv/lib/python3.13/site-packages/django/db/models/query.py", line 629, in get
    num = len(clone)
  File "/home/pete/DjangoDev/django_bp_start/.venv/lib/python3.13/site-packages/django/db/models/query.py", line 366, in __len__
    self._fetch_all()
    ~~~~~~~~~~~~~~~^^
  File "/home/pete/DjangoDev/django_bp_start/.venv/lib/python3.13/site-packages/django/db/models/query.py", line 1949, in _fetch_all
    self._result_cache = list(self._iterable_class(self))
                         ~~~~^^^^^^^^^^^^^^^^^^^^^^^^^^^^
  File "/home/pete/DjangoDev/django_bp_start/.venv/lib/python3.13/site-packages/django/db/models/query.py", line 91, in __iter__
    results = compiler.execute_sql(
        chunked_fetch=self.chunked_fetch, chunk_size=self.chunk_size
    )
  File "/home/pete/DjangoDev/django_bp_start/.venv/lib/python3.13/site-packages/django/db/models/sql/compiler.py", line 1623, in execute_sql
    cursor.execute(sql, params)
    ~~~~~~~~~~~~~~^^^^^^^^^^^^^
  File "/home/pete/DjangoDev/django_bp_start/.venv/lib/python3.13/site-packages/django/db/backends/utils.py", line 122, in execute
    return super().execute(sql, params)
           ~~~~~~~~~~~~~~~^^^^^^^^^^^^^
  File "/home/pete/DjangoDev/django_bp_start/.venv/lib/python3.13/site-packages/django/db/backends/utils.py", line 79, in execute
    return self._execute_with_wrappers(
           ~~~~~~~~~~~~~~~~~~~~~~~~~~~^
        sql, params, many=False, executor=self._execute
        ^^^^^^^^^^^^^^^^^^^^^^^^^^^^^^^^^^^^^^^^^^^^^^^
    )
    ^
  File "/home/pete/DjangoDev/django_bp_start/.venv/lib/python3.13/site-packages/django/db/backends/utils.py", line 92, in _execute_with_wrappers
    return executor(sql, params, many, context)
  File "/home/pete/DjangoDev/django_bp_start/.venv/lib/python3.13/site-packages/django/db/backends/utils.py", line 100, in _execute
    with self.db.wrap_database_errors:
         ^^^^^^^^^^^^^^^^^^^^^^^^^^^^
  File "/home/pete/DjangoDev/django_bp_start/.venv/lib/python3.13/site-packages/django/db/utils.py", line 91, in __exit__
    raise dj_exc_value.with_traceback(traceback) from exc_value
  File "/home/pete/DjangoDev/django_bp_start/.venv/lib/python3.13/site-packages/django/db/backends/utils.py", line 105, in _execute
    return self.cursor.execute(sql, params)
           ~~~~~~~~~~~~~~~~~~~^^^^^^^^^^^^^
  File "/home/pete/DjangoDev/django_bp_start/.venv/lib/python3.13/site-packages/psycopg/cursor.py", line 97, in execute
    raise ex.with_traceback(None)
django.db.utils.ProgrammingError: column users_customuser.tenant_id does not exist
LINE 1: ...r"."is_active", "users_customuser"."date_joined", "users_cus...
                                                             ^
INFO 2025-10-03 04:38:01,595 autoreload 48086 140341890454976 Watching for file changes with StatReloader
ERROR 2025-10-03 04:38:05,622 log 48086 140341790369472 Internal Server Error: /admin/
Traceback (most recent call last):
  File "/home/pete/DjangoDev/django_bp_start/.venv/lib/python3.13/site-packages/django/db/backends/utils.py", line 103, in _execute
    return self.cursor.execute(sql)
           ~~~~~~~~~~~~~~~~~~~^^^^^
  File "/home/pete/DjangoDev/django_bp_start/.venv/lib/python3.13/site-packages/psycopg/cursor.py", line 97, in execute
    raise ex.with_traceback(None)
psycopg.errors.SyntaxError: syntax error at or near "NULL"
LINE 1: SET app.tenant_id = NULL
                            ^

The above exception was the direct cause of the following exception:

Traceback (most recent call last):
  File "/home/pete/DjangoDev/django_bp_start/.venv/lib/python3.13/site-packages/django/core/handlers/exception.py", line 55, in inner
    response = get_response(request)
  File "/home/pete/DjangoDev/django_bp_start/config/middleware.py", line 17, in __call__
    cursor.execute("SET app.tenant_id = NULL")
    ~~~~~~~~~~~~~~^^^^^^^^^^^^^^^^^^^^^^^^^^^^
  File "/home/pete/DjangoDev/django_bp_start/.venv/lib/python3.13/site-packages/django/db/backends/utils.py", line 122, in execute
    return super().execute(sql, params)
           ~~~~~~~~~~~~~~~^^^^^^^^^^^^^
  File "/home/pete/DjangoDev/django_bp_start/.venv/lib/python3.13/site-packages/django/db/backends/utils.py", line 79, in execute
    return self._execute_with_wrappers(
           ~~~~~~~~~~~~~~~~~~~~~~~~~~~^
        sql, params, many=False, executor=self._execute
        ^^^^^^^^^^^^^^^^^^^^^^^^^^^^^^^^^^^^^^^^^^^^^^^
    )
    ^
  File "/home/pete/DjangoDev/django_bp_start/.venv/lib/python3.13/site-packages/django/db/backends/utils.py", line 92, in _execute_with_wrappers
    return executor(sql, params, many, context)
  File "/home/pete/DjangoDev/django_bp_start/.venv/lib/python3.13/site-packages/django/db/backends/utils.py", line 100, in _execute
    with self.db.wrap_database_errors:
         ^^^^^^^^^^^^^^^^^^^^^^^^^^^^
  File "/home/pete/DjangoDev/django_bp_start/.venv/lib/python3.13/site-packages/django/db/utils.py", line 91, in __exit__
    raise dj_exc_value.with_traceback(traceback) from exc_value
  File "/home/pete/DjangoDev/django_bp_start/.venv/lib/python3.13/site-packages/django/db/backends/utils.py", line 103, in _execute
    return self.cursor.execute(sql)
           ~~~~~~~~~~~~~~~~~~~^^^^^
  File "/home/pete/DjangoDev/django_bp_start/.venv/lib/python3.13/site-packages/psycopg/cursor.py", line 97, in execute
    raise ex.with_traceback(None)
django.db.utils.ProgrammingError: syntax error at or near "NULL"
LINE 1: SET app.tenant_id = NULL
                            ^
ERROR 2025-10-03 04:38:05,624 basehttp 48086 140341790369472 "GET /admin/ HTTP/1.1" 500 111594
ERROR 2025-10-03 04:38:05,686 log 48086 140341790369472 Internal Server Error: /favicon.ico
Traceback (most recent call last):
  File "/home/pete/DjangoDev/django_bp_start/.venv/lib/python3.13/site-packages/django/db/backends/utils.py", line 103, in _execute
    return self.cursor.execute(sql)
           ~~~~~~~~~~~~~~~~~~~^^^^^
  File "/home/pete/DjangoDev/django_bp_start/.venv/lib/python3.13/site-packages/psycopg/cursor.py", line 97, in execute
    raise ex.with_traceback(None)
psycopg.errors.SyntaxError: syntax error at or near "NULL"
LINE 1: SET app.tenant_id = NULL
                            ^

The above exception was the direct cause of the following exception:

Traceback (most recent call last):
  File "/home/pete/DjangoDev/django_bp_start/.venv/lib/python3.13/site-packages/django/core/handlers/exception.py", line 55, in inner
    response = get_response(request)
  File "/home/pete/DjangoDev/django_bp_start/config/middleware.py", line 17, in __call__
    cursor.execute("SET app.tenant_id = NULL")
    ~~~~~~~~~~~~~~^^^^^^^^^^^^^^^^^^^^^^^^^^^^
  File "/home/pete/DjangoDev/django_bp_start/.venv/lib/python3.13/site-packages/django/db/backends/utils.py", line 122, in execute
    return super().execute(sql, params)
           ~~~~~~~~~~~~~~~^^^^^^^^^^^^^
  File "/home/pete/DjangoDev/django_bp_start/.venv/lib/python3.13/site-packages/django/db/backends/utils.py", line 79, in execute
    return self._execute_with_wrappers(
           ~~~~~~~~~~~~~~~~~~~~~~~~~~~^
        sql, params, many=False, executor=self._execute
        ^^^^^^^^^^^^^^^^^^^^^^^^^^^^^^^^^^^^^^^^^^^^^^^
    )
    ^
  File "/home/pete/DjangoDev/django_bp_start/.venv/lib/python3.13/site-packages/django/db/backends/utils.py", line 92, in _execute_with_wrappers
    return executor(sql, params, many, context)
  File "/home/pete/DjangoDev/django_bp_start/.venv/lib/python3.13/site-packages/django/db/backends/utils.py", line 100, in _execute
    with self.db.wrap_database_errors:
         ^^^^^^^^^^^^^^^^^^^^^^^^^^^^
  File "/home/pete/DjangoDev/django_bp_start/.venv/lib/python3.13/site-packages/django/db/utils.py", line 91, in __exit__
    raise dj_exc_value.with_traceback(traceback) from exc_value
  File "/home/pete/DjangoDev/django_bp_start/.venv/lib/python3.13/site-packages/django/db/backends/utils.py", line 103, in _execute
    return self.cursor.execute(sql)
           ~~~~~~~~~~~~~~~~~~~^^^^^
  File "/home/pete/DjangoDev/django_bp_start/.venv/lib/python3.13/site-packages/psycopg/cursor.py", line 97, in execute
    raise ex.with_traceback(None)
django.db.utils.ProgrammingError: syntax error at or near "NULL"
LINE 1: SET app.tenant_id = NULL
                            ^
INFO 2025-10-03 04:41:38,286 autoreload 48301 140318851425728 Watching for file changes with StatReloader
ERROR 2025-10-03 04:41:48,855 log 48301 140318751057600 Internal Server Error: /favicon.ico
Traceback (most recent call last):
  File "/home/pete/DjangoDev/django_bp_start/.venv/lib/python3.13/site-packages/django/db/backends/utils.py", line 103, in _execute
    return self.cursor.execute(sql)
           ~~~~~~~~~~~~~~~~~~~^^^^^
  File "/home/pete/DjangoDev/django_bp_start/.venv/lib/python3.13/site-packages/psycopg/cursor.py", line 97, in execute
    raise ex.with_traceback(None)
psycopg.errors.SyntaxError: syntax error at or near "NULL"
LINE 1: SET app.tenant_id = NULL
                            ^

The above exception was the direct cause of the following exception:

Traceback (most recent call last):
  File "/home/pete/DjangoDev/django_bp_start/.venv/lib/python3.13/site-packages/django/core/handlers/exception.py", line 55, in inner
    response = get_response(request)
  File "/home/pete/DjangoDev/django_bp_start/config/middleware.py", line 17, in __call__
    cursor.execute("SET app.tenant_id = NULL")
    ~~~~~~~~~~~~~~^^^^^^^^^^^^^^^^^^^^^^^^^^^^
  File "/home/pete/DjangoDev/django_bp_start/.venv/lib/python3.13/site-packages/django/db/backends/utils.py", line 122, in execute
    return super().execute(sql, params)
           ~~~~~~~~~~~~~~~^^^^^^^^^^^^^
  File "/home/pete/DjangoDev/django_bp_start/.venv/lib/python3.13/site-packages/django/db/backends/utils.py", line 79, in execute
    return self._execute_with_wrappers(
           ~~~~~~~~~~~~~~~~~~~~~~~~~~~^
        sql, params, many=False, executor=self._execute
        ^^^^^^^^^^^^^^^^^^^^^^^^^^^^^^^^^^^^^^^^^^^^^^^
    )
    ^
  File "/home/pete/DjangoDev/django_bp_start/.venv/lib/python3.13/site-packages/django/db/backends/utils.py", line 92, in _execute_with_wrappers
    return executor(sql, params, many, context)
  File "/home/pete/DjangoDev/django_bp_start/.venv/lib/python3.13/site-packages/django/db/backends/utils.py", line 100, in _execute
    with self.db.wrap_database_errors:
         ^^^^^^^^^^^^^^^^^^^^^^^^^^^^
  File "/home/pete/DjangoDev/django_bp_start/.venv/lib/python3.13/site-packages/django/db/utils.py", line 91, in __exit__
    raise dj_exc_value.with_traceback(traceback) from exc_value
  File "/home/pete/DjangoDev/django_bp_start/.venv/lib/python3.13/site-packages/django/db/backends/utils.py", line 103, in _execute
    return self.cursor.execute(sql)
           ~~~~~~~~~~~~~~~~~~~^^^^^
  File "/home/pete/DjangoDev/django_bp_start/.venv/lib/python3.13/site-packages/psycopg/cursor.py", line 97, in execute
    raise ex.with_traceback(None)
django.db.utils.ProgrammingError: syntax error at or near "NULL"
LINE 1: SET app.tenant_id = NULL
                            ^
ERROR 2025-10-03 04:41:55,896 log 48301 140318751057600 Internal Server Error: /admin/
Traceback (most recent call last):
  File "/home/pete/DjangoDev/django_bp_start/.venv/lib/python3.13/site-packages/django/db/backends/utils.py", line 103, in _execute
    return self.cursor.execute(sql)
           ~~~~~~~~~~~~~~~~~~~^^^^^
  File "/home/pete/DjangoDev/django_bp_start/.venv/lib/python3.13/site-packages/psycopg/cursor.py", line 97, in execute
    raise ex.with_traceback(None)
psycopg.errors.SyntaxError: syntax error at or near "NULL"
LINE 1: SET app.tenant_id = NULL
                            ^

The above exception was the direct cause of the following exception:

Traceback (most recent call last):
  File "/home/pete/DjangoDev/django_bp_start/.venv/lib/python3.13/site-packages/django/core/handlers/exception.py", line 55, in inner
    response = get_response(request)
  File "/home/pete/DjangoDev/django_bp_start/config/middleware.py", line 17, in __call__
    cursor.execute("SET app.tenant_id = NULL")
    ~~~~~~~~~~~~~~^^^^^^^^^^^^^^^^^^^^^^^^^^^^
  File "/home/pete/DjangoDev/django_bp_start/.venv/lib/python3.13/site-packages/django/db/backends/utils.py", line 122, in execute
    return super().execute(sql, params)
           ~~~~~~~~~~~~~~~^^^^^^^^^^^^^
  File "/home/pete/DjangoDev/django_bp_start/.venv/lib/python3.13/site-packages/django/db/backends/utils.py", line 79, in execute
    return self._execute_with_wrappers(
           ~~~~~~~~~~~~~~~~~~~~~~~~~~~^
        sql, params, many=False, executor=self._execute
        ^^^^^^^^^^^^^^^^^^^^^^^^^^^^^^^^^^^^^^^^^^^^^^^
    )
    ^
  File "/home/pete/DjangoDev/django_bp_start/.venv/lib/python3.13/site-packages/django/db/backends/utils.py", line 92, in _execute_with_wrappers
    return executor(sql, params, many, context)
  File "/home/pete/DjangoDev/django_bp_start/.venv/lib/python3.13/site-packages/django/db/backends/utils.py", line 100, in _execute
    with self.db.wrap_database_errors:
         ^^^^^^^^^^^^^^^^^^^^^^^^^^^^
  File "/home/pete/DjangoDev/django_bp_start/.venv/lib/python3.13/site-packages/django/db/utils.py", line 91, in __exit__
    raise dj_exc_value.with_traceback(traceback) from exc_value
  File "/home/pete/DjangoDev/django_bp_start/.venv/lib/python3.13/site-packages/django/db/backends/utils.py", line 103, in _execute
    return self.cursor.execute(sql)
           ~~~~~~~~~~~~~~~~~~~^^^^^
  File "/home/pete/DjangoDev/django_bp_start/.venv/lib/python3.13/site-packages/psycopg/cursor.py", line 97, in execute
    raise ex.with_traceback(None)
django.db.utils.ProgrammingError: syntax error at or near "NULL"
LINE 1: SET app.tenant_id = NULL
                            ^
ERROR 2025-10-03 04:41:55,897 basehttp 48301 140318751057600 "GET /admin/ HTTP/1.1" 500 111594
INFO 2025-10-03 04:42:18,952 autoreload 48384 140416605918656 Watching for file changes with StatReloader
ERROR 2025-10-03 04:42:24,093 log 48384 140416506652352 Internal Server Error: /admin/
Traceback (most recent call last):
  File "/home/pete/DjangoDev/django_bp_start/.venv/lib/python3.13/site-packages/django/db/backends/utils.py", line 103, in _execute
    return self.cursor.execute(sql)
           ~~~~~~~~~~~~~~~~~~~^^^^^
  File "/home/pete/DjangoDev/django_bp_start/.venv/lib/python3.13/site-packages/psycopg/cursor.py", line 97, in execute
    raise ex.with_traceback(None)
psycopg.errors.SyntaxError: syntax error at or near "NULL"
LINE 1: SET app.tenant_id = NULL
                            ^

The above exception was the direct cause of the following exception:

Traceback (most recent call last):
  File "/home/pete/DjangoDev/django_bp_start/.venv/lib/python3.13/site-packages/django/core/handlers/exception.py", line 55, in inner
    response = get_response(request)
  File "/home/pete/DjangoDev/django_bp_start/config/middleware.py", line 17, in __call__
    cursor.execute("SET app.tenant_id = NULL")
    ~~~~~~~~~~~~~~^^^^^^^^^^^^^^^^^^^^^^^^^^^^
  File "/home/pete/DjangoDev/django_bp_start/.venv/lib/python3.13/site-packages/django/db/backends/utils.py", line 122, in execute
    return super().execute(sql, params)
           ~~~~~~~~~~~~~~~^^^^^^^^^^^^^
  File "/home/pete/DjangoDev/django_bp_start/.venv/lib/python3.13/site-packages/django/db/backends/utils.py", line 79, in execute
    return self._execute_with_wrappers(
           ~~~~~~~~~~~~~~~~~~~~~~~~~~~^
        sql, params, many=False, executor=self._execute
        ^^^^^^^^^^^^^^^^^^^^^^^^^^^^^^^^^^^^^^^^^^^^^^^
    )
    ^
  File "/home/pete/DjangoDev/django_bp_start/.venv/lib/python3.13/site-packages/django/db/backends/utils.py", line 92, in _execute_with_wrappers
    return executor(sql, params, many, context)
  File "/home/pete/DjangoDev/django_bp_start/.venv/lib/python3.13/site-packages/django/db/backends/utils.py", line 100, in _execute
    with self.db.wrap_database_errors:
         ^^^^^^^^^^^^^^^^^^^^^^^^^^^^
  File "/home/pete/DjangoDev/django_bp_start/.venv/lib/python3.13/site-packages/django/db/utils.py", line 91, in __exit__
    raise dj_exc_value.with_traceback(traceback) from exc_value
  File "/home/pete/DjangoDev/django_bp_start/.venv/lib/python3.13/site-packages/django/db/backends/utils.py", line 103, in _execute
    return self.cursor.execute(sql)
           ~~~~~~~~~~~~~~~~~~~^^^^^
  File "/home/pete/DjangoDev/django_bp_start/.venv/lib/python3.13/site-packages/psycopg/cursor.py", line 97, in execute
    raise ex.with_traceback(None)
django.db.utils.ProgrammingError: syntax error at or near "NULL"
LINE 1: SET app.tenant_id = NULL
                            ^
ERROR 2025-10-03 04:42:24,095 basehttp 48384 140416506652352 "GET /admin/ HTTP/1.1" 500 111594
ERROR 2025-10-03 04:42:35,249 log 48384 140416506652352 Internal Server Error: /
Traceback (most recent call last):
  File "/home/pete/DjangoDev/django_bp_start/.venv/lib/python3.13/site-packages/django/db/backends/utils.py", line 103, in _execute
    return self.cursor.execute(sql)
           ~~~~~~~~~~~~~~~~~~~^^^^^
  File "/home/pete/DjangoDev/django_bp_start/.venv/lib/python3.13/site-packages/psycopg/cursor.py", line 97, in execute
    raise ex.with_traceback(None)
psycopg.errors.SyntaxError: syntax error at or near "NULL"
LINE 1: SET app.tenant_id = NULL
                            ^

The above exception was the direct cause of the following exception:

Traceback (most recent call last):
  File "/home/pete/DjangoDev/django_bp_start/.venv/lib/python3.13/site-packages/django/core/handlers/exception.py", line 55, in inner
    response = get_response(request)
  File "/home/pete/DjangoDev/django_bp_start/config/middleware.py", line 17, in __call__
    cursor.execute("SET app.tenant_id = NULL")
    ~~~~~~~~~~~~~~^^^^^^^^^^^^^^^^^^^^^^^^^^^^
  File "/home/pete/DjangoDev/django_bp_start/.venv/lib/python3.13/site-packages/django/db/backends/utils.py", line 122, in execute
    return super().execute(sql, params)
           ~~~~~~~~~~~~~~~^^^^^^^^^^^^^
  File "/home/pete/DjangoDev/django_bp_start/.venv/lib/python3.13/site-packages/django/db/backends/utils.py", line 79, in execute
    return self._execute_with_wrappers(
           ~~~~~~~~~~~~~~~~~~~~~~~~~~~^
        sql, params, many=False, executor=self._execute
        ^^^^^^^^^^^^^^^^^^^^^^^^^^^^^^^^^^^^^^^^^^^^^^^
    )
    ^
  File "/home/pete/DjangoDev/django_bp_start/.venv/lib/python3.13/site-packages/django/db/backends/utils.py", line 92, in _execute_with_wrappers
    return executor(sql, params, many, context)
  File "/home/pete/DjangoDev/django_bp_start/.venv/lib/python3.13/site-packages/django/db/backends/utils.py", line 100, in _execute
    with self.db.wrap_database_errors:
         ^^^^^^^^^^^^^^^^^^^^^^^^^^^^
  File "/home/pete/DjangoDev/django_bp_start/.venv/lib/python3.13/site-packages/django/db/utils.py", line 91, in __exit__
    raise dj_exc_value.with_traceback(traceback) from exc_value
  File "/home/pete/DjangoDev/django_bp_start/.venv/lib/python3.13/site-packages/django/db/backends/utils.py", line 103, in _execute
    return self.cursor.execute(sql)
           ~~~~~~~~~~~~~~~~~~~^^^^^
  File "/home/pete/DjangoDev/django_bp_start/.venv/lib/python3.13/site-packages/psycopg/cursor.py", line 97, in execute
    raise ex.with_traceback(None)
django.db.utils.ProgrammingError: syntax error at or near "NULL"
LINE 1: SET app.tenant_id = NULL
                            ^
ERROR 2025-10-03 04:42:35,250 basehttp 48384 140416506652352 "GET / HTTP/1.1" 500 111307
INFO 2025-10-03 04:42:43,773 autoreload 48431 139821851350464 Watching for file changes with StatReloader
INFO 2025-10-03 04:43:55,591 autoreload 48431 139821851350464 /home/pete/DjangoDev/django_bp_start/apps/products/models.py changed, reloading.
INFO 2025-10-03 04:43:55,906 autoreload 48509 140033728771520 Watching for file changes with StatReloader
INFO 2025-10-03 04:44:35,418 autoreload 48509 140033728771520 /home/pete/DjangoDev/django_bp_start/apps/products/models.py changed, reloading.
INFO 2025-10-03 04:44:35,727 autoreload 48541 140665965594048 Watching for file changes with StatReloader
INFO 2025-10-03 04:50:19,133 autoreload 48867 139643450828224 Watching for file changes with StatReloader
ERROR 2025-10-03 04:50:28,616 log 48867 139643278325440 Internal Server Error: /admin/
Traceback (most recent call last):
  File "/home/pete/DjangoDev/django_bp_start/.venv/lib/python3.13/site-packages/django/db/backends/utils.py", line 103, in _execute
    return self.cursor.execute(sql)
           ~~~~~~~~~~~~~~~~~~~^^^^^
  File "/home/pete/DjangoDev/django_bp_start/.venv/lib/python3.13/site-packages/psycopg/cursor.py", line 97, in execute
    raise ex.with_traceback(None)
psycopg.errors.SyntaxError: syntax error at or near "NULL"
LINE 1: SET app.tenant_id = NULL
                            ^

The above exception was the direct cause of the following exception:

Traceback (most recent call last):
  File "/home/pete/DjangoDev/django_bp_start/.venv/lib/python3.13/site-packages/django/core/handlers/exception.py", line 55, in inner
    response = get_response(request)
  File "/home/pete/DjangoDev/django_bp_start/config/middleware.py", line 17, in __call__
    cursor.execute("SET app.tenant_id = NULL")
    ~~~~~~~~~~~~~~^^^^^^^^^^^^^^^^^^^^^^^^^^^^
  File "/home/pete/DjangoDev/django_bp_start/.venv/lib/python3.13/site-packages/django/db/backends/utils.py", line 122, in execute
    return super().execute(sql, params)
           ~~~~~~~~~~~~~~~^^^^^^^^^^^^^
  File "/home/pete/DjangoDev/django_bp_start/.venv/lib/python3.13/site-packages/django/db/backends/utils.py", line 79, in execute
    return self._execute_with_wrappers(
           ~~~~~~~~~~~~~~~~~~~~~~~~~~~^
        sql, params, many=False, executor=self._execute
        ^^^^^^^^^^^^^^^^^^^^^^^^^^^^^^^^^^^^^^^^^^^^^^^
    )
    ^
  File "/home/pete/DjangoDev/django_bp_start/.venv/lib/python3.13/site-packages/django/db/backends/utils.py", line 92, in _execute_with_wrappers
    return executor(sql, params, many, context)
  File "/home/pete/DjangoDev/django_bp_start/.venv/lib/python3.13/site-packages/django/db/backends/utils.py", line 100, in _execute
    with self.db.wrap_database_errors:
         ^^^^^^^^^^^^^^^^^^^^^^^^^^^^
  File "/home/pete/DjangoDev/django_bp_start/.venv/lib/python3.13/site-packages/django/db/utils.py", line 91, in __exit__
    raise dj_exc_value.with_traceback(traceback) from exc_value
  File "/home/pete/DjangoDev/django_bp_start/.venv/lib/python3.13/site-packages/django/db/backends/utils.py", line 103, in _execute
    return self.cursor.execute(sql)
           ~~~~~~~~~~~~~~~~~~~^^^^^
  File "/home/pete/DjangoDev/django_bp_start/.venv/lib/python3.13/site-packages/psycopg/cursor.py", line 97, in execute
    raise ex.with_traceback(None)
django.db.utils.ProgrammingError: syntax error at or near "NULL"
LINE 1: SET app.tenant_id = NULL
                            ^
ERROR 2025-10-03 04:50:28,618 basehttp 48867 139643278325440 "GET /admin/ HTTP/1.1" 500 111594
ERROR 2025-10-03 04:50:28,699 log 48867 139643278325440 Internal Server Error: /favicon.ico
Traceback (most recent call last):
  File "/home/pete/DjangoDev/django_bp_start/.venv/lib/python3.13/site-packages/django/db/backends/utils.py", line 103, in _execute
    return self.cursor.execute(sql)
           ~~~~~~~~~~~~~~~~~~~^^^^^
  File "/home/pete/DjangoDev/django_bp_start/.venv/lib/python3.13/site-packages/psycopg/cursor.py", line 97, in execute
    raise ex.with_traceback(None)
psycopg.errors.SyntaxError: syntax error at or near "NULL"
LINE 1: SET app.tenant_id = NULL
                            ^

The above exception was the direct cause of the following exception:

Traceback (most recent call last):
  File "/home/pete/DjangoDev/django_bp_start/.venv/lib/python3.13/site-packages/django/core/handlers/exception.py", line 55, in inner
    response = get_response(request)
  File "/home/pete/DjangoDev/django_bp_start/config/middleware.py", line 17, in __call__
    cursor.execute("SET app.tenant_id = NULL")
    ~~~~~~~~~~~~~~^^^^^^^^^^^^^^^^^^^^^^^^^^^^
  File "/home/pete/DjangoDev/django_bp_start/.venv/lib/python3.13/site-packages/django/db/backends/utils.py", line 122, in execute
    return super().execute(sql, params)
           ~~~~~~~~~~~~~~~^^^^^^^^^^^^^
  File "/home/pete/DjangoDev/django_bp_start/.venv/lib/python3.13/site-packages/django/db/backends/utils.py", line 79, in execute
    return self._execute_with_wrappers(
           ~~~~~~~~~~~~~~~~~~~~~~~~~~~^
        sql, params, many=False, executor=self._execute
        ^^^^^^^^^^^^^^^^^^^^^^^^^^^^^^^^^^^^^^^^^^^^^^^
    )
    ^
  File "/home/pete/DjangoDev/django_bp_start/.venv/lib/python3.13/site-packages/django/db/backends/utils.py", line 92, in _execute_with_wrappers
    return executor(sql, params, many, context)
  File "/home/pete/DjangoDev/django_bp_start/.venv/lib/python3.13/site-packages/django/db/backends/utils.py", line 100, in _execute
    with self.db.wrap_database_errors:
         ^^^^^^^^^^^^^^^^^^^^^^^^^^^^
  File "/home/pete/DjangoDev/django_bp_start/.venv/lib/python3.13/site-packages/django/db/utils.py", line 91, in __exit__
    raise dj_exc_value.with_traceback(traceback) from exc_value
  File "/home/pete/DjangoDev/django_bp_start/.venv/lib/python3.13/site-packages/django/db/backends/utils.py", line 103, in _execute
    return self.cursor.execute(sql)
           ~~~~~~~~~~~~~~~~~~~^^^^^
  File "/home/pete/DjangoDev/django_bp_start/.venv/lib/python3.13/site-packages/psycopg/cursor.py", line 97, in execute
    raise ex.with_traceback(None)
django.db.utils.ProgrammingError: syntax error at or near "NULL"
LINE 1: SET app.tenant_id = NULL
                            ^
INFO 2025-10-03 05:14:46,758 autoreload 49764 140223464293824 Watching for file changes with StatReloader
ERROR 2025-10-03 05:14:53,530 log 49764 140223364196032 Internal Server Error: /admin/
Traceback (most recent call last):
  File "/home/pete/DjangoDev/django_bp_start/.venv/lib/python3.13/site-packages/django/db/backends/utils.py", line 103, in _execute
    return self.cursor.execute(sql)
           ~~~~~~~~~~~~~~~~~~~^^^^^
  File "/home/pete/DjangoDev/django_bp_start/.venv/lib/python3.13/site-packages/psycopg/cursor.py", line 97, in execute
    raise ex.with_traceback(None)
psycopg.errors.SyntaxError: syntax error at or near "NULL"
LINE 1: SET app.tenant_id = NULL
                            ^

The above exception was the direct cause of the following exception:

Traceback (most recent call last):
  File "/home/pete/DjangoDev/django_bp_start/.venv/lib/python3.13/site-packages/django/core/handlers/exception.py", line 55, in inner
    response = get_response(request)
  File "/home/pete/DjangoDev/django_bp_start/config/middleware.py", line 17, in __call__
    cursor.execute("SET app.tenant_id = NULL")
    ~~~~~~~~~~~~~~^^^^^^^^^^^^^^^^^^^^^^^^^^^^
  File "/home/pete/DjangoDev/django_bp_start/.venv/lib/python3.13/site-packages/django/db/backends/utils.py", line 122, in execute
    return super().execute(sql, params)
           ~~~~~~~~~~~~~~~^^^^^^^^^^^^^
  File "/home/pete/DjangoDev/django_bp_start/.venv/lib/python3.13/site-packages/django/db/backends/utils.py", line 79, in execute
    return self._execute_with_wrappers(
           ~~~~~~~~~~~~~~~~~~~~~~~~~~~^
        sql, params, many=False, executor=self._execute
        ^^^^^^^^^^^^^^^^^^^^^^^^^^^^^^^^^^^^^^^^^^^^^^^
    )
    ^
  File "/home/pete/DjangoDev/django_bp_start/.venv/lib/python3.13/site-packages/django/db/backends/utils.py", line 92, in _execute_with_wrappers
    return executor(sql, params, many, context)
  File "/home/pete/DjangoDev/django_bp_start/.venv/lib/python3.13/site-packages/django/db/backends/utils.py", line 100, in _execute
    with self.db.wrap_database_errors:
         ^^^^^^^^^^^^^^^^^^^^^^^^^^^^
  File "/home/pete/DjangoDev/django_bp_start/.venv/lib/python3.13/site-packages/django/db/utils.py", line 91, in __exit__
    raise dj_exc_value.with_traceback(traceback) from exc_value
  File "/home/pete/DjangoDev/django_bp_start/.venv/lib/python3.13/site-packages/django/db/backends/utils.py", line 103, in _execute
    return self.cursor.execute(sql)
           ~~~~~~~~~~~~~~~~~~~^^^^^
  File "/home/pete/DjangoDev/django_bp_start/.venv/lib/python3.13/site-packages/psycopg/cursor.py", line 97, in execute
    raise ex.with_traceback(None)
django.db.utils.ProgrammingError: syntax error at or near "NULL"
LINE 1: SET app.tenant_id = NULL
                            ^
ERROR 2025-10-03 05:14:53,532 basehttp 49764 140223364196032 "GET /admin/ HTTP/1.1" 500 111516
ERROR 2025-10-03 05:14:53,597 log 49764 140223364196032 Internal Server Error: /favicon.ico
Traceback (most recent call last):
  File "/home/pete/DjangoDev/django_bp_start/.venv/lib/python3.13/site-packages/django/db/backends/utils.py", line 103, in _execute
    return self.cursor.execute(sql)
           ~~~~~~~~~~~~~~~~~~~^^^^^
  File "/home/pete/DjangoDev/django_bp_start/.venv/lib/python3.13/site-packages/psycopg/cursor.py", line 97, in execute
    raise ex.with_traceback(None)
psycopg.errors.SyntaxError: syntax error at or near "NULL"
LINE 1: SET app.tenant_id = NULL
                            ^

The above exception was the direct cause of the following exception:

Traceback (most recent call last):
  File "/home/pete/DjangoDev/django_bp_start/.venv/lib/python3.13/site-packages/django/core/handlers/exception.py", line 55, in inner
    response = get_response(request)
  File "/home/pete/DjangoDev/django_bp_start/config/middleware.py", line 17, in __call__
    cursor.execute("SET app.tenant_id = NULL")
    ~~~~~~~~~~~~~~^^^^^^^^^^^^^^^^^^^^^^^^^^^^
  File "/home/pete/DjangoDev/django_bp_start/.venv/lib/python3.13/site-packages/django/db/backends/utils.py", line 122, in execute
    return super().execute(sql, params)
           ~~~~~~~~~~~~~~~^^^^^^^^^^^^^
  File "/home/pete/DjangoDev/django_bp_start/.venv/lib/python3.13/site-packages/django/db/backends/utils.py", line 79, in execute
    return self._execute_with_wrappers(
           ~~~~~~~~~~~~~~~~~~~~~~~~~~~^
        sql, params, many=False, executor=self._execute
        ^^^^^^^^^^^^^^^^^^^^^^^^^^^^^^^^^^^^^^^^^^^^^^^
    )
    ^
  File "/home/pete/DjangoDev/django_bp_start/.venv/lib/python3.13/site-packages/django/db/backends/utils.py", line 92, in _execute_with_wrappers
    return executor(sql, params, many, context)
  File "/home/pete/DjangoDev/django_bp_start/.venv/lib/python3.13/site-packages/django/db/backends/utils.py", line 100, in _execute
    with self.db.wrap_database_errors:
         ^^^^^^^^^^^^^^^^^^^^^^^^^^^^
  File "/home/pete/DjangoDev/django_bp_start/.venv/lib/python3.13/site-packages/django/db/utils.py", line 91, in __exit__
    raise dj_exc_value.with_traceback(traceback) from exc_value
  File "/home/pete/DjangoDev/django_bp_start/.venv/lib/python3.13/site-packages/django/db/backends/utils.py", line 103, in _execute
    return self.cursor.execute(sql)
           ~~~~~~~~~~~~~~~~~~~^^^^^
  File "/home/pete/DjangoDev/django_bp_start/.venv/lib/python3.13/site-packages/psycopg/cursor.py", line 97, in execute
    raise ex.with_traceback(None)
django.db.utils.ProgrammingError: syntax error at or near "NULL"
LINE 1: SET app.tenant_id = NULL
                            ^
ERROR 2025-10-03 05:14:53,599 basehttp 49764 140223364196032 "GET /favicon.ico HTTP/1.1" 500 111142
INFO 2025-10-03 05:22:13,120 autoreload 50102 139692146374080 Watching for file changes with StatReloader
ERROR 2025-10-03 05:22:21,680 log 50102 139692046542528 Internal Server Error: /api/products/
Traceback (most recent call last):
  File "/home/pete/DjangoDev/django_bp_start/.venv/lib/python3.13/site-packages/django/db/backends/utils.py", line 103, in _execute
    return self.cursor.execute(sql)
           ~~~~~~~~~~~~~~~~~~~^^^^^
  File "/home/pete/DjangoDev/django_bp_start/.venv/lib/python3.13/site-packages/psycopg/cursor.py", line 97, in execute
    raise ex.with_traceback(None)
psycopg.errors.SyntaxError: syntax error at or near "NULL"
LINE 1: SET app.tenant_id = NULL
                            ^

The above exception was the direct cause of the following exception:

Traceback (most recent call last):
  File "/home/pete/DjangoDev/django_bp_start/.venv/lib/python3.13/site-packages/django/core/handlers/exception.py", line 55, in inner
    response = get_response(request)
  File "/home/pete/DjangoDev/django_bp_start/config/middleware.py", line 17, in __call__
    cursor.execute("SET app.tenant_id = NULL")
    ~~~~~~~~~~~~~~^^^^^^^^^^^^^^^^^^^^^^^^^^^^
  File "/home/pete/DjangoDev/django_bp_start/.venv/lib/python3.13/site-packages/django/db/backends/utils.py", line 122, in execute
    return super().execute(sql, params)
           ~~~~~~~~~~~~~~~^^^^^^^^^^^^^
  File "/home/pete/DjangoDev/django_bp_start/.venv/lib/python3.13/site-packages/django/db/backends/utils.py", line 79, in execute
    return self._execute_with_wrappers(
           ~~~~~~~~~~~~~~~~~~~~~~~~~~~^
        sql, params, many=False, executor=self._execute
        ^^^^^^^^^^^^^^^^^^^^^^^^^^^^^^^^^^^^^^^^^^^^^^^
    )
    ^
  File "/home/pete/DjangoDev/django_bp_start/.venv/lib/python3.13/site-packages/django/db/backends/utils.py", line 92, in _execute_with_wrappers
    return executor(sql, params, many, context)
  File "/home/pete/DjangoDev/django_bp_start/.venv/lib/python3.13/site-packages/django/db/backends/utils.py", line 100, in _execute
    with self.db.wrap_database_errors:
         ^^^^^^^^^^^^^^^^^^^^^^^^^^^^
  File "/home/pete/DjangoDev/django_bp_start/.venv/lib/python3.13/site-packages/django/db/utils.py", line 91, in __exit__
    raise dj_exc_value.with_traceback(traceback) from exc_value
  File "/home/pete/DjangoDev/django_bp_start/.venv/lib/python3.13/site-packages/django/db/backends/utils.py", line 103, in _execute
    return self.cursor.execute(sql)
           ~~~~~~~~~~~~~~~~~~~^^^^^
  File "/home/pete/DjangoDev/django_bp_start/.venv/lib/python3.13/site-packages/psycopg/cursor.py", line 97, in execute
    raise ex.with_traceback(None)
django.db.utils.ProgrammingError: syntax error at or near "NULL"
LINE 1: SET app.tenant_id = NULL
                            ^
ERROR 2025-10-03 05:22:21,682 basehttp 50102 139692046542528 "GET /api/products/ HTTP/1.1" 500 111502
ERROR 2025-10-03 05:22:21,742 log 50102 139692046542528 Internal Server Error: /favicon.ico
Traceback (most recent call last):
  File "/home/pete/DjangoDev/django_bp_start/.venv/lib/python3.13/site-packages/django/db/backends/utils.py", line 103, in _execute
    return self.cursor.execute(sql)
           ~~~~~~~~~~~~~~~~~~~^^^^^
  File "/home/pete/DjangoDev/django_bp_start/.venv/lib/python3.13/site-packages/psycopg/cursor.py", line 97, in execute
    raise ex.with_traceback(None)
psycopg.errors.SyntaxError: syntax error at or near "NULL"
LINE 1: SET app.tenant_id = NULL
                            ^

The above exception was the direct cause of the following exception:

Traceback (most recent call last):
  File "/home/pete/DjangoDev/django_bp_start/.venv/lib/python3.13/site-packages/django/core/handlers/exception.py", line 55, in inner
    response = get_response(request)
  File "/home/pete/DjangoDev/django_bp_start/config/middleware.py", line 17, in __call__
    cursor.execute("SET app.tenant_id = NULL")
    ~~~~~~~~~~~~~~^^^^^^^^^^^^^^^^^^^^^^^^^^^^
  File "/home/pete/DjangoDev/django_bp_start/.venv/lib/python3.13/site-packages/django/db/backends/utils.py", line 122, in execute
    return super().execute(sql, params)
           ~~~~~~~~~~~~~~~^^^^^^^^^^^^^
  File "/home/pete/DjangoDev/django_bp_start/.venv/lib/python3.13/site-packages/django/db/backends/utils.py", line 79, in execute
    return self._execute_with_wrappers(
           ~~~~~~~~~~~~~~~~~~~~~~~~~~~^
        sql, params, many=False, executor=self._execute
        ^^^^^^^^^^^^^^^^^^^^^^^^^^^^^^^^^^^^^^^^^^^^^^^
    )
    ^
  File "/home/pete/DjangoDev/django_bp_start/.venv/lib/python3.13/site-packages/django/db/backends/utils.py", line 92, in _execute_with_wrappers
    return executor(sql, params, many, context)
  File "/home/pete/DjangoDev/django_bp_start/.venv/lib/python3.13/site-packages/django/db/backends/utils.py", line 100, in _execute
    with self.db.wrap_database_errors:
         ^^^^^^^^^^^^^^^^^^^^^^^^^^^^
  File "/home/pete/DjangoDev/django_bp_start/.venv/lib/python3.13/site-packages/django/db/utils.py", line 91, in __exit__
    raise dj_exc_value.with_traceback(traceback) from exc_value
  File "/home/pete/DjangoDev/django_bp_start/.venv/lib/python3.13/site-packages/django/db/backends/utils.py", line 103, in _execute
    return self.cursor.execute(sql)
           ~~~~~~~~~~~~~~~~~~~^^^^^
  File "/home/pete/DjangoDev/django_bp_start/.venv/lib/python3.13/site-packages/psycopg/cursor.py", line 97, in execute
    raise ex.with_traceback(None)
django.db.utils.ProgrammingError: syntax error at or near "NULL"
LINE 1: SET app.tenant_id = NULL
                            ^
ERROR 2025-10-03 05:22:47,780 log 50102 139692037101248 Internal Server Error: /api/products/
Traceback (most recent call last):
  File "/home/pete/DjangoDev/django_bp_start/.venv/lib/python3.13/site-packages/django/db/backends/utils.py", line 103, in _execute
    return self.cursor.execute(sql)
           ~~~~~~~~~~~~~~~~~~~^^^^^
  File "/home/pete/DjangoDev/django_bp_start/.venv/lib/python3.13/site-packages/psycopg/cursor.py", line 97, in execute
    raise ex.with_traceback(None)
psycopg.errors.SyntaxError: syntax error at or near "NULL"
LINE 1: SET app.tenant_id = NULL
                            ^

The above exception was the direct cause of the following exception:

Traceback (most recent call last):
  File "/home/pete/DjangoDev/django_bp_start/.venv/lib/python3.13/site-packages/django/core/handlers/exception.py", line 55, in inner
    response = get_response(request)
  File "/home/pete/DjangoDev/django_bp_start/config/middleware.py", line 17, in __call__
    cursor.execute("SET app.tenant_id = NULL")
    ~~~~~~~~~~~~~~^^^^^^^^^^^^^^^^^^^^^^^^^^^^
  File "/home/pete/DjangoDev/django_bp_start/.venv/lib/python3.13/site-packages/django/db/backends/utils.py", line 122, in execute
    return super().execute(sql, params)
           ~~~~~~~~~~~~~~~^^^^^^^^^^^^^
  File "/home/pete/DjangoDev/django_bp_start/.venv/lib/python3.13/site-packages/django/db/backends/utils.py", line 79, in execute
    return self._execute_with_wrappers(
           ~~~~~~~~~~~~~~~~~~~~~~~~~~~^
        sql, params, many=False, executor=self._execute
        ^^^^^^^^^^^^^^^^^^^^^^^^^^^^^^^^^^^^^^^^^^^^^^^
    )
    ^
  File "/home/pete/DjangoDev/django_bp_start/.venv/lib/python3.13/site-packages/django/db/backends/utils.py", line 92, in _execute_with_wrappers
    return executor(sql, params, many, context)
  File "/home/pete/DjangoDev/django_bp_start/.venv/lib/python3.13/site-packages/django/db/backends/utils.py", line 100, in _execute
    with self.db.wrap_database_errors:
         ^^^^^^^^^^^^^^^^^^^^^^^^^^^^
  File "/home/pete/DjangoDev/django_bp_start/.venv/lib/python3.13/site-packages/django/db/utils.py", line 91, in __exit__
    raise dj_exc_value.with_traceback(traceback) from exc_value
  File "/home/pete/DjangoDev/django_bp_start/.venv/lib/python3.13/site-packages/django/db/backends/utils.py", line 103, in _execute
    return self.cursor.execute(sql)
           ~~~~~~~~~~~~~~~~~~~^^^^^
  File "/home/pete/DjangoDev/django_bp_start/.venv/lib/python3.13/site-packages/psycopg/cursor.py", line 97, in execute
    raise ex.with_traceback(None)
django.db.utils.ProgrammingError: syntax error at or near "NULL"
LINE 1: SET app.tenant_id = NULL
                            ^
ERROR 2025-10-03 05:22:47,782 basehttp 50102 139692037101248 "GET /api/products/ HTTP/1.1" 500 111767
ERROR 2025-10-03 05:22:47,840 log 50102 139692037101248 Internal Server Error: /favicon.ico
Traceback (most recent call last):
  File "/home/pete/DjangoDev/django_bp_start/.venv/lib/python3.13/site-packages/django/db/backends/utils.py", line 103, in _execute
    return self.cursor.execute(sql)
           ~~~~~~~~~~~~~~~~~~~^^^^^
  File "/home/pete/DjangoDev/django_bp_start/.venv/lib/python3.13/site-packages/psycopg/cursor.py", line 97, in execute
    raise ex.with_traceback(None)
psycopg.errors.SyntaxError: syntax error at or near "NULL"
LINE 1: SET app.tenant_id = NULL
                            ^

The above exception was the direct cause of the following exception:

Traceback (most recent call last):
  File "/home/pete/DjangoDev/django_bp_start/.venv/lib/python3.13/site-packages/django/core/handlers/exception.py", line 55, in inner
    response = get_response(request)
  File "/home/pete/DjangoDev/django_bp_start/config/middleware.py", line 17, in __call__
    cursor.execute("SET app.tenant_id = NULL")
    ~~~~~~~~~~~~~~^^^^^^^^^^^^^^^^^^^^^^^^^^^^
  File "/home/pete/DjangoDev/django_bp_start/.venv/lib/python3.13/site-packages/django/db/backends/utils.py", line 122, in execute
    return super().execute(sql, params)
           ~~~~~~~~~~~~~~~^^^^^^^^^^^^^
  File "/home/pete/DjangoDev/django_bp_start/.venv/lib/python3.13/site-packages/django/db/backends/utils.py", line 79, in execute
    return self._execute_with_wrappers(
           ~~~~~~~~~~~~~~~~~~~~~~~~~~~^
        sql, params, many=False, executor=self._execute
        ^^^^^^^^^^^^^^^^^^^^^^^^^^^^^^^^^^^^^^^^^^^^^^^
    )
    ^
  File "/home/pete/DjangoDev/django_bp_start/.venv/lib/python3.13/site-packages/django/db/backends/utils.py", line 92, in _execute_with_wrappers
    return executor(sql, params, many, context)
  File "/home/pete/DjangoDev/django_bp_start/.venv/lib/python3.13/site-packages/django/db/backends/utils.py", line 100, in _execute
    with self.db.wrap_database_errors:
         ^^^^^^^^^^^^^^^^^^^^^^^^^^^^
  File "/home/pete/DjangoDev/django_bp_start/.venv/lib/python3.13/site-packages/django/db/utils.py", line 91, in __exit__
    raise dj_exc_value.with_traceback(traceback) from exc_value
  File "/home/pete/DjangoDev/django_bp_start/.venv/lib/python3.13/site-packages/django/db/backends/utils.py", line 103, in _execute
    return self.cursor.execute(sql)
           ~~~~~~~~~~~~~~~~~~~^^^^^
  File "/home/pete/DjangoDev/django_bp_start/.venv/lib/python3.13/site-packages/psycopg/cursor.py", line 97, in execute
    raise ex.with_traceback(None)
django.db.utils.ProgrammingError: syntax error at or near "NULL"
LINE 1: SET app.tenant_id = NULL
                            ^
ERROR 2025-10-03 05:22:47,842 basehttp 50102 139692037101248 "GET /favicon.ico HTTP/1.1" 500 111414
ERROR 2025-10-03 05:22:49,064 log 50102 139692028708544 Internal Server Error: /api/products/
Traceback (most recent call last):
  File "/home/pete/DjangoDev/django_bp_start/.venv/lib/python3.13/site-packages/django/db/backends/utils.py", line 103, in _execute
    return self.cursor.execute(sql)
           ~~~~~~~~~~~~~~~~~~~^^^^^
  File "/home/pete/DjangoDev/django_bp_start/.venv/lib/python3.13/site-packages/psycopg/cursor.py", line 97, in execute
    raise ex.with_traceback(None)
psycopg.errors.SyntaxError: syntax error at or near "NULL"
LINE 1: SET app.tenant_id = NULL
                            ^

The above exception was the direct cause of the following exception:

Traceback (most recent call last):
  File "/home/pete/DjangoDev/django_bp_start/.venv/lib/python3.13/site-packages/django/core/handlers/exception.py", line 55, in inner
    response = get_response(request)
  File "/home/pete/DjangoDev/django_bp_start/config/middleware.py", line 17, in __call__
    cursor.execute("SET app.tenant_id = NULL")
    ~~~~~~~~~~~~~~^^^^^^^^^^^^^^^^^^^^^^^^^^^^
  File "/home/pete/DjangoDev/django_bp_start/.venv/lib/python3.13/site-packages/django/db/backends/utils.py", line 122, in execute
    return super().execute(sql, params)
           ~~~~~~~~~~~~~~~^^^^^^^^^^^^^
  File "/home/pete/DjangoDev/django_bp_start/.venv/lib/python3.13/site-packages/django/db/backends/utils.py", line 79, in execute
    return self._execute_with_wrappers(
           ~~~~~~~~~~~~~~~~~~~~~~~~~~~^
        sql, params, many=False, executor=self._execute
        ^^^^^^^^^^^^^^^^^^^^^^^^^^^^^^^^^^^^^^^^^^^^^^^
    )
    ^
  File "/home/pete/DjangoDev/django_bp_start/.venv/lib/python3.13/site-packages/django/db/backends/utils.py", line 92, in _execute_with_wrappers
    return executor(sql, params, many, context)
  File "/home/pete/DjangoDev/django_bp_start/.venv/lib/python3.13/site-packages/django/db/backends/utils.py", line 100, in _execute
    with self.db.wrap_database_errors:
         ^^^^^^^^^^^^^^^^^^^^^^^^^^^^
  File "/home/pete/DjangoDev/django_bp_start/.venv/lib/python3.13/site-packages/django/db/utils.py", line 91, in __exit__
    raise dj_exc_value.with_traceback(traceback) from exc_value
  File "/home/pete/DjangoDev/django_bp_start/.venv/lib/python3.13/site-packages/django/db/backends/utils.py", line 103, in _execute
    return self.cursor.execute(sql)
           ~~~~~~~~~~~~~~~~~~~^^^^^
  File "/home/pete/DjangoDev/django_bp_start/.venv/lib/python3.13/site-packages/psycopg/cursor.py", line 97, in execute
    raise ex.with_traceback(None)
django.db.utils.ProgrammingError: syntax error at or near "NULL"
LINE 1: SET app.tenant_id = NULL
                            ^
ERROR 2025-10-03 05:22:49,065 basehttp 50102 139692028708544 "GET /api/products/ HTTP/1.1" 500 111767
ERROR 2025-10-03 05:22:49,124 log 50102 139692028708544 Internal Server Error: /favicon.ico
Traceback (most recent call last):
  File "/home/pete/DjangoDev/django_bp_start/.venv/lib/python3.13/site-packages/django/db/backends/utils.py", line 103, in _execute
    return self.cursor.execute(sql)
           ~~~~~~~~~~~~~~~~~~~^^^^^
  File "/home/pete/DjangoDev/django_bp_start/.venv/lib/python3.13/site-packages/psycopg/cursor.py", line 97, in execute
    raise ex.with_traceback(None)
psycopg.errors.SyntaxError: syntax error at or near "NULL"
LINE 1: SET app.tenant_id = NULL
                            ^

The above exception was the direct cause of the following exception:

Traceback (most recent call last):
  File "/home/pete/DjangoDev/django_bp_start/.venv/lib/python3.13/site-packages/django/core/handlers/exception.py", line 55, in inner
    response = get_response(request)
  File "/home/pete/DjangoDev/django_bp_start/config/middleware.py", line 17, in __call__
    cursor.execute("SET app.tenant_id = NULL")
    ~~~~~~~~~~~~~~^^^^^^^^^^^^^^^^^^^^^^^^^^^^
  File "/home/pete/DjangoDev/django_bp_start/.venv/lib/python3.13/site-packages/django/db/backends/utils.py", line 122, in execute
    return super().execute(sql, params)
           ~~~~~~~~~~~~~~~^^^^^^^^^^^^^
  File "/home/pete/DjangoDev/django_bp_start/.venv/lib/python3.13/site-packages/django/db/backends/utils.py", line 79, in execute
    return self._execute_with_wrappers(
           ~~~~~~~~~~~~~~~~~~~~~~~~~~~^
        sql, params, many=False, executor=self._execute
        ^^^^^^^^^^^^^^^^^^^^^^^^^^^^^^^^^^^^^^^^^^^^^^^
    )
    ^
  File "/home/pete/DjangoDev/django_bp_start/.venv/lib/python3.13/site-packages/django/db/backends/utils.py", line 92, in _execute_with_wrappers
    return executor(sql, params, many, context)
  File "/home/pete/DjangoDev/django_bp_start/.venv/lib/python3.13/site-packages/django/db/backends/utils.py", line 100, in _execute
    with self.db.wrap_database_errors:
         ^^^^^^^^^^^^^^^^^^^^^^^^^^^^
  File "/home/pete/DjangoDev/django_bp_start/.venv/lib/python3.13/site-packages/django/db/utils.py", line 91, in __exit__
    raise dj_exc_value.with_traceback(traceback) from exc_value
  File "/home/pete/DjangoDev/django_bp_start/.venv/lib/python3.13/site-packages/django/db/backends/utils.py", line 103, in _execute
    return self.cursor.execute(sql)
           ~~~~~~~~~~~~~~~~~~~^^^^^
  File "/home/pete/DjangoDev/django_bp_start/.venv/lib/python3.13/site-packages/psycopg/cursor.py", line 97, in execute
    raise ex.with_traceback(None)
django.db.utils.ProgrammingError: syntax error at or near "NULL"
LINE 1: SET app.tenant_id = NULL
                            ^
ERROR 2025-10-03 05:22:49,126 basehttp 50102 139692028708544 "GET /favicon.ico HTTP/1.1" 500 111414
INFO 2025-10-03 05:26:34,348 autoreload 50398 139689558889920 Watching for file changes with StatReloader
ERROR 2025-10-03 05:26:44,433 log 50398 139689458656960 Internal Server Error: /
Traceback (most recent call last):
  File "/home/pete/DjangoDev/django_bp_start/.venv/lib/python3.13/site-packages/django/db/backends/utils.py", line 103, in _execute
    return self.cursor.execute(sql)
           ~~~~~~~~~~~~~~~~~~~^^^^^
  File "/home/pete/DjangoDev/django_bp_start/.venv/lib/python3.13/site-packages/psycopg/cursor.py", line 97, in execute
    raise ex.with_traceback(None)
psycopg.errors.SyntaxError: syntax error at or near "NULL"
LINE 1: SET app.tenant_id = NULL
                            ^

The above exception was the direct cause of the following exception:

Traceback (most recent call last):
  File "/home/pete/DjangoDev/django_bp_start/.venv/lib/python3.13/site-packages/django/core/handlers/exception.py", line 55, in inner
    response = get_response(request)
  File "/home/pete/DjangoDev/django_bp_start/config/middleware.py", line 17, in __call__
    cursor.execute("SET app.tenant_id = NULL")
    ~~~~~~~~~~~~~~^^^^^^^^^^^^^^^^^^^^^^^^^^^^
  File "/home/pete/DjangoDev/django_bp_start/.venv/lib/python3.13/site-packages/django/db/backends/utils.py", line 122, in execute
    return super().execute(sql, params)
           ~~~~~~~~~~~~~~~^^^^^^^^^^^^^
  File "/home/pete/DjangoDev/django_bp_start/.venv/lib/python3.13/site-packages/django/db/backends/utils.py", line 79, in execute
    return self._execute_with_wrappers(
           ~~~~~~~~~~~~~~~~~~~~~~~~~~~^
        sql, params, many=False, executor=self._execute
        ^^^^^^^^^^^^^^^^^^^^^^^^^^^^^^^^^^^^^^^^^^^^^^^
    )
    ^
  File "/home/pete/DjangoDev/django_bp_start/.venv/lib/python3.13/site-packages/django/db/backends/utils.py", line 92, in _execute_with_wrappers
    return executor(sql, params, many, context)
  File "/home/pete/DjangoDev/django_bp_start/.venv/lib/python3.13/site-packages/django/db/backends/utils.py", line 100, in _execute
    with self.db.wrap_database_errors:
         ^^^^^^^^^^^^^^^^^^^^^^^^^^^^
  File "/home/pete/DjangoDev/django_bp_start/.venv/lib/python3.13/site-packages/django/db/utils.py", line 91, in __exit__
    raise dj_exc_value.with_traceback(traceback) from exc_value
  File "/home/pete/DjangoDev/django_bp_start/.venv/lib/python3.13/site-packages/django/db/backends/utils.py", line 103, in _execute
    return self.cursor.execute(sql)
           ~~~~~~~~~~~~~~~~~~~^^^^^
  File "/home/pete/DjangoDev/django_bp_start/.venv/lib/python3.13/site-packages/psycopg/cursor.py", line 97, in execute
    raise ex.with_traceback(None)
django.db.utils.ProgrammingError: syntax error at or near "NULL"
LINE 1: SET app.tenant_id = NULL
                            ^
ERROR 2025-10-03 05:26:44,434 basehttp 50398 139689458656960 "GET / HTTP/1.1" 500 111159
ERROR 2025-10-03 05:26:44,532 log 50398 139689458656960 Internal Server Error: /favicon.ico
Traceback (most recent call last):
  File "/home/pete/DjangoDev/django_bp_start/.venv/lib/python3.13/site-packages/django/db/backends/utils.py", line 103, in _execute
    return self.cursor.execute(sql)
           ~~~~~~~~~~~~~~~~~~~^^^^^
  File "/home/pete/DjangoDev/django_bp_start/.venv/lib/python3.13/site-packages/psycopg/cursor.py", line 97, in execute
    raise ex.with_traceback(None)
psycopg.errors.SyntaxError: syntax error at or near "NULL"
LINE 1: SET app.tenant_id = NULL
                            ^

The above exception was the direct cause of the following exception:

Traceback (most recent call last):
  File "/home/pete/DjangoDev/django_bp_start/.venv/lib/python3.13/site-packages/django/core/handlers/exception.py", line 55, in inner
    response = get_response(request)
  File "/home/pete/DjangoDev/django_bp_start/config/middleware.py", line 17, in __call__
    cursor.execute("SET app.tenant_id = NULL")
    ~~~~~~~~~~~~~~^^^^^^^^^^^^^^^^^^^^^^^^^^^^
  File "/home/pete/DjangoDev/django_bp_start/.venv/lib/python3.13/site-packages/django/db/backends/utils.py", line 122, in execute
    return super().execute(sql, params)
           ~~~~~~~~~~~~~~~^^^^^^^^^^^^^
  File "/home/pete/DjangoDev/django_bp_start/.venv/lib/python3.13/site-packages/django/db/backends/utils.py", line 79, in execute
    return self._execute_with_wrappers(
           ~~~~~~~~~~~~~~~~~~~~~~~~~~~^
        sql, params, many=False, executor=self._execute
        ^^^^^^^^^^^^^^^^^^^^^^^^^^^^^^^^^^^^^^^^^^^^^^^
    )
    ^
  File "/home/pete/DjangoDev/django_bp_start/.venv/lib/python3.13/site-packages/django/db/backends/utils.py", line 92, in _execute_with_wrappers
    return executor(sql, params, many, context)
  File "/home/pete/DjangoDev/django_bp_start/.venv/lib/python3.13/site-packages/django/db/backends/utils.py", line 100, in _execute
    with self.db.wrap_database_errors:
         ^^^^^^^^^^^^^^^^^^^^^^^^^^^^
  File "/home/pete/DjangoDev/django_bp_start/.venv/lib/python3.13/site-packages/django/db/utils.py", line 91, in __exit__
    raise dj_exc_value.with_traceback(traceback) from exc_value
  File "/home/pete/DjangoDev/django_bp_start/.venv/lib/python3.13/site-packages/django/db/backends/utils.py", line 103, in _execute
    return self.cursor.execute(sql)
           ~~~~~~~~~~~~~~~~~~~^^^^^
  File "/home/pete/DjangoDev/django_bp_start/.venv/lib/python3.13/site-packages/psycopg/cursor.py", line 97, in execute
    raise ex.with_traceback(None)
django.db.utils.ProgrammingError: syntax error at or near "NULL"
LINE 1: SET app.tenant_id = NULL
                            ^
ERROR 2025-10-03 05:27:26,473 log 50398 139689381066432 Internal Server Error: /admin/
Traceback (most recent call last):
  File "/home/pete/DjangoDev/django_bp_start/.venv/lib/python3.13/site-packages/django/db/backends/utils.py", line 103, in _execute
    return self.cursor.execute(sql)
           ~~~~~~~~~~~~~~~~~~~^^^^^
  File "/home/pete/DjangoDev/django_bp_start/.venv/lib/python3.13/site-packages/psycopg/cursor.py", line 97, in execute
    raise ex.with_traceback(None)
psycopg.errors.SyntaxError: syntax error at or near "NULL"
LINE 1: SET app.tenant_id = NULL
                            ^

The above exception was the direct cause of the following exception:

Traceback (most recent call last):
  File "/home/pete/DjangoDev/django_bp_start/.venv/lib/python3.13/site-packages/django/core/handlers/exception.py", line 55, in inner
    response = get_response(request)
  File "/home/pete/DjangoDev/django_bp_start/config/middleware.py", line 17, in __call__
    cursor.execute("SET app.tenant_id = NULL")
    ~~~~~~~~~~~~~~^^^^^^^^^^^^^^^^^^^^^^^^^^^^
  File "/home/pete/DjangoDev/django_bp_start/.venv/lib/python3.13/site-packages/django/db/backends/utils.py", line 122, in execute
    return super().execute(sql, params)
           ~~~~~~~~~~~~~~~^^^^^^^^^^^^^
  File "/home/pete/DjangoDev/django_bp_start/.venv/lib/python3.13/site-packages/django/db/backends/utils.py", line 79, in execute
    return self._execute_with_wrappers(
           ~~~~~~~~~~~~~~~~~~~~~~~~~~~^
        sql, params, many=False, executor=self._execute
        ^^^^^^^^^^^^^^^^^^^^^^^^^^^^^^^^^^^^^^^^^^^^^^^
    )
    ^
  File "/home/pete/DjangoDev/django_bp_start/.venv/lib/python3.13/site-packages/django/db/backends/utils.py", line 92, in _execute_with_wrappers
    return executor(sql, params, many, context)
  File "/home/pete/DjangoDev/django_bp_start/.venv/lib/python3.13/site-packages/django/db/backends/utils.py", line 100, in _execute
    with self.db.wrap_database_errors:
         ^^^^^^^^^^^^^^^^^^^^^^^^^^^^
  File "/home/pete/DjangoDev/django_bp_start/.venv/lib/python3.13/site-packages/django/db/utils.py", line 91, in __exit__
    raise dj_exc_value.with_traceback(traceback) from exc_value
  File "/home/pete/DjangoDev/django_bp_start/.venv/lib/python3.13/site-packages/django/db/backends/utils.py", line 103, in _execute
    return self.cursor.execute(sql)
           ~~~~~~~~~~~~~~~~~~~^^^^^
  File "/home/pete/DjangoDev/django_bp_start/.venv/lib/python3.13/site-packages/psycopg/cursor.py", line 97, in execute
    raise ex.with_traceback(None)
django.db.utils.ProgrammingError: syntax error at or near "NULL"
LINE 1: SET app.tenant_id = NULL
                            ^
ERROR 2025-10-03 05:27:26,474 basehttp 50398 139689381066432 "GET /admin/ HTTP/1.1" 500 111367
INFO 2025-10-03 05:32:22,920 autoreload 50398 139689558889920 /home/pete/DjangoDev/django_bp_start/config/middleware.py changed, reloading.
INFO 2025-10-03 05:32:23,231 autoreload 50621 140548254246336 Watching for file changes with StatReloader
INFO 2025-10-03 05:32:40,031 autoreload 50657 140380826518976 Watching for file changes with StatReloader
INFO 2025-10-03 05:32:46,447 basehttp 50657 140380726093504 "GET /admin/ HTTP/1.1" 302 0
INFO 2025-10-03 05:32:46,492 basehttp 50657 140380726093504 "GET /admin/login/?next=/admin/ HTTP/1.1" 200 4173
INFO 2025-10-03 05:32:46,547 basehttp 50657 140380716652224 "GET /static/admin/css/dark_mode.css HTTP/1.1" 304 0
INFO 2025-10-03 05:32:46,547 basehttp 50657 140380726093504 "GET /static/admin/css/base.css HTTP/1.1" 200 22120
INFO 2025-10-03 05:32:46,549 basehttp 50657 140380708259520 "GET /static/admin/js/theme.js HTTP/1.1" 304 0
INFO 2025-10-03 05:32:46,549 basehttp 50657 140380716652224 "GET /static/admin/css/responsive.css HTTP/1.1" 304 0
INFO 2025-10-03 05:32:46,550 basehttp 50657 140380691474112 "GET /static/admin/js/nav_sidebar.js HTTP/1.1" 304 0
INFO 2025-10-03 05:32:46,550 basehttp 50657 140380699866816 "GET /static/admin/css/nav_sidebar.css HTTP/1.1" 304 0
INFO 2025-10-03 05:32:46,550 basehttp 50657 140380683081408 "GET /static/admin/css/login.css HTTP/1.1" 304 0
WARNING 2025-10-03 05:32:46,667 log 50657 140380708259520 Not Found: /favicon.ico
INFO 2025-10-03 05:32:57,713 basehttp 50657 140380726093504 "POST /admin/login/?next=/admin/ HTTP/1.1" 302 0
INFO 2025-10-03 05:32:57,755 basehttp 50657 140380726093504 "GET /admin/ HTTP/1.1" 200 8744
INFO 2025-10-03 05:32:57,806 basehttp 50657 140380699866816 "GET /static/admin/css/dashboard.css HTTP/1.1" 304 0
INFO 2025-10-03 05:32:57,810 basehttp 50657 140380683081408 "GET /static/admin/img/icon-changelink.svg HTTP/1.1" 200 380
INFO 2025-10-03 05:32:57,810 basehttp 50657 140380691474112 "GET /static/admin/img/icon-addlink.svg HTTP/1.1" 200 331
WARNING 2025-10-03 05:32:57,849 log 50657 140380683081408 Not Found: /favicon.ico
WARNING 2025-10-03 05:32:57,849 basehttp 50657 140380683081408 "GET /favicon.ico HTTP/1.1" 404 2508
INFO 2025-10-03 05:33:01,562 basehttp 50657 140380726093504 "GET /admin/products/product/ HTTP/1.1" 200 10016
INFO 2025-10-03 05:33:01,579 basehttp 50657 140380726093504 "GET /static/admin/js/jquery.init.js HTTP/1.1" 304 0
INFO 2025-10-03 05:33:01,579 basehttp 50657 140380691474112 "GET /static/admin/css/changelists.css HTTP/1.1" 304 0
INFO 2025-10-03 05:33:01,580 basehttp 50657 140380708259520 "GET /static/admin/js/core.js HTTP/1.1" 304 0
INFO 2025-10-03 05:33:01,580 basehttp 50657 140380683081408 "GET /static/admin/img/search.svg HTTP/1.1" 200 458
INFO 2025-10-03 05:33:01,580 basehttp 50657 140380699866816 "GET /static/admin/js/vendor/jquery/jquery.js HTTP/1.1" 304 0
INFO 2025-10-03 05:33:01,581 basehttp 50657 140380708259520 "GET /static/admin/js/actions.js HTTP/1.1" 304 0
INFO 2025-10-03 05:33:01,581 basehttp 50657 140380691474112 "GET /static/admin/js/admin/RelatedObjectLookups.js HTTP/1.1" 304 0
INFO 2025-10-03 05:33:01,582 basehttp 50657 140380699866816 "GET /static/admin/js/filters.js HTTP/1.1" 200 978
INFO 2025-10-03 05:33:01,582 basehttp 50657 140380683081408 "GET /static/admin/js/urlify.js HTTP/1.1" 304 0
INFO 2025-10-03 05:33:01,614 basehttp 50657 140380716652224 "GET /admin/jsi18n/ HTTP/1.1" 200 3342
INFO 2025-10-03 05:33:01,615 basehttp 50657 140380716652224 "GET /static/admin/js/prepopulate.js HTTP/1.1" 304 0
INFO 2025-10-03 05:33:01,621 basehttp 50657 140380726093504 "GET /static/admin/js/vendor/xregexp/xregexp.js HTTP/1.1" 304 0
INFO 2025-10-03 05:33:01,673 basehttp 50657 140380683081408 "GET /static/admin/img/tooltag-add.svg HTTP/1.1" 200 331
WARNING 2025-10-03 05:33:01,708 log 50657 140380716652224 Not Found: /favicon.ico
INFO 2025-10-03 05:33:03,629 basehttp 50657 140380726093504 "GET /admin/products/product/add/ HTTP/1.1" 200 14458
INFO 2025-10-03 05:33:03,644 basehttp 50657 140380699866816 "GET /static/admin/css/forms.css HTTP/1.1" 200 8525
INFO 2025-10-03 05:33:03,646 basehttp 50657 140380699866816 "GET /static/admin/js/change_form.js HTTP/1.1" 200 606
INFO 2025-10-03 05:33:03,647 basehttp 50657 140380691474112 "GET /static/admin/js/prepopulate_init.js HTTP/1.1" 200 586
INFO 2025-10-03 05:33:03,649 basehttp 50657 140380691474112 "GET /static/admin/css/widgets.css HTTP/1.1" 200 11973
INFO 2025-10-03 05:33:03,678 basehttp 50657 140380683081408 "GET /admin/jsi18n/ HTTP/1.1" 200 3342
INFO 2025-10-03 05:33:03,691 basehttp 50657 140380699866816 "GET /static/admin/img/icon-viewlink.svg HTTP/1.1" 200 581
INFO 2025-10-03 05:33:09,724 basehttp 50657 140380726093504 "GET /admin/tenants/tenant/ HTTP/1.1" 200 9680
INFO 2025-10-03 05:33:09,770 basehttp 50657 140380691474112 "GET /admin/jsi18n/ HTTP/1.1" 200 3342
WARNING 2025-10-03 05:33:09,821 log 50657 140380691474112 Not Found: /favicon.ico
INFO 2025-10-03 05:33:11,886 basehttp 50657 140380726093504 "GET /admin/tenants/tenant/add/ HTTP/1.1" 200 11301
INFO 2025-10-03 05:33:11,933 basehttp 50657 140380699866816 "GET /admin/jsi18n/ HTTP/1.1" 200 3342
WARNING 2025-10-03 05:33:11,992 log 50657 140380699866816 Not Found: /favicon.ico
INFO 2025-10-03 05:33:28,474 basehttp 50657 140380726093504 "POST /admin/tenants/tenant/add/ HTTP/1.1" 302 0
INFO 2025-10-03 05:33:28,514 basehttp 50657 140380726093504 "GET /admin/tenants/tenant/add/ HTTP/1.1" 200 11551
INFO 2025-10-03 05:33:28,597 basehttp 50657 140380683081408 "GET /admin/jsi18n/ HTTP/1.1" 200 3342
INFO 2025-10-03 05:33:28,609 basehttp 50657 140380683081408 "GET /static/admin/img/icon-yes.svg HTTP/1.1" 200 436
INFO 2025-10-03 05:33:37,226 basehttp 50657 140380726093504 "POST /admin/tenants/tenant/add/ HTTP/1.1" 302 0
INFO 2025-10-03 05:33:37,265 basehttp 50657 140380726093504 "GET /admin/tenants/tenant/add/ HTTP/1.1" 200 11547
INFO 2025-10-03 05:33:37,350 basehttp 50657 140380683081408 "GET /admin/jsi18n/ HTTP/1.1" 200 3342
WARNING 2025-10-03 05:33:37,408 log 50657 140380683081408 Not Found: /favicon.ico
INFO 2025-10-03 05:34:02,731 basehttp 50657 140380726093504 "POST /admin/tenants/tenant/add/ HTTP/1.1" 302 0
INFO 2025-10-03 05:34:02,770 basehttp 50657 140380726093504 "GET /admin/tenants/tenant/add/ HTTP/1.1" 200 11543
INFO 2025-10-03 05:34:02,856 basehttp 50657 140380708259520 "GET /admin/jsi18n/ HTTP/1.1" 200 3342
WARNING 2025-10-03 05:34:02,915 log 50657 140380708259520 Not Found: /favicon.ico
INFO 2025-10-03 05:34:15,170 basehttp 50657 140380726093504 "POST /admin/tenants/tenant/add/ HTTP/1.1" 302 0
INFO 2025-10-03 05:34:15,211 basehttp 50657 140380726093504 "GET /admin/tenants/tenant/add/ HTTP/1.1" 200 11548
INFO 2025-10-03 05:34:15,297 basehttp 50657 140380726093504 "GET /admin/jsi18n/ HTTP/1.1" 200 3342
WARNING 2025-10-03 05:34:15,397 log 50657 140380708259520 Not Found: /favicon.ico
INFO 2025-10-03 05:34:21,985 basehttp 50657 140380726093504 "POST /admin/tenants/tenant/add/ HTTP/1.1" 302 0
INFO 2025-10-03 05:34:22,024 basehttp 50657 140380726093504 "GET /admin/tenants/tenant/add/ HTTP/1.1" 200 11549
INFO 2025-10-03 05:34:22,109 basehttp 50657 140380726093504 "GET /admin/jsi18n/ HTTP/1.1" 200 3342
WARNING 2025-10-03 05:34:22,206 log 50657 140380708259520 Not Found: /favicon.ico
INFO 2025-10-03 05:34:32,979 basehttp 50657 140380726093504 "POST /admin/tenants/tenant/add/ HTTP/1.1" 302 0
INFO 2025-10-03 05:34:33,022 basehttp 50657 140380726093504 "GET /admin/tenants/tenant/ HTTP/1.1" 200 13021
INFO 2025-10-03 05:34:33,108 basehttp 50657 140380726093504 "GET /admin/jsi18n/ HTTP/1.1" 200 3342
WARNING 2025-10-03 05:34:33,198 log 50657 140380708259520 Not Found: /favicon.ico
INFO 2025-10-03 05:34:34,533 basehttp 50657 140380726093504 "GET /admin/tenants/tenant/ HTTP/1.1" 200 12811
INFO 2025-10-03 05:34:34,578 basehttp 50657 140380683081408 "GET /admin/jsi18n/ HTTP/1.1" 200 3342
WARNING 2025-10-03 05:34:34,629 log 50657 140380683081408 Not Found: /favicon.ico
INFO 2025-10-03 05:35:03,126 basehttp 50657 140380726093504 "POST /admin/tenants/tenant/ HTTP/1.1" 200 10518
INFO 2025-10-03 05:35:03,138 basehttp 50657 140380726093504 "GET /static/admin/js/cancel.js HTTP/1.1" 200 884
INFO 2025-10-03 05:35:04,695 basehttp 50657 140380726093504 "POST /admin/tenants/tenant/ HTTP/1.1" 302 0
INFO 2025-10-03 05:35:04,735 basehttp 50657 140380726093504 "GET /admin/tenants/tenant/ HTTP/1.1" 200 9817
INFO 2025-10-03 05:35:04,819 basehttp 50657 140380726093504 "GET /admin/jsi18n/ HTTP/1.1" 200 3342
WARNING 2025-10-03 05:35:04,911 log 50657 140380683081408 Not Found: /favicon.ico
INFO 2025-10-03 05:35:06,340 basehttp 50657 140380726093504 "GET /admin/tenants/tenant/add/ HTTP/1.1" 200 11301
INFO 2025-10-03 05:35:06,385 basehttp 50657 140380726093504 "GET /admin/jsi18n/ HTTP/1.1" 200 3342
INFO 2025-10-03 05:35:12,761 basehttp 50657 140380726093504 "POST /admin/tenants/tenant/add/ HTTP/1.1" 302 0
INFO 2025-10-03 05:35:12,800 basehttp 50657 140380726093504 "GET /admin/tenants/tenant/add/ HTTP/1.1" 200 11539
INFO 2025-10-03 05:35:12,884 basehttp 50657 140380726093504 "GET /admin/jsi18n/ HTTP/1.1" 200 3342
INFO 2025-10-03 05:35:20,001 basehttp 50657 140380726093504 "POST /admin/tenants/tenant/add/ HTTP/1.1" 302 0
INFO 2025-10-03 05:35:20,041 basehttp 50657 140380726093504 "GET /admin/tenants/tenant/add/ HTTP/1.1" 200 11549
INFO 2025-10-03 05:35:20,125 basehttp 50657 140380726093504 "GET /admin/jsi18n/ HTTP/1.1" 200 3342
WARNING 2025-10-03 05:35:20,225 log 50657 140380683081408 Not Found: /favicon.ico
INFO 2025-10-03 05:35:24,777 basehttp 50657 140380726093504 "POST /admin/tenants/tenant/add/ HTTP/1.1" 302 0
INFO 2025-10-03 05:35:24,816 basehttp 50657 140380726093504 "GET /admin/tenants/tenant/add/ HTTP/1.1" 200 11543
INFO 2025-10-03 05:35:24,901 basehttp 50657 140380726093504 "GET /admin/jsi18n/ HTTP/1.1" 200 3342
WARNING 2025-10-03 05:35:24,998 log 50657 140380683081408 Not Found: /favicon.ico
INFO 2025-10-03 05:35:38,627 basehttp 50657 140380726093504 "GET /admin/tenants/tenant/ HTTP/1.1" 200 11789
INFO 2025-10-03 05:35:38,674 basehttp 50657 140380726093504 "GET /admin/jsi18n/ HTTP/1.1" 200 3342
WARNING 2025-10-03 05:35:38,761 log 50657 140380683081408 Not Found: /favicon.ico
INFO 2025-10-03 05:35:44,933 basehttp 50657 140380726093504 "GET /admin/tenants/tenant/add/ HTTP/1.1" 200 11301
INFO 2025-10-03 05:35:44,979 basehttp 50657 140380726093504 "GET /admin/jsi18n/ HTTP/1.1" 200 3342
WARNING 2025-10-03 05:35:45,079 log 50657 140380683081408 Not Found: /favicon.ico
INFO 2025-10-03 05:35:54,611 basehttp 50657 140380726093504 "POST /admin/tenants/tenant/add/ HTTP/1.1" 302 0
INFO 2025-10-03 05:35:54,650 basehttp 50657 140380726093504 "GET /admin/tenants/tenant/add/ HTTP/1.1" 200 11549
INFO 2025-10-03 05:35:54,734 basehttp 50657 140380726093504 "GET /admin/jsi18n/ HTTP/1.1" 200 3342
WARNING 2025-10-03 05:35:54,832 log 50657 140380683081408 Not Found: /favicon.ico
INFO 2025-10-03 05:36:01,187 basehttp 50657 140380726093504 "GET /admin/tenants/tenant/ HTTP/1.1" 200 12125
INFO 2025-10-03 05:36:01,232 basehttp 50657 140380726093504 "GET /admin/jsi18n/ HTTP/1.1" 200 3342
WARNING 2025-10-03 05:36:01,320 log 50657 140380683081408 Not Found: /favicon.ico
INFO 2025-10-03 05:36:06,475 basehttp 50657 140380726093504 "GET /admin/tenants/tenant/add/ HTTP/1.1" 200 11301
INFO 2025-10-03 05:36:06,519 basehttp 50657 140380726093504 "GET /admin/jsi18n/ HTTP/1.1" 200 3342
WARNING 2025-10-03 05:36:06,616 log 50657 140380683081408 Not Found: /favicon.ico
INFO 2025-10-03 05:36:17,632 basehttp 50657 140380726093504 "POST /admin/tenants/tenant/add/ HTTP/1.1" 302 0
INFO 2025-10-03 05:36:17,672 basehttp 50657 140380726093504 "GET /admin/tenants/tenant/add/ HTTP/1.1" 200 11546
INFO 2025-10-03 05:36:17,757 basehttp 50657 140380726093504 "GET /admin/jsi18n/ HTTP/1.1" 200 3342
WARNING 2025-10-03 05:36:17,851 log 50657 140380683081408 Not Found: /favicon.ico
INFO 2025-10-03 05:36:19,845 basehttp 50657 140380726093504 "GET /admin/tenants/tenant/ HTTP/1.1" 200 12452
INFO 2025-10-03 05:36:19,891 basehttp 50657 140380726093504 "GET /admin/jsi18n/ HTTP/1.1" 200 3342
WARNING 2025-10-03 05:36:19,983 log 50657 140380683081408 Not Found: /favicon.ico
INFO 2025-10-03 05:36:22,892 basehttp 50657 140380726093504 "GET /admin/products/product/ HTTP/1.1" 200 10016
INFO 2025-10-03 05:36:22,937 basehttp 50657 140380726093504 "GET /admin/jsi18n/ HTTP/1.1" 200 3342
INFO 2025-10-03 05:36:25,031 basehttp 50657 140380726093504 "GET /admin/products/product/add/ HTTP/1.1" 200 14699
INFO 2025-10-03 05:36:25,077 basehttp 50657 140380683081408 "GET /admin/jsi18n/ HTTP/1.1" 200 3342
WARNING 2025-10-03 05:36:25,133 log 50657 140380683081408 Not Found: /favicon.ico
INFO 2025-10-03 05:36:42,445 basehttp 50657 140380726093504 "POST /admin/products/product/add/ HTTP/1.1" 302 0
INFO 2025-10-03 05:36:42,488 basehttp 50657 140380726093504 "GET /admin/products/product/add/ HTTP/1.1" 200 14936
INFO 2025-10-03 05:36:42,573 basehttp 50657 140380726093504 "GET /admin/jsi18n/ HTTP/1.1" 200 3342
INFO 2025-10-03 05:36:58,762 basehttp 50657 140380726093504 "POST /admin/products/product/add/ HTTP/1.1" 302 0
INFO 2025-10-03 05:36:58,805 basehttp 50657 140380726093504 "GET /admin/products/product/add/ HTTP/1.1" 200 14938
INFO 2025-10-03 05:36:58,888 basehttp 50657 140380726093504 "GET /admin/jsi18n/ HTTP/1.1" 200 3342
WARNING 2025-10-03 05:36:58,990 log 50657 140380683081408 Not Found: /favicon.ico
INFO 2025-10-03 05:37:21,794 basehttp 50657 140380726093504 "POST /admin/products/product/add/ HTTP/1.1" 302 0
INFO 2025-10-03 05:37:21,837 basehttp 50657 140380726093504 "GET /admin/products/product/ HTTP/1.1" 200 12562
INFO 2025-10-03 05:37:21,923 basehttp 50657 140380726093504 "GET /admin/jsi18n/ HTTP/1.1" 200 3342
WARNING 2025-10-03 05:37:22,012 log 50657 140380683081408 Not Found: /favicon.ico
INFO 2025-10-03 05:37:42,064 basehttp 50657 140380726093504 "GET /api/ HTTP/1.1" 200 5439
INFO 2025-10-03 05:37:42,080 basehttp 50657 140380691474112 "GET /static/rest_framework/js/jquery-3.7.1.min.js HTTP/1.1" 304 0
INFO 2025-10-03 05:37:42,080 basehttp 50657 140380683081408 "GET /static/rest_framework/css/bootstrap-tweaks.css HTTP/1.1" 200 3426
INFO 2025-10-03 05:37:42,080 basehttp 50657 140380699866816 "GET /static/rest_framework/css/default.css HTTP/1.1" 200 1152
INFO 2025-10-03 05:37:42,081 basehttp 50657 140380716652224 "GET /static/rest_framework/js/ajax-form.js HTTP/1.1" 304 0
INFO 2025-10-03 05:37:42,082 basehttp 50657 140380708259520 "GET /static/rest_framework/css/prettify.css HTTP/1.1" 200 817
INFO 2025-10-03 05:37:42,082 basehttp 50657 140380691474112 "GET /static/rest_framework/js/csrf.js HTTP/1.1" 304 0
INFO 2025-10-03 05:37:42,083 basehttp 50657 140380699866816 "GET /static/rest_framework/js/bootstrap.min.js HTTP/1.1" 304 0
INFO 2025-10-03 05:37:42,083 basehttp 50657 140380716652224 "GET /static/rest_framework/js/prettify-min.js HTTP/1.1" 304 0
INFO 2025-10-03 05:37:42,083 basehttp 50657 140380683081408 "GET /static/rest_framework/js/load-ajax-form.js HTTP/1.1" 200 59
INFO 2025-10-03 05:37:42,083 basehttp 50657 140380726093504 "GET /static/rest_framework/css/bootstrap.min.css HTTP/1.1" 200 121457
INFO 2025-10-03 05:37:42,083 basehttp 50657 140380708259520 "GET /static/rest_framework/js/default.js HTTP/1.1" 304 0
INFO 2025-10-03 05:37:42,130 basehttp 50657 140380683081408 "GET /static/rest_framework/img/grid.png HTTP/1.1" 200 1458
WARNING 2025-10-03 05:37:42,210 log 50657 140380683081408 Not Found: /favicon.ico
INFO 2025-10-03 05:37:45,387 basehttp 50657 140380726093504 "GET /api/users/ HTTP/1.1" 200 9212
WARNING 2025-10-03 05:37:45,447 log 50657 140380699866816 Not Found: /favicon.ico
INFO 2025-10-03 05:37:51,777 basehttp 50657 140380726093504 "GET /api/ HTTP/1.1" 200 5439
INFO 2025-10-03 05:37:53,820 basehttp 50657 140380726093504 "GET /api/products/ HTTP/1.1" 200 9347
WARNING 2025-10-03 05:37:53,880 log 50657 140380708259520 Not Found: /favicon.ico
INFO 2025-10-03 05:39:46,972 autoreload 51327 140685823342016 Watching for file changes with StatReloader
INFO 2025-10-03 05:39:51,262 basehttp 51327 140685723297472 "GET /api/products/ HTTP/1.1" 200 10158
WARNING 2025-10-03 05:39:51,322 log 51327 140685723297472 Not Found: /favicon.ico
INFO 2025-10-03 05:42:43,849 autoreload 51327 140685823342016 /home/pete/DjangoDev/django_bp_start/apps/products/serializers.py changed, reloading.
INFO 2025-10-03 05:42:44,153 autoreload 51458 140097796326848 Watching for file changes with StatReloader
INFO 2025-10-03 05:43:01,448 autoreload 51458 140097796326848 /home/pete/DjangoDev/django_bp_start/apps/products/serializers.py changed, reloading.
INFO 2025-10-03 05:43:01,767 autoreload 51467 139767392101824 Watching for file changes with StatReloader
INFO 2025-10-03 05:44:03,492 autoreload 51467 139767392101824 /home/pete/DjangoDev/django_bp_start/config/api_router.py changed, reloading.
INFO 2025-10-03 05:44:03,791 autoreload 52086 139663180629440 Watching for file changes with StatReloader
INFO 2025-10-03 05:45:48,064 autoreload 52208 139742365148608 Watching for file changes with StatReloader
INFO 2025-10-03 05:46:24,447 autoreload 52208 139742365148608 /home/pete/DjangoDev/django_bp_start/config/api_router.py changed, reloading.
INFO 2025-10-03 05:46:24,746 autoreload 52324 140301736502720 Watching for file changes with StatReloader
INFO 2025-10-03 05:46:34,788 basehttp 52324 140301637248704 "GET /api/products/ HTTP/1.1" 200 10430
WARNING 2025-10-03 05:46:34,850 log 52324 140301637248704 Not Found: /favicon.ico
INFO 2025-10-03 05:46:38,421 basehttp 52324 140301637248704 "GET /api/ HTTP/1.1" 200 5576
WARNING 2025-10-03 05:46:38,481 log 52324 140301637248704 Not Found: /favicon.ico
INFO 2025-10-03 05:46:42,081 basehttp 52324 140301627807424 "GET /api/tenants/ HTTP/1.1" 200 9861
INFO 2025-10-03 05:54:34,709 autoreload 52324 140301736502720 /home/pete/DjangoDev/django_bp_start/apps/users/models.py changed, reloading.
INFO 2025-10-03 05:54:35,021 autoreload 52557 139971371890112 Watching for file changes with StatReloader
INFO 2025-10-03 05:54:57,342 autoreload 52557 139971371890112 /home/pete/DjangoDev/django_bp_start/apps/users/models.py changed, reloading.
INFO 2025-10-03 05:54:57,649 autoreload 52568 140500458370496 Watching for file changes with StatReloader
INFO 2025-10-03 06:05:20,621 autoreload 54160 140590367983040 Watching for file changes with StatReloader
INFO 2025-10-03 06:05:28,256 basehttp 54160 140590269327040 "GET /api/ HTTP/1.1" 200 5588
WARNING 2025-10-03 06:05:28,319 log 54160 140590269327040 Not Found: /favicon.ico
INFO 2025-10-03 06:05:30,535 basehttp 54160 140590269327040 "GET /api/tenants/ HTTP/1.1" 200 9873
WARNING 2025-10-03 06:05:30,597 log 54160 140590269327040 Not Found: /favicon.ico
INFO 2025-10-03 06:05:45,552 basehttp 54160 140590269327040 "GET /api/ HTTP/1.1" 200 5588
INFO 2025-10-03 06:05:47,494 basehttp 54160 140590269327040 "GET /api/users/ HTTP/1.1" 200 9224
WARNING 2025-10-03 06:05:47,555 log 54160 140590269327040 Not Found: /favicon.ico
ERROR 2025-10-03 06:06:11,359 log 54160 140590184396480 Internal Server Error: /api/users/
Traceback (most recent call last):
  File "/home/pete/DjangoDev/django_bp_start/.venv/lib/python3.13/site-packages/django/core/handlers/exception.py", line 55, in inner
    response = get_response(request)
  File "/home/pete/DjangoDev/django_bp_start/.venv/lib/python3.13/site-packages/django/core/handlers/base.py", line 197, in _get_response
    response = wrapped_callback(request, *callback_args, **callback_kwargs)
  File "/home/pete/DjangoDev/django_bp_start/.venv/lib/python3.13/site-packages/django/views/decorators/csrf.py", line 65, in _view_wrapper
    return view_func(request, *args, **kwargs)
  File "/home/pete/DjangoDev/django_bp_start/.venv/lib/python3.13/site-packages/rest_framework/viewsets.py", line 125, in view
    return self.dispatch(request, *args, **kwargs)
           ~~~~~~~~~~~~~^^^^^^^^^^^^^^^^^^^^^^^^^^
  File "/home/pete/DjangoDev/django_bp_start/.venv/lib/python3.13/site-packages/rest_framework/views.py", line 515, in dispatch
    response = self.handle_exception(exc)
  File "/home/pete/DjangoDev/django_bp_start/.venv/lib/python3.13/site-packages/rest_framework/views.py", line 475, in handle_exception
    self.raise_uncaught_exception(exc)
    ~~~~~~~~~~~~~~~~~~~~~~~~~~~~~^^^^^
  File "/home/pete/DjangoDev/django_bp_start/.venv/lib/python3.13/site-packages/rest_framework/views.py", line 486, in raise_uncaught_exception
    raise exc
  File "/home/pete/DjangoDev/django_bp_start/.venv/lib/python3.13/site-packages/rest_framework/views.py", line 512, in dispatch
    response = handler(request, *args, **kwargs)
  File "/home/pete/DjangoDev/django_bp_start/apps/users/views.py", line 27, in create
    return super().create(request, *args, **kwargs)
           ~~~~~~~~~~~~~~^^^^^^^^^^^^^^^^^^^^^^^^^^
  File "/home/pete/DjangoDev/django_bp_start/.venv/lib/python3.13/site-packages/rest_framework/mixins.py", line 19, in create
    self.perform_create(serializer)
    ~~~~~~~~~~~~~~~~~~~^^^^^^^^^^^^
  File "/home/pete/DjangoDev/django_bp_start/apps/users/views.py", line 31, in perform_create
    user.set_password(serializer.validated_data["password"])
                      ~~~~~~~~~~~~~~~~~~~~~~~~~^^^^^^^^^^^^
KeyError: 'password'
ERROR 2025-10-03 06:06:11,361 basehttp 54160 140590184396480 "POST /api/users/ HTTP/1.1" 500 113746
INFO 2025-10-03 06:07:51,255 autoreload 54160 140590367983040 /home/pete/DjangoDev/django_bp_start/apps/users/serializers.py changed, reloading.
INFO 2025-10-03 06:07:51,565 autoreload 54285 140541044712896 Watching for file changes with StatReloader
INFO 2025-10-03 06:08:05,831 autoreload 54285 140541044712896 /home/pete/DjangoDev/django_bp_start/apps/users/serializers.py changed, reloading.
INFO 2025-10-03 06:08:06,135 autoreload 54294 140240275588544 Watching for file changes with StatReloader
INFO 2025-10-03 06:08:08,451 basehttp 54294 140240174966464 "GET /api/users/ HTTP/1.1" 200 10544
INFO 2025-10-03 06:08:10,556 basehttp 54294 140240174966464 "GET /api/ HTTP/1.1" 200 5588
WARNING 2025-10-03 06:08:10,618 log 54294 140240174966464 Not Found: /favicon.ico
INFO 2025-10-03 06:08:14,001 basehttp 54294 140240165525184 "GET /api/users/ HTTP/1.1" 200 10544
INFO 2025-10-03 06:08:44,056 basehttp 54294 140240165525184 "OPTIONS /api/users/ HTTP/1.1" 200 12066
INFO 2025-10-03 06:08:53,283 basehttp 54294 140240165525184 "GET /api/users/?format=api HTTP/1.1" 200 10621
INFO 2025-10-03 06:09:18,734 basehttp 54294 140240165525184 "GET /admin/ HTTP/1.1" 200 12242
INFO 2025-10-03 06:09:18,750 basehttp 54294 140240174966464 "GET /static/admin/img/icon-deletelink.svg HTTP/1.1" 200 392
INFO 2025-10-03 06:09:22,953 basehttp 54294 140240165525184 "GET /admin/users/customuser/ HTTP/1.1" 200 14108
INFO 2025-10-03 06:09:23,002 basehttp 54294 140240174966464 "GET /admin/jsi18n/ HTTP/1.1" 200 3342
INFO 2025-10-03 06:09:23,003 basehttp 54294 140240165525184 "GET /static/admin/img/icon-no.svg HTTP/1.1" 200 560
INFO 2025-10-03 06:09:23,018 basehttp 54294 140240165525184 "GET /static/admin/img/sorting-icons.svg HTTP/1.1" 200 1097
WARNING 2025-10-03 06:09:23,053 log 54294 140240174966464 Not Found: /favicon.ico
INFO 2025-10-03 06:09:26,599 basehttp 54294 140240165525184 "GET /admin/users/customuser/2/change/ HTTP/1.1" 200 24300
INFO 2025-10-03 06:09:26,619 basehttp 54294 140240165525184 "GET /static/admin/js/admin/DateTimeShortcuts.js HTTP/1.1" 200 19319
INFO 2025-10-03 06:09:26,619 basehttp 54294 140239934842560 "GET /static/admin/js/SelectFilter2.js HTTP/1.1" 304 0
INFO 2025-10-03 06:09:26,619 basehttp 54294 140239943235264 "GET /static/admin/js/SelectBox.js HTTP/1.1" 304 0
INFO 2025-10-03 06:09:26,619 basehttp 54294 140240174966464 "GET /static/admin/js/calendar.js HTTP/1.1" 304 0
INFO 2025-10-03 06:09:26,649 basehttp 54294 140240156083904 "GET /admin/jsi18n/ HTTP/1.1" 200 3342
INFO 2025-10-03 06:09:26,677 basehttp 54294 140239934842560 "GET /static/admin/img/selector-icons.svg HTTP/1.1" 200 3291
INFO 2025-10-03 06:09:26,678 basehttp 54294 140240174966464 "GET /static/admin/img/icon-calendar.svg HTTP/1.1" 200 1086
INFO 2025-10-03 06:09:26,678 basehttp 54294 140239943235264 "GET /static/admin/img/icon-clock.svg HTTP/1.1" 200 677
WARNING 2025-10-03 06:09:26,705 log 54294 140240156083904 Not Found: /favicon.ico
INFO 2025-10-03 06:09:43,744 basehttp 54294 140240165525184 "GET /admin/users/customuser/2/password/ HTTP/1.1" 200 11196
INFO 2025-10-03 06:09:43,756 basehttp 54294 140239934842560 "GET /static/admin/css/unusable_password_field.css HTTP/1.1" 304 0
INFO 2025-10-03 06:09:43,756 basehttp 54294 140240174966464 "GET /static/admin/js/unusable_password_field.js HTTP/1.1" 304 0
INFO 2025-10-03 06:09:57,960 basehttp 54294 140240165525184 "POST /admin/users/customuser/2/password/ HTTP/1.1" 302 0
INFO 2025-10-03 06:09:58,014 basehttp 54294 140240165525184 "GET /admin/users/customuser/2/change/ HTTP/1.1" 200 24668
INFO 2025-10-03 06:09:58,102 basehttp 54294 140239934842560 "GET /admin/jsi18n/ HTTP/1.1" 200 3342
WARNING 2025-10-03 06:09:58,160 log 54294 140239934842560 Not Found: /favicon.ico
WARNING 2025-10-03 06:09:58,160 basehttp 54294 140239934842560 "GET /favicon.ico HTTP/1.1" 404 2508
INFO 2025-10-03 06:10:25,105 basehttp 54294 140240165525184 "POST /admin/users/customuser/2/change/ HTTP/1.1" 302 0
INFO 2025-10-03 06:10:25,148 basehttp 54294 140240165525184 "GET /admin/users/customuser/ HTTP/1.1" 200 14336
INFO 2025-10-03 06:10:25,243 basehttp 54294 140239934842560 "GET /admin/jsi18n/ HTTP/1.1" 200 3342
WARNING 2025-10-03 06:10:25,298 log 54294 140239934842560 Not Found: /favicon.ico
INFO 2025-10-03 06:10:27,373 basehttp 54294 140240165525184 "GET /admin/users/customuser/2/change/ HTTP/1.1" 200 24566
INFO 2025-10-03 06:10:27,421 basehttp 54294 140240174966464 "GET /admin/jsi18n/ HTTP/1.1" 200 3342
INFO 2025-10-03 06:10:34,138 basehttp 54294 140240165525184 "GET /admin/tenants/tenant/ HTTP/1.1" 200 12452
INFO 2025-10-03 06:10:34,185 basehttp 54294 140240174966464 "GET /admin/jsi18n/ HTTP/1.1" 200 3342
INFO 2025-10-03 06:10:40,978 basehttp 54294 140240165525184 "GET /admin/users/customuser/ HTTP/1.1" 200 14122
INFO 2025-10-03 06:10:41,024 basehttp 54294 140240174966464 "GET /admin/jsi18n/ HTTP/1.1" 200 3342
INFO 2025-10-03 06:13:10,983 autoreload 54704 139674780329408 Watching for file changes with StatReloader
INFO 2025-10-03 06:13:16,985 basehttp 54704 139674680026816 "GET /admin/tenants/tenant/ HTTP/1.1" 200 12452
INFO 2025-10-03 06:13:17,007 basehttp 54704 139674670585536 "GET /static/admin/css/dark_mode.css HTTP/1.1" 304 0
INFO 2025-10-03 06:13:17,007 basehttp 54704 139674680026816 "GET /static/admin/css/base.css HTTP/1.1" 200 22120
INFO 2025-10-03 06:13:17,008 basehttp 54704 139674653800128 "GET /static/admin/css/nav_sidebar.css HTTP/1.1" 304 0
INFO 2025-10-03 06:13:17,009 basehttp 54704 139674662192832 "GET /static/admin/js/theme.js HTTP/1.1" 304 0
INFO 2025-10-03 06:13:17,009 basehttp 54704 139674653800128 "GET /static/admin/js/vendor/jquery/jquery.js HTTP/1.1" 304 0
INFO 2025-10-03 06:13:17,010 basehttp 54704 139674645407424 "GET /static/admin/js/nav_sidebar.js HTTP/1.1" 304 0
INFO 2025-10-03 06:13:17,010 basehttp 54704 139674637014720 "GET /static/admin/css/changelists.css HTTP/1.1" 304 0
INFO 2025-10-03 06:13:17,011 basehttp 54704 139674662192832 "GET /static/admin/js/jquery.init.js HTTP/1.1" 304 0
INFO 2025-10-03 06:13:17,011 basehttp 54704 139674645407424 "GET /static/admin/js/core.js HTTP/1.1" 304 0
INFO 2025-10-03 06:13:17,011 basehttp 54704 139674637014720 "GET /static/admin/js/admin/RelatedObjectLookups.js HTTP/1.1" 304 0
INFO 2025-10-03 06:13:17,043 basehttp 54704 139674670585536 "GET /admin/jsi18n/ HTTP/1.1" 200 3342
INFO 2025-10-03 06:13:17,047 basehttp 54704 139674680026816 "GET /static/admin/js/actions.js HTTP/1.1" 304 0
INFO 2025-10-03 06:13:17,051 basehttp 54704 139674653800128 "GET /static/admin/js/urlify.js HTTP/1.1" 304 0
INFO 2025-10-03 06:13:17,052 basehttp 54704 139674645407424 "GET /static/admin/js/vendor/xregexp/xregexp.js HTTP/1.1" 304 0
INFO 2025-10-03 06:13:17,052 basehttp 54704 139674662192832 "GET /static/admin/js/prepopulate.js HTTP/1.1" 304 0
INFO 2025-10-03 06:13:17,054 basehttp 54704 139674637014720 "GET /static/admin/css/responsive.css HTTP/1.1" 304 0
INFO 2025-10-03 06:13:17,084 basehttp 54704 139674670585536 "GET /static/admin/js/filters.js HTTP/1.1" 304 0
INFO 2025-10-03 06:13:17,105 basehttp 54704 139674653800128 "GET /static/admin/img/icon-addlink.svg HTTP/1.1" 200 331
INFO 2025-10-03 06:13:17,105 basehttp 54704 139674645407424 "GET /static/admin/img/tooltag-add.svg HTTP/1.1" 200 331
WARNING 2025-10-03 06:13:17,184 log 54704 139674670585536 Not Found: /favicon.ico
INFO 2025-10-03 06:13:20,443 basehttp 54704 139674680026816 "GET /admin/users/customuser/ HTTP/1.1" 200 14122
INFO 2025-10-03 06:13:20,492 basehttp 54704 139674653800128 "GET /admin/jsi18n/ HTTP/1.1" 200 3342
INFO 2025-10-03 06:13:20,503 basehttp 54704 139674653800128 "GET /static/admin/img/search.svg HTTP/1.1" 200 458
INFO 2025-10-03 06:13:20,504 basehttp 54704 139674645407424 "GET /static/admin/img/icon-yes.svg HTTP/1.1" 200 436
INFO 2025-10-03 06:13:20,508 basehttp 54704 139674645407424 "GET /static/admin/img/icon-viewlink.svg HTTP/1.1" 200 581
INFO 2025-10-03 06:13:25,504 basehttp 54704 139674680026816 "GET /admin/users/customuser/1/change/ HTTP/1.1" 200 24610
INFO 2025-10-03 06:13:25,521 basehttp 54704 139674645407424 "GET /static/admin/css/forms.css HTTP/1.1" 200 8525
INFO 2025-10-03 06:13:25,524 basehttp 54704 139674637014720 "GET /static/admin/js/prepopulate_init.js HTTP/1.1" 304 0
INFO 2025-10-03 06:13:25,524 basehttp 54704 139674662192832 "GET /static/admin/js/change_form.js HTTP/1.1" 304 0
INFO 2025-10-03 06:13:25,527 basehttp 54704 139674637014720 "GET /static/admin/css/widgets.css HTTP/1.1" 200 11973
INFO 2025-10-03 06:13:25,553 basehttp 54704 139674653800128 "GET /admin/jsi18n/ HTTP/1.1" 200 3342
INFO 2025-10-03 06:13:38,291 basehttp 54704 139674680026816 "POST /admin/users/customuser/1/change/ HTTP/1.1" 302 0
INFO 2025-10-03 06:13:38,333 basehttp 54704 139674680026816 "GET /admin/users/customuser/ HTTP/1.1" 200 14344
INFO 2025-10-03 06:13:38,424 basehttp 54704 139674637014720 "GET /admin/jsi18n/ HTTP/1.1" 200 3342
INFO 2025-10-03 06:13:51,805 basehttp 54704 139674680026816 "GET /api/ HTTP/1.1" 200 5588
INFO 2025-10-03 06:13:51,819 basehttp 54704 139674637014720 "GET /static/rest_framework/js/load-ajax-form.js HTTP/1.1" 200 59
INFO 2025-10-03 06:13:54,889 basehttp 54704 139674680026816 "GET /api/tenants/ HTTP/1.1" 200 9873
INFO 2025-10-03 06:13:58,819 basehttp 54704 139674680026816 "GET /api/ HTTP/1.1" 200 5588
INFO 2025-10-03 06:14:00,321 basehttp 54704 139674680026816 "GET /api/users/ HTTP/1.1" 200 10544
ERROR 2025-10-03 06:14:22,734 log 54704 139674680026816 Internal Server Error: /api/users/
Traceback (most recent call last):
  File "/home/pete/DjangoDev/django_bp_start/.venv/lib/python3.13/site-packages/rest_framework/request.py", line 422, in __getattr__
    return getattr(_request, attr)
AttributeError: 'WSGIRequest' object has no attribute 'tenant'

During handling of the above exception, another exception occurred:

Traceback (most recent call last):
  File "/home/pete/DjangoDev/django_bp_start/.venv/lib/python3.13/site-packages/django/core/handlers/exception.py", line 55, in inner
    response = get_response(request)
  File "/home/pete/DjangoDev/django_bp_start/.venv/lib/python3.13/site-packages/django/core/handlers/base.py", line 197, in _get_response
    response = wrapped_callback(request, *callback_args, **callback_kwargs)
  File "/home/pete/DjangoDev/django_bp_start/.venv/lib/python3.13/site-packages/django/views/decorators/csrf.py", line 65, in _view_wrapper
    return view_func(request, *args, **kwargs)
  File "/home/pete/DjangoDev/django_bp_start/.venv/lib/python3.13/site-packages/rest_framework/viewsets.py", line 125, in view
    return self.dispatch(request, *args, **kwargs)
           ~~~~~~~~~~~~~^^^^^^^^^^^^^^^^^^^^^^^^^^
  File "/home/pete/DjangoDev/django_bp_start/.venv/lib/python3.13/site-packages/rest_framework/views.py", line 515, in dispatch
    response = self.handle_exception(exc)
  File "/home/pete/DjangoDev/django_bp_start/.venv/lib/python3.13/site-packages/rest_framework/views.py", line 475, in handle_exception
    self.raise_uncaught_exception(exc)
    ~~~~~~~~~~~~~~~~~~~~~~~~~~~~~^^^^^
  File "/home/pete/DjangoDev/django_bp_start/.venv/lib/python3.13/site-packages/rest_framework/views.py", line 486, in raise_uncaught_exception
    raise exc
  File "/home/pete/DjangoDev/django_bp_start/.venv/lib/python3.13/site-packages/rest_framework/views.py", line 512, in dispatch
    response = handler(request, *args, **kwargs)
  File "/home/pete/DjangoDev/django_bp_start/apps/users/views.py", line 31, in create
    self.perform_create(serializer)
    ~~~~~~~~~~~~~~~~~~~^^^^^^^^^^^^
  File "/home/pete/DjangoDev/django_bp_start/apps/users/views.py", line 42, in perform_create
    serializer.save(tenant=self.request.tenant)
                           ^^^^^^^^^^^^^^^^^^^
  File "/home/pete/DjangoDev/django_bp_start/.venv/lib/python3.13/site-packages/rest_framework/request.py", line 424, in __getattr__
    raise AttributeError(f"'{self.__class__.__name__}' object has no attribute '{attr}'")
AttributeError: 'Request' object has no attribute 'tenant'
ERROR 2025-10-03 06:14:22,736 basehttp 54704 139674680026816 "POST /api/users/ HTTP/1.1" 500 119017
INFO 2025-10-03 06:15:15,482 autoreload 54704 139674780329408 /home/pete/DjangoDev/django_bp_start/config/middleware.py changed, reloading.
INFO 2025-10-03 06:15:15,804 autoreload 54815 139894928745920 Watching for file changes with StatReloader
INFO 2025-10-03 06:15:17,962 autoreload 54815 139894928745920 /home/pete/DjangoDev/django_bp_start/config/middleware.py changed, reloading.
INFO 2025-10-03 06:15:18,270 autoreload 54828 140556575778240 Watching for file changes with StatReloader
INFO 2025-10-03 06:15:22,874 autoreload 54859 139621397517760 Watching for file changes with StatReloader
ERROR 2025-10-03 06:15:27,724 log 54859 139621297022656 Internal Server Error: /api/users/
Traceback (most recent call last):
  File "/home/pete/DjangoDev/django_bp_start/.venv/lib/python3.13/site-packages/django/core/handlers/exception.py", line 55, in inner
    response = get_response(request)
  File "/home/pete/DjangoDev/django_bp_start/config/middleware.py", line 14, in __call__
    request.tenant = Tenant.objects.get(slug="default")
                     ~~~~~~~~~~~~~~~~~~^^^^^^^^^^^^^^^^
  File "/home/pete/DjangoDev/django_bp_start/.venv/lib/python3.13/site-packages/django/db/models/manager.py", line 87, in manager_method
    return getattr(self.get_queryset(), name)(*args, **kwargs)
           ~~~~~~~~~~~~~~~~~~~~~~~~~~~~~~~~~~^^^^^^^^^^^^^^^^^
  File "/home/pete/DjangoDev/django_bp_start/.venv/lib/python3.13/site-packages/django/db/models/query.py", line 633, in get
    raise self.model.DoesNotExist(
        "%s matching query does not exist." % self.model._meta.object_name
    )
apps.tenants.models.Tenant.DoesNotExist: Tenant matching query does not exist.
ERROR 2025-10-03 06:15:27,725 basehttp 54859 139621297022656 "GET /api/users/ HTTP/1.1" 500 78053
ERROR 2025-10-03 06:15:32,145 log 54859 139621297022656 Internal Server Error: /api/users/
Traceback (most recent call last):
  File "/home/pete/DjangoDev/django_bp_start/.venv/lib/python3.13/site-packages/django/core/handlers/exception.py", line 55, in inner
    response = get_response(request)
  File "/home/pete/DjangoDev/django_bp_start/config/middleware.py", line 14, in __call__
    request.tenant = Tenant.objects.get(slug="default")
                     ~~~~~~~~~~~~~~~~~~^^^^^^^^^^^^^^^^
  File "/home/pete/DjangoDev/django_bp_start/.venv/lib/python3.13/site-packages/django/db/models/manager.py", line 87, in manager_method
    return getattr(self.get_queryset(), name)(*args, **kwargs)
           ~~~~~~~~~~~~~~~~~~~~~~~~~~~~~~~~~~^^^^^^^^^^^^^^^^^
  File "/home/pete/DjangoDev/django_bp_start/.venv/lib/python3.13/site-packages/django/db/models/query.py", line 633, in get
    raise self.model.DoesNotExist(
        "%s matching query does not exist." % self.model._meta.object_name
    )
apps.tenants.models.Tenant.DoesNotExist: Tenant matching query does not exist.
ERROR 2025-10-03 06:15:32,146 basehttp 54859 139621297022656 "GET /api/users/ HTTP/1.1" 500 78053
INFO 2025-10-03 06:17:08,096 autoreload 54859 139621397517760 /home/pete/DjangoDev/django_bp_start/config/settings.py changed, reloading.
INFO 2025-10-03 06:17:08,409 autoreload 54996 139909056869824 Watching for file changes with StatReloader
INFO 2025-10-03 06:17:34,797 autoreload 54996 139909056869824 /home/pete/DjangoDev/django_bp_start/config/settings.py changed, reloading.
INFO 2025-10-03 06:17:35,110 autoreload 55016 140526781466048 Watching for file changes with StatReloader
INFO 2025-10-03 06:18:37,581 autoreload 55058 139975977272768 Watching for file changes with StatReloader
ERROR 2025-10-03 06:18:44,105 log 55058 139975802746560 Internal Server Error: /api/users/
Traceback (most recent call last):
  File "/home/pete/DjangoDev/django_bp_start/.venv/lib/python3.13/site-packages/django/core/handlers/exception.py", line 55, in inner
    response = get_response(request)
  File "/home/pete/DjangoDev/django_bp_start/config/middleware.py", line 14, in __call__
    request.tenant = Tenant.objects.get(slug="default")
                     ~~~~~~~~~~~~~~~~~~^^^^^^^^^^^^^^^^
  File "/home/pete/DjangoDev/django_bp_start/.venv/lib/python3.13/site-packages/django/db/models/manager.py", line 87, in manager_method
    return getattr(self.get_queryset(), name)(*args, **kwargs)
           ~~~~~~~~~~~~~~~~~~~~~~~~~~~~~~~~~~^^^^^^^^^^^^^^^^^
  File "/home/pete/DjangoDev/django_bp_start/.venv/lib/python3.13/site-packages/django/db/models/query.py", line 633, in get
    raise self.model.DoesNotExist(
        "%s matching query does not exist." % self.model._meta.object_name
    )
apps.tenants.models.Tenant.DoesNotExist: Tenant matching query does not exist.
ERROR 2025-10-03 06:18:44,106 basehttp 55058 139975802746560 "GET /api/users/ HTTP/1.1" 500 77913
INFO 2025-10-03 06:19:51,472 autoreload 55058 139975977272768 /home/pete/DjangoDev/django_bp_start/config/middleware.py changed, reloading.
INFO 2025-10-03 06:19:51,781 autoreload 55103 140057720772032 Watching for file changes with StatReloader
INFO 2025-10-03 06:19:54,936 autoreload 55103 140057720772032 /home/pete/DjangoDev/django_bp_start/config/middleware.py changed, reloading.
INFO 2025-10-03 06:19:55,242 autoreload 55111 140452886500800 Watching for file changes with StatReloader
INFO 2025-10-03 06:20:01,264 autoreload 55143 139881578464704 Watching for file changes with StatReloader
WARNING 2025-10-03 06:20:10,904 log 55143 139881478088384 Not Found: /api/
WARNING 2025-10-03 06:20:10,905 basehttp 55143 139881478088384 "GET /api/ HTTP/1.1" 404 1924
WARNING 2025-10-03 06:20:10,955 log 55143 139881478088384 Not Found: /favicon.ico
WARNING 2025-10-03 06:20:10,955 basehttp 55143 139881478088384 "GET /favicon.ico HTTP/1.1" 404 1816
WARNING 2025-10-03 06:20:20,615 log 55143 139881478088384 Not Found: /api/
WARNING 2025-10-03 06:20:20,616 basehttp 55143 139881478088384 "GET /api/ HTTP/1.1" 404 1924
WARNING 2025-10-03 06:20:20,663 log 55143 139881478088384 Not Found: /favicon.ico
INFO 2025-10-03 11:24:01,996 autoreload 58687 139623354090944 Watching for file changes with StatReloader
ERROR 2025-10-03 11:24:08,782 log 58687 139623253665472 Internal Server Error: /api/
Traceback (most recent call last):
  File "/home/pete/DjangoDev/django_bp_start/.venv/lib/python3.13/site-packages/django/db/backends/utils.py", line 105, in _execute
    return self.cursor.execute(sql, params)
           ~~~~~~~~~~~~~~~~~~~^^^^^^^^^^^^^
  File "/home/pete/DjangoDev/django_bp_start/.venv/lib/python3.13/site-packages/psycopg/cursor.py", line 97, in execute
    raise ex.with_traceback(None)
psycopg.errors.UndefinedColumn: column tenants_tenant.slug does not exist
LINE 1: ...enants_tenant"."name", "tenants_tenant"."domain", "tenants_t...
                                                             ^

The above exception was the direct cause of the following exception:

Traceback (most recent call last):
  File "/home/pete/DjangoDev/django_bp_start/.venv/lib/python3.13/site-packages/django/core/handlers/exception.py", line 55, in inner
    response = get_response(request)
  File "/home/pete/DjangoDev/django_bp_start/config/middleware.py", line 16, in __call__
    request.tenant = Tenant.objects.get(slug="default")
                     ~~~~~~~~~~~~~~~~~~^^^^^^^^^^^^^^^^
  File "/home/pete/DjangoDev/django_bp_start/.venv/lib/python3.13/site-packages/django/db/models/manager.py", line 87, in manager_method
    return getattr(self.get_queryset(), name)(*args, **kwargs)
           ~~~~~~~~~~~~~~~~~~~~~~~~~~~~~~~~~~^^^^^^^^^^^^^^^^^
  File "/home/pete/DjangoDev/django_bp_start/.venv/lib/python3.13/site-packages/django/db/models/query.py", line 629, in get
    num = len(clone)
  File "/home/pete/DjangoDev/django_bp_start/.venv/lib/python3.13/site-packages/django/db/models/query.py", line 366, in __len__
    self._fetch_all()
    ~~~~~~~~~~~~~~~^^
  File "/home/pete/DjangoDev/django_bp_start/.venv/lib/python3.13/site-packages/django/db/models/query.py", line 1949, in _fetch_all
    self._result_cache = list(self._iterable_class(self))
                         ~~~~^^^^^^^^^^^^^^^^^^^^^^^^^^^^
  File "/home/pete/DjangoDev/django_bp_start/.venv/lib/python3.13/site-packages/django/db/models/query.py", line 91, in __iter__
    results = compiler.execute_sql(
        chunked_fetch=self.chunked_fetch, chunk_size=self.chunk_size
    )
  File "/home/pete/DjangoDev/django_bp_start/.venv/lib/python3.13/site-packages/django/db/models/sql/compiler.py", line 1623, in execute_sql
    cursor.execute(sql, params)
    ~~~~~~~~~~~~~~^^^^^^^^^^^^^
  File "/home/pete/DjangoDev/django_bp_start/.venv/lib/python3.13/site-packages/django/db/backends/utils.py", line 122, in execute
    return super().execute(sql, params)
           ~~~~~~~~~~~~~~~^^^^^^^^^^^^^
  File "/home/pete/DjangoDev/django_bp_start/.venv/lib/python3.13/site-packages/django/db/backends/utils.py", line 79, in execute
    return self._execute_with_wrappers(
           ~~~~~~~~~~~~~~~~~~~~~~~~~~~^
        sql, params, many=False, executor=self._execute
        ^^^^^^^^^^^^^^^^^^^^^^^^^^^^^^^^^^^^^^^^^^^^^^^
    )
    ^
  File "/home/pete/DjangoDev/django_bp_start/.venv/lib/python3.13/site-packages/django/db/backends/utils.py", line 92, in _execute_with_wrappers
    return executor(sql, params, many, context)
  File "/home/pete/DjangoDev/django_bp_start/.venv/lib/python3.13/site-packages/django/db/backends/utils.py", line 100, in _execute
    with self.db.wrap_database_errors:
         ^^^^^^^^^^^^^^^^^^^^^^^^^^^^
  File "/home/pete/DjangoDev/django_bp_start/.venv/lib/python3.13/site-packages/django/db/utils.py", line 91, in __exit__
    raise dj_exc_value.with_traceback(traceback) from exc_value
  File "/home/pete/DjangoDev/django_bp_start/.venv/lib/python3.13/site-packages/django/db/backends/utils.py", line 105, in _execute
    return self.cursor.execute(sql, params)
           ~~~~~~~~~~~~~~~~~~~^^^^^^^^^^^^^
  File "/home/pete/DjangoDev/django_bp_start/.venv/lib/python3.13/site-packages/psycopg/cursor.py", line 97, in execute
    raise ex.with_traceback(None)
django.db.utils.ProgrammingError: column tenants_tenant.slug does not exist
LINE 1: ...enants_tenant"."name", "tenants_tenant"."domain", "tenants_t...
                                                             ^
ERROR 2025-10-03 11:24:08,785 basehttp 58687 139623253665472 "GET /api/ HTTP/1.1" 500 142548
INFO 2025-10-03 11:26:36,414 autoreload 58873 140494418949568 Watching for file changes with StatReloader
ERROR 2025-10-03 11:26:41,891 log 58873 140494318331584 Internal Server Error: /api/
Traceback (most recent call last):
  File "/home/pete/DjangoDev/django_bp_start/.venv/lib/python3.13/site-packages/django/db/backends/utils.py", line 105, in _execute
    return self.cursor.execute(sql, params)
           ~~~~~~~~~~~~~~~~~~~^^^^^^^^^^^^^
  File "/home/pete/DjangoDev/django_bp_start/.venv/lib/python3.13/site-packages/psycopg/cursor.py", line 97, in execute
    raise ex.with_traceback(None)
psycopg.errors.UndefinedColumn: column tenants_tenant.slug does not exist
LINE 1: ...enants_tenant"."name", "tenants_tenant"."domain", "tenants_t...
                                                             ^

The above exception was the direct cause of the following exception:

Traceback (most recent call last):
  File "/home/pete/DjangoDev/django_bp_start/.venv/lib/python3.13/site-packages/django/core/handlers/exception.py", line 55, in inner
    response = get_response(request)
  File "/home/pete/DjangoDev/django_bp_start/config/middleware.py", line 16, in __call__
    request.tenant = Tenant.objects.get(slug="default")
                     ~~~~~~~~~~~~~~~~~~^^^^^^^^^^^^^^^^
  File "/home/pete/DjangoDev/django_bp_start/.venv/lib/python3.13/site-packages/django/db/models/manager.py", line 87, in manager_method
    return getattr(self.get_queryset(), name)(*args, **kwargs)
           ~~~~~~~~~~~~~~~~~~~~~~~~~~~~~~~~~~^^^^^^^^^^^^^^^^^
  File "/home/pete/DjangoDev/django_bp_start/.venv/lib/python3.13/site-packages/django/db/models/query.py", line 629, in get
    num = len(clone)
  File "/home/pete/DjangoDev/django_bp_start/.venv/lib/python3.13/site-packages/django/db/models/query.py", line 366, in __len__
    self._fetch_all()
    ~~~~~~~~~~~~~~~^^
  File "/home/pete/DjangoDev/django_bp_start/.venv/lib/python3.13/site-packages/django/db/models/query.py", line 1949, in _fetch_all
    self._result_cache = list(self._iterable_class(self))
                         ~~~~^^^^^^^^^^^^^^^^^^^^^^^^^^^^
  File "/home/pete/DjangoDev/django_bp_start/.venv/lib/python3.13/site-packages/django/db/models/query.py", line 91, in __iter__
    results = compiler.execute_sql(
        chunked_fetch=self.chunked_fetch, chunk_size=self.chunk_size
    )
  File "/home/pete/DjangoDev/django_bp_start/.venv/lib/python3.13/site-packages/django/db/models/sql/compiler.py", line 1623, in execute_sql
    cursor.execute(sql, params)
    ~~~~~~~~~~~~~~^^^^^^^^^^^^^
  File "/home/pete/DjangoDev/django_bp_start/.venv/lib/python3.13/site-packages/django/db/backends/utils.py", line 122, in execute
    return super().execute(sql, params)
           ~~~~~~~~~~~~~~~^^^^^^^^^^^^^
  File "/home/pete/DjangoDev/django_bp_start/.venv/lib/python3.13/site-packages/django/db/backends/utils.py", line 79, in execute
    return self._execute_with_wrappers(
           ~~~~~~~~~~~~~~~~~~~~~~~~~~~^
        sql, params, many=False, executor=self._execute
        ^^^^^^^^^^^^^^^^^^^^^^^^^^^^^^^^^^^^^^^^^^^^^^^
    )
    ^
  File "/home/pete/DjangoDev/django_bp_start/.venv/lib/python3.13/site-packages/django/db/backends/utils.py", line 92, in _execute_with_wrappers
    return executor(sql, params, many, context)
  File "/home/pete/DjangoDev/django_bp_start/.venv/lib/python3.13/site-packages/django/db/backends/utils.py", line 100, in _execute
    with self.db.wrap_database_errors:
         ^^^^^^^^^^^^^^^^^^^^^^^^^^^^
  File "/home/pete/DjangoDev/django_bp_start/.venv/lib/python3.13/site-packages/django/db/utils.py", line 91, in __exit__
    raise dj_exc_value.with_traceback(traceback) from exc_value
  File "/home/pete/DjangoDev/django_bp_start/.venv/lib/python3.13/site-packages/django/db/backends/utils.py", line 105, in _execute
    return self.cursor.execute(sql, params)
           ~~~~~~~~~~~~~~~~~~~^^^^^^^^^^^^^
  File "/home/pete/DjangoDev/django_bp_start/.venv/lib/python3.13/site-packages/psycopg/cursor.py", line 97, in execute
    raise ex.with_traceback(None)
django.db.utils.ProgrammingError: column tenants_tenant.slug does not exist
LINE 1: ...enants_tenant"."name", "tenants_tenant"."domain", "tenants_t...
                                                             ^
ERROR 2025-10-03 11:26:41,893 basehttp 58873 140494318331584 "GET /api/ HTTP/1.1" 500 142548
INFO 2025-10-03 11:27:07,878 autoreload 58873 140494418949568 /home/pete/DjangoDev/django_bp_start/apps/tenants/serializers.py changed, reloading.
INFO 2025-10-03 11:27:08,185 autoreload 58928 140417388078528 Watching for file changes with StatReloader
ERROR 2025-10-03 11:27:12,879 log 58928 140417288890048 Internal Server Error: /api/
Traceback (most recent call last):
  File "/home/pete/DjangoDev/django_bp_start/.venv/lib/python3.13/site-packages/django/db/backends/utils.py", line 105, in _execute
    return self.cursor.execute(sql, params)
           ~~~~~~~~~~~~~~~~~~~^^^^^^^^^^^^^
  File "/home/pete/DjangoDev/django_bp_start/.venv/lib/python3.13/site-packages/psycopg/cursor.py", line 97, in execute
    raise ex.with_traceback(None)
psycopg.errors.UndefinedColumn: column tenants_tenant.slug does not exist
LINE 1: ...enants_tenant"."name", "tenants_tenant"."domain", "tenants_t...
                                                             ^

The above exception was the direct cause of the following exception:

Traceback (most recent call last):
  File "/home/pete/DjangoDev/django_bp_start/.venv/lib/python3.13/site-packages/django/core/handlers/exception.py", line 55, in inner
    response = get_response(request)
  File "/home/pete/DjangoDev/django_bp_start/config/middleware.py", line 16, in __call__
    request.tenant = Tenant.objects.get(slug="default")
                     ~~~~~~~~~~~~~~~~~~^^^^^^^^^^^^^^^^
  File "/home/pete/DjangoDev/django_bp_start/.venv/lib/python3.13/site-packages/django/db/models/manager.py", line 87, in manager_method
    return getattr(self.get_queryset(), name)(*args, **kwargs)
           ~~~~~~~~~~~~~~~~~~~~~~~~~~~~~~~~~~^^^^^^^^^^^^^^^^^
  File "/home/pete/DjangoDev/django_bp_start/.venv/lib/python3.13/site-packages/django/db/models/query.py", line 629, in get
    num = len(clone)
  File "/home/pete/DjangoDev/django_bp_start/.venv/lib/python3.13/site-packages/django/db/models/query.py", line 366, in __len__
    self._fetch_all()
    ~~~~~~~~~~~~~~~^^
  File "/home/pete/DjangoDev/django_bp_start/.venv/lib/python3.13/site-packages/django/db/models/query.py", line 1949, in _fetch_all
    self._result_cache = list(self._iterable_class(self))
                         ~~~~^^^^^^^^^^^^^^^^^^^^^^^^^^^^
  File "/home/pete/DjangoDev/django_bp_start/.venv/lib/python3.13/site-packages/django/db/models/query.py", line 91, in __iter__
    results = compiler.execute_sql(
        chunked_fetch=self.chunked_fetch, chunk_size=self.chunk_size
    )
  File "/home/pete/DjangoDev/django_bp_start/.venv/lib/python3.13/site-packages/django/db/models/sql/compiler.py", line 1623, in execute_sql
    cursor.execute(sql, params)
    ~~~~~~~~~~~~~~^^^^^^^^^^^^^
  File "/home/pete/DjangoDev/django_bp_start/.venv/lib/python3.13/site-packages/django/db/backends/utils.py", line 122, in execute
    return super().execute(sql, params)
           ~~~~~~~~~~~~~~~^^^^^^^^^^^^^
  File "/home/pete/DjangoDev/django_bp_start/.venv/lib/python3.13/site-packages/django/db/backends/utils.py", line 79, in execute
    return self._execute_with_wrappers(
           ~~~~~~~~~~~~~~~~~~~~~~~~~~~^
        sql, params, many=False, executor=self._execute
        ^^^^^^^^^^^^^^^^^^^^^^^^^^^^^^^^^^^^^^^^^^^^^^^
    )
    ^
  File "/home/pete/DjangoDev/django_bp_start/.venv/lib/python3.13/site-packages/django/db/backends/utils.py", line 92, in _execute_with_wrappers
    return executor(sql, params, many, context)
  File "/home/pete/DjangoDev/django_bp_start/.venv/lib/python3.13/site-packages/django/db/backends/utils.py", line 100, in _execute
    with self.db.wrap_database_errors:
         ^^^^^^^^^^^^^^^^^^^^^^^^^^^^
  File "/home/pete/DjangoDev/django_bp_start/.venv/lib/python3.13/site-packages/django/db/utils.py", line 91, in __exit__
    raise dj_exc_value.with_traceback(traceback) from exc_value
  File "/home/pete/DjangoDev/django_bp_start/.venv/lib/python3.13/site-packages/django/db/backends/utils.py", line 105, in _execute
    return self.cursor.execute(sql, params)
           ~~~~~~~~~~~~~~~~~~~^^^^^^^^^^^^^
  File "/home/pete/DjangoDev/django_bp_start/.venv/lib/python3.13/site-packages/psycopg/cursor.py", line 97, in execute
    raise ex.with_traceback(None)
django.db.utils.ProgrammingError: column tenants_tenant.slug does not exist
LINE 1: ...enants_tenant"."name", "tenants_tenant"."domain", "tenants_t...
                                                             ^
ERROR 2025-10-03 11:27:12,882 basehttp 58928 140417288890048 "GET /api/ HTTP/1.1" 500 142548
INFO 2025-10-03 11:28:55,384 autoreload 58928 140417388078528 /home/pete/DjangoDev/django_bp_start/apps/tenants/serializers.py changed, reloading.
INFO 2025-10-03 11:28:55,684 autoreload 59024 140115760727488 Watching for file changes with StatReloader
INFO 2025-10-03 11:29:03,709 autoreload 59056 139850720564672 Watching for file changes with StatReloader
INFO 2025-10-03 11:29:24,183 autoreload 59111 139665607050688 Watching for file changes with StatReloader
ERROR 2025-10-03 11:29:30,258 log 59111 139665507083968 Internal Server Error: /api/tenants/
Traceback (most recent call last):
  File "/home/pete/DjangoDev/django_bp_start/.venv/lib/python3.13/site-packages/django/db/backends/utils.py", line 105, in _execute
    return self.cursor.execute(sql, params)
           ~~~~~~~~~~~~~~~~~~~^^^^^^^^^^^^^
  File "/home/pete/DjangoDev/django_bp_start/.venv/lib/python3.13/site-packages/psycopg/cursor.py", line 97, in execute
    raise ex.with_traceback(None)
psycopg.errors.UndefinedColumn: column tenants_tenant.slug does not exist
LINE 1: ...enants_tenant"."name", "tenants_tenant"."domain", "tenants_t...
                                                             ^

The above exception was the direct cause of the following exception:

Traceback (most recent call last):
  File "/home/pete/DjangoDev/django_bp_start/.venv/lib/python3.13/site-packages/django/core/handlers/exception.py", line 55, in inner
    response = get_response(request)
  File "/home/pete/DjangoDev/django_bp_start/config/middleware.py", line 16, in __call__
    request.tenant = Tenant.objects.get(slug="default")
                     ~~~~~~~~~~~~~~~~~~^^^^^^^^^^^^^^^^
  File "/home/pete/DjangoDev/django_bp_start/.venv/lib/python3.13/site-packages/django/db/models/manager.py", line 87, in manager_method
    return getattr(self.get_queryset(), name)(*args, **kwargs)
           ~~~~~~~~~~~~~~~~~~~~~~~~~~~~~~~~~~^^^^^^^^^^^^^^^^^
  File "/home/pete/DjangoDev/django_bp_start/.venv/lib/python3.13/site-packages/django/db/models/query.py", line 629, in get
    num = len(clone)
  File "/home/pete/DjangoDev/django_bp_start/.venv/lib/python3.13/site-packages/django/db/models/query.py", line 366, in __len__
    self._fetch_all()
    ~~~~~~~~~~~~~~~^^
  File "/home/pete/DjangoDev/django_bp_start/.venv/lib/python3.13/site-packages/django/db/models/query.py", line 1949, in _fetch_all
    self._result_cache = list(self._iterable_class(self))
                         ~~~~^^^^^^^^^^^^^^^^^^^^^^^^^^^^
  File "/home/pete/DjangoDev/django_bp_start/.venv/lib/python3.13/site-packages/django/db/models/query.py", line 91, in __iter__
    results = compiler.execute_sql(
        chunked_fetch=self.chunked_fetch, chunk_size=self.chunk_size
    )
  File "/home/pete/DjangoDev/django_bp_start/.venv/lib/python3.13/site-packages/django/db/models/sql/compiler.py", line 1623, in execute_sql
    cursor.execute(sql, params)
    ~~~~~~~~~~~~~~^^^^^^^^^^^^^
  File "/home/pete/DjangoDev/django_bp_start/.venv/lib/python3.13/site-packages/django/db/backends/utils.py", line 122, in execute
    return super().execute(sql, params)
           ~~~~~~~~~~~~~~~^^^^^^^^^^^^^
  File "/home/pete/DjangoDev/django_bp_start/.venv/lib/python3.13/site-packages/django/db/backends/utils.py", line 79, in execute
    return self._execute_with_wrappers(
           ~~~~~~~~~~~~~~~~~~~~~~~~~~~^
        sql, params, many=False, executor=self._execute
        ^^^^^^^^^^^^^^^^^^^^^^^^^^^^^^^^^^^^^^^^^^^^^^^
    )
    ^
  File "/home/pete/DjangoDev/django_bp_start/.venv/lib/python3.13/site-packages/django/db/backends/utils.py", line 92, in _execute_with_wrappers
    return executor(sql, params, many, context)
  File "/home/pete/DjangoDev/django_bp_start/.venv/lib/python3.13/site-packages/django/db/backends/utils.py", line 100, in _execute
    with self.db.wrap_database_errors:
         ^^^^^^^^^^^^^^^^^^^^^^^^^^^^
  File "/home/pete/DjangoDev/django_bp_start/.venv/lib/python3.13/site-packages/django/db/utils.py", line 91, in __exit__
    raise dj_exc_value.with_traceback(traceback) from exc_value
  File "/home/pete/DjangoDev/django_bp_start/.venv/lib/python3.13/site-packages/django/db/backends/utils.py", line 105, in _execute
    return self.cursor.execute(sql, params)
           ~~~~~~~~~~~~~~~~~~~^^^^^^^^^^^^^
  File "/home/pete/DjangoDev/django_bp_start/.venv/lib/python3.13/site-packages/psycopg/cursor.py", line 97, in execute
    raise ex.with_traceback(None)
django.db.utils.ProgrammingError: column tenants_tenant.slug does not exist
LINE 1: ...enants_tenant"."name", "tenants_tenant"."domain", "tenants_t...
                                                             ^
ERROR 2025-10-03 11:29:30,261 basehttp 59111 139665507083968 "GET /api/tenants/ HTTP/1.1" 500 142618
INFO 2025-10-03 11:32:59,418 autoreload 59111 139665607050688 /home/pete/DjangoDev/django_bp_start/config/middleware.py changed, reloading.
INFO 2025-10-03 11:32:59,727 autoreload 59274 140186386978240 Watching for file changes with StatReloader
ERROR 2025-10-03 11:33:10,511 log 59274 140186286548672 Internal Server Error: /api/tenants/
Traceback (most recent call last):
  File "/home/pete/DjangoDev/django_bp_start/.venv/lib/python3.13/site-packages/django/db/backends/utils.py", line 105, in _execute
    return self.cursor.execute(sql, params)
           ~~~~~~~~~~~~~~~~~~~^^^^^^^^^^^^^
  File "/home/pete/DjangoDev/django_bp_start/.venv/lib/python3.13/site-packages/psycopg/cursor.py", line 97, in execute
    raise ex.with_traceback(None)
psycopg.errors.UndefinedColumn: column tenants_tenant.slug does not exist
LINE 1: ...enants_tenant"."name", "tenants_tenant"."domain", "tenants_t...
                                                             ^

The above exception was the direct cause of the following exception:

Traceback (most recent call last):
  File "/home/pete/DjangoDev/django_bp_start/.venv/lib/python3.13/site-packages/django/core/handlers/exception.py", line 55, in inner
    response = get_response(request)
  File "/home/pete/DjangoDev/django_bp_start/config/middleware.py", line 16, in __call__
    request.tenant = Tenant.objects.get(name="makeitexist.net")
                     ~~~~~~~~~~~~~~~~~~^^^^^^^^^^^^^^^^^^^^^^^^
  File "/home/pete/DjangoDev/django_bp_start/.venv/lib/python3.13/site-packages/django/db/models/manager.py", line 87, in manager_method
    return getattr(self.get_queryset(), name)(*args, **kwargs)
           ~~~~~~~~~~~~~~~~~~~~~~~~~~~~~~~~~~^^^^^^^^^^^^^^^^^
  File "/home/pete/DjangoDev/django_bp_start/.venv/lib/python3.13/site-packages/django/db/models/query.py", line 629, in get
    num = len(clone)
  File "/home/pete/DjangoDev/django_bp_start/.venv/lib/python3.13/site-packages/django/db/models/query.py", line 366, in __len__
    self._fetch_all()
    ~~~~~~~~~~~~~~~^^
  File "/home/pete/DjangoDev/django_bp_start/.venv/lib/python3.13/site-packages/django/db/models/query.py", line 1949, in _fetch_all
    self._result_cache = list(self._iterable_class(self))
                         ~~~~^^^^^^^^^^^^^^^^^^^^^^^^^^^^
  File "/home/pete/DjangoDev/django_bp_start/.venv/lib/python3.13/site-packages/django/db/models/query.py", line 91, in __iter__
    results = compiler.execute_sql(
        chunked_fetch=self.chunked_fetch, chunk_size=self.chunk_size
    )
  File "/home/pete/DjangoDev/django_bp_start/.venv/lib/python3.13/site-packages/django/db/models/sql/compiler.py", line 1623, in execute_sql
    cursor.execute(sql, params)
    ~~~~~~~~~~~~~~^^^^^^^^^^^^^
  File "/home/pete/DjangoDev/django_bp_start/.venv/lib/python3.13/site-packages/django/db/backends/utils.py", line 122, in execute
    return super().execute(sql, params)
           ~~~~~~~~~~~~~~~^^^^^^^^^^^^^
  File "/home/pete/DjangoDev/django_bp_start/.venv/lib/python3.13/site-packages/django/db/backends/utils.py", line 79, in execute
    return self._execute_with_wrappers(
           ~~~~~~~~~~~~~~~~~~~~~~~~~~~^
        sql, params, many=False, executor=self._execute
        ^^^^^^^^^^^^^^^^^^^^^^^^^^^^^^^^^^^^^^^^^^^^^^^
    )
    ^
  File "/home/pete/DjangoDev/django_bp_start/.venv/lib/python3.13/site-packages/django/db/backends/utils.py", line 92, in _execute_with_wrappers
    return executor(sql, params, many, context)
  File "/home/pete/DjangoDev/django_bp_start/.venv/lib/python3.13/site-packages/django/db/backends/utils.py", line 100, in _execute
    with self.db.wrap_database_errors:
         ^^^^^^^^^^^^^^^^^^^^^^^^^^^^
  File "/home/pete/DjangoDev/django_bp_start/.venv/lib/python3.13/site-packages/django/db/utils.py", line 91, in __exit__
    raise dj_exc_value.with_traceback(traceback) from exc_value
  File "/home/pete/DjangoDev/django_bp_start/.venv/lib/python3.13/site-packages/django/db/backends/utils.py", line 105, in _execute
    return self.cursor.execute(sql, params)
           ~~~~~~~~~~~~~~~~~~~^^^^^^^^^^^^^
  File "/home/pete/DjangoDev/django_bp_start/.venv/lib/python3.13/site-packages/psycopg/cursor.py", line 97, in execute
    raise ex.with_traceback(None)
django.db.utils.ProgrammingError: column tenants_tenant.slug does not exist
LINE 1: ...enants_tenant"."name", "tenants_tenant"."domain", "tenants_t...
                                                             ^
ERROR 2025-10-03 11:33:10,514 basehttp 59274 140186286548672 "GET /api/tenants/ HTTP/1.1" 500 142738
INFO 2025-10-03 11:33:26,492 autoreload 59328 140330956457408 Watching for file changes with StatReloader
ERROR 2025-10-03 11:33:30,885 log 59328 140330856867520 Internal Server Error: /api/tenants/
Traceback (most recent call last):
  File "/home/pete/DjangoDev/django_bp_start/.venv/lib/python3.13/site-packages/django/db/backends/utils.py", line 105, in _execute
    return self.cursor.execute(sql, params)
           ~~~~~~~~~~~~~~~~~~~^^^^^^^^^^^^^
  File "/home/pete/DjangoDev/django_bp_start/.venv/lib/python3.13/site-packages/psycopg/cursor.py", line 97, in execute
    raise ex.with_traceback(None)
psycopg.errors.UndefinedColumn: column tenants_tenant.slug does not exist
LINE 1: ...enants_tenant"."name", "tenants_tenant"."domain", "tenants_t...
                                                             ^

The above exception was the direct cause of the following exception:

Traceback (most recent call last):
  File "/home/pete/DjangoDev/django_bp_start/.venv/lib/python3.13/site-packages/django/core/handlers/exception.py", line 55, in inner
    response = get_response(request)
  File "/home/pete/DjangoDev/django_bp_start/config/middleware.py", line 16, in __call__
    request.tenant = Tenant.objects.get(name="makeitexist.net")
                     ~~~~~~~~~~~~~~~~~~^^^^^^^^^^^^^^^^^^^^^^^^
  File "/home/pete/DjangoDev/django_bp_start/.venv/lib/python3.13/site-packages/django/db/models/manager.py", line 87, in manager_method
    return getattr(self.get_queryset(), name)(*args, **kwargs)
           ~~~~~~~~~~~~~~~~~~~~~~~~~~~~~~~~~~^^^^^^^^^^^^^^^^^
  File "/home/pete/DjangoDev/django_bp_start/.venv/lib/python3.13/site-packages/django/db/models/query.py", line 629, in get
    num = len(clone)
  File "/home/pete/DjangoDev/django_bp_start/.venv/lib/python3.13/site-packages/django/db/models/query.py", line 366, in __len__
    self._fetch_all()
    ~~~~~~~~~~~~~~~^^
  File "/home/pete/DjangoDev/django_bp_start/.venv/lib/python3.13/site-packages/django/db/models/query.py", line 1949, in _fetch_all
    self._result_cache = list(self._iterable_class(self))
                         ~~~~^^^^^^^^^^^^^^^^^^^^^^^^^^^^
  File "/home/pete/DjangoDev/django_bp_start/.venv/lib/python3.13/site-packages/django/db/models/query.py", line 91, in __iter__
    results = compiler.execute_sql(
        chunked_fetch=self.chunked_fetch, chunk_size=self.chunk_size
    )
  File "/home/pete/DjangoDev/django_bp_start/.venv/lib/python3.13/site-packages/django/db/models/sql/compiler.py", line 1623, in execute_sql
    cursor.execute(sql, params)
    ~~~~~~~~~~~~~~^^^^^^^^^^^^^
  File "/home/pete/DjangoDev/django_bp_start/.venv/lib/python3.13/site-packages/django/db/backends/utils.py", line 122, in execute
    return super().execute(sql, params)
           ~~~~~~~~~~~~~~~^^^^^^^^^^^^^
  File "/home/pete/DjangoDev/django_bp_start/.venv/lib/python3.13/site-packages/django/db/backends/utils.py", line 79, in execute
    return self._execute_with_wrappers(
           ~~~~~~~~~~~~~~~~~~~~~~~~~~~^
        sql, params, many=False, executor=self._execute
        ^^^^^^^^^^^^^^^^^^^^^^^^^^^^^^^^^^^^^^^^^^^^^^^
    )
    ^
  File "/home/pete/DjangoDev/django_bp_start/.venv/lib/python3.13/site-packages/django/db/backends/utils.py", line 92, in _execute_with_wrappers
    return executor(sql, params, many, context)
  File "/home/pete/DjangoDev/django_bp_start/.venv/lib/python3.13/site-packages/django/db/backends/utils.py", line 100, in _execute
    with self.db.wrap_database_errors:
         ^^^^^^^^^^^^^^^^^^^^^^^^^^^^
  File "/home/pete/DjangoDev/django_bp_start/.venv/lib/python3.13/site-packages/django/db/utils.py", line 91, in __exit__
    raise dj_exc_value.with_traceback(traceback) from exc_value
  File "/home/pete/DjangoDev/django_bp_start/.venv/lib/python3.13/site-packages/django/db/backends/utils.py", line 105, in _execute
    return self.cursor.execute(sql, params)
           ~~~~~~~~~~~~~~~~~~~^^^^^^^^^^^^^
  File "/home/pete/DjangoDev/django_bp_start/.venv/lib/python3.13/site-packages/psycopg/cursor.py", line 97, in execute
    raise ex.with_traceback(None)
django.db.utils.ProgrammingError: column tenants_tenant.slug does not exist
LINE 1: ...enants_tenant"."name", "tenants_tenant"."domain", "tenants_t...
                                                             ^
ERROR 2025-10-03 11:33:30,888 basehttp 59328 140330856867520 "GET /api/tenants/ HTTP/1.1" 500 142738
INFO 2025-10-03 11:35:02,584 autoreload 59328 140330956457408 /home/pete/DjangoDev/django_bp_start/apps/tenants/serializers.py changed, reloading.
INFO 2025-10-03 11:35:02,886 autoreload 59377 140168299046336 Watching for file changes with StatReloader
INFO 2025-10-03 11:35:39,193 autoreload 59430 140171202983360 Watching for file changes with StatReloader
ERROR 2025-10-03 11:35:59,627 log 59430 140171103168192 Internal Server Error: /api
Traceback (most recent call last):
  File "/home/pete/DjangoDev/django_bp_start/.venv/lib/python3.13/site-packages/django/db/backends/utils.py", line 105, in _execute
    return self.cursor.execute(sql, params)
           ~~~~~~~~~~~~~~~~~~~^^^^^^^^^^^^^
  File "/home/pete/DjangoDev/django_bp_start/.venv/lib/python3.13/site-packages/psycopg/cursor.py", line 97, in execute
    raise ex.with_traceback(None)
psycopg.errors.UndefinedColumn: column tenants_tenant.slug does not exist
LINE 1: ...enants_tenant"."name", "tenants_tenant"."domain", "tenants_t...
                                                             ^

The above exception was the direct cause of the following exception:

Traceback (most recent call last):
  File "/home/pete/DjangoDev/django_bp_start/.venv/lib/python3.13/site-packages/django/core/handlers/exception.py", line 55, in inner
    response = get_response(request)
  File "/home/pete/DjangoDev/django_bp_start/config/middleware.py", line 16, in __call__
    request.tenant = Tenant.objects.get(name="makeitexist.net")
                     ~~~~~~~~~~~~~~~~~~^^^^^^^^^^^^^^^^^^^^^^^^
  File "/home/pete/DjangoDev/django_bp_start/.venv/lib/python3.13/site-packages/django/db/models/manager.py", line 87, in manager_method
    return getattr(self.get_queryset(), name)(*args, **kwargs)
           ~~~~~~~~~~~~~~~~~~~~~~~~~~~~~~~~~~^^^^^^^^^^^^^^^^^
  File "/home/pete/DjangoDev/django_bp_start/.venv/lib/python3.13/site-packages/django/db/models/query.py", line 629, in get
    num = len(clone)
  File "/home/pete/DjangoDev/django_bp_start/.venv/lib/python3.13/site-packages/django/db/models/query.py", line 366, in __len__
    self._fetch_all()
    ~~~~~~~~~~~~~~~^^
  File "/home/pete/DjangoDev/django_bp_start/.venv/lib/python3.13/site-packages/django/db/models/query.py", line 1949, in _fetch_all
    self._result_cache = list(self._iterable_class(self))
                         ~~~~^^^^^^^^^^^^^^^^^^^^^^^^^^^^
  File "/home/pete/DjangoDev/django_bp_start/.venv/lib/python3.13/site-packages/django/db/models/query.py", line 91, in __iter__
    results = compiler.execute_sql(
        chunked_fetch=self.chunked_fetch, chunk_size=self.chunk_size
    )
  File "/home/pete/DjangoDev/django_bp_start/.venv/lib/python3.13/site-packages/django/db/models/sql/compiler.py", line 1623, in execute_sql
    cursor.execute(sql, params)
    ~~~~~~~~~~~~~~^^^^^^^^^^^^^
  File "/home/pete/DjangoDev/django_bp_start/.venv/lib/python3.13/site-packages/django/db/backends/utils.py", line 122, in execute
    return super().execute(sql, params)
           ~~~~~~~~~~~~~~~^^^^^^^^^^^^^
  File "/home/pete/DjangoDev/django_bp_start/.venv/lib/python3.13/site-packages/django/db/backends/utils.py", line 79, in execute
    return self._execute_with_wrappers(
           ~~~~~~~~~~~~~~~~~~~~~~~~~~~^
        sql, params, many=False, executor=self._execute
        ^^^^^^^^^^^^^^^^^^^^^^^^^^^^^^^^^^^^^^^^^^^^^^^
    )
    ^
  File "/home/pete/DjangoDev/django_bp_start/.venv/lib/python3.13/site-packages/django/db/backends/utils.py", line 92, in _execute_with_wrappers
    return executor(sql, params, many, context)
  File "/home/pete/DjangoDev/django_bp_start/.venv/lib/python3.13/site-packages/django/db/backends/utils.py", line 100, in _execute
    with self.db.wrap_database_errors:
         ^^^^^^^^^^^^^^^^^^^^^^^^^^^^
  File "/home/pete/DjangoDev/django_bp_start/.venv/lib/python3.13/site-packages/django/db/utils.py", line 91, in __exit__
    raise dj_exc_value.with_traceback(traceback) from exc_value
  File "/home/pete/DjangoDev/django_bp_start/.venv/lib/python3.13/site-packages/django/db/backends/utils.py", line 105, in _execute
    return self.cursor.execute(sql, params)
           ~~~~~~~~~~~~~~~~~~~^^^^^^^^^^^^^
  File "/home/pete/DjangoDev/django_bp_start/.venv/lib/python3.13/site-packages/psycopg/cursor.py", line 97, in execute
    raise ex.with_traceback(None)
django.db.utils.ProgrammingError: column tenants_tenant.slug does not exist
LINE 1: ...enants_tenant"."name", "tenants_tenant"."domain", "tenants_t...
                                                             ^
ERROR 2025-10-03 11:35:59,630 basehttp 59430 140171103168192 "GET /api HTTP/1.1" 500 142547
INFO 2025-10-03 11:38:21,537 autoreload 59931 140047306331584 Watching for file changes with StatReloader
ERROR 2025-10-03 11:38:35,464 log 59931 140047207622336 Internal Server Error: /
Traceback (most recent call last):
  File "/home/pete/DjangoDev/django_bp_start/.venv/lib/python3.13/site-packages/django/db/backends/utils.py", line 105, in _execute
    return self.cursor.execute(sql, params)
           ~~~~~~~~~~~~~~~~~~~^^^^^^^^^^^^^
  File "/home/pete/DjangoDev/django_bp_start/.venv/lib/python3.13/site-packages/psycopg/cursor.py", line 97, in execute
    raise ex.with_traceback(None)
psycopg.errors.UndefinedColumn: column tenants_tenant.slug does not exist
LINE 1: ...enants_tenant"."name", "tenants_tenant"."domain", "tenants_t...
                                                             ^

The above exception was the direct cause of the following exception:

Traceback (most recent call last):
  File "/home/pete/DjangoDev/django_bp_start/.venv/lib/python3.13/site-packages/django/core/handlers/exception.py", line 55, in inner
    response = get_response(request)
  File "/home/pete/DjangoDev/django_bp_start/config/middleware.py", line 16, in __call__
    request.tenant = Tenant.objects.get(name="makeitexist.net")
                     ~~~~~~~~~~~~~~~~~~^^^^^^^^^^^^^^^^^^^^^^^^
  File "/home/pete/DjangoDev/django_bp_start/.venv/lib/python3.13/site-packages/django/db/models/manager.py", line 87, in manager_method
    return getattr(self.get_queryset(), name)(*args, **kwargs)
           ~~~~~~~~~~~~~~~~~~~~~~~~~~~~~~~~~~^^^^^^^^^^^^^^^^^
  File "/home/pete/DjangoDev/django_bp_start/.venv/lib/python3.13/site-packages/django/db/models/query.py", line 629, in get
    num = len(clone)
  File "/home/pete/DjangoDev/django_bp_start/.venv/lib/python3.13/site-packages/django/db/models/query.py", line 366, in __len__
    self._fetch_all()
    ~~~~~~~~~~~~~~~^^
  File "/home/pete/DjangoDev/django_bp_start/.venv/lib/python3.13/site-packages/django/db/models/query.py", line 1949, in _fetch_all
    self._result_cache = list(self._iterable_class(self))
                         ~~~~^^^^^^^^^^^^^^^^^^^^^^^^^^^^
  File "/home/pete/DjangoDev/django_bp_start/.venv/lib/python3.13/site-packages/django/db/models/query.py", line 91, in __iter__
    results = compiler.execute_sql(
        chunked_fetch=self.chunked_fetch, chunk_size=self.chunk_size
    )
  File "/home/pete/DjangoDev/django_bp_start/.venv/lib/python3.13/site-packages/django/db/models/sql/compiler.py", line 1623, in execute_sql
    cursor.execute(sql, params)
    ~~~~~~~~~~~~~~^^^^^^^^^^^^^
  File "/home/pete/DjangoDev/django_bp_start/.venv/lib/python3.13/site-packages/django/db/backends/utils.py", line 122, in execute
    return super().execute(sql, params)
           ~~~~~~~~~~~~~~~^^^^^^^^^^^^^
  File "/home/pete/DjangoDev/django_bp_start/.venv/lib/python3.13/site-packages/django/db/backends/utils.py", line 79, in execute
    return self._execute_with_wrappers(
           ~~~~~~~~~~~~~~~~~~~~~~~~~~~^
        sql, params, many=False, executor=self._execute
        ^^^^^^^^^^^^^^^^^^^^^^^^^^^^^^^^^^^^^^^^^^^^^^^
    )
    ^
  File "/home/pete/DjangoDev/django_bp_start/.venv/lib/python3.13/site-packages/django/db/backends/utils.py", line 92, in _execute_with_wrappers
    return executor(sql, params, many, context)
  File "/home/pete/DjangoDev/django_bp_start/.venv/lib/python3.13/site-packages/django/db/backends/utils.py", line 100, in _execute
    with self.db.wrap_database_errors:
         ^^^^^^^^^^^^^^^^^^^^^^^^^^^^
  File "/home/pete/DjangoDev/django_bp_start/.venv/lib/python3.13/site-packages/django/db/utils.py", line 91, in __exit__
    raise dj_exc_value.with_traceback(traceback) from exc_value
  File "/home/pete/DjangoDev/django_bp_start/.venv/lib/python3.13/site-packages/django/db/backends/utils.py", line 105, in _execute
    return self.cursor.execute(sql, params)
           ~~~~~~~~~~~~~~~~~~~^^^^^^^^^^^^^
  File "/home/pete/DjangoDev/django_bp_start/.venv/lib/python3.13/site-packages/psycopg/cursor.py", line 97, in execute
    raise ex.with_traceback(None)
django.db.utils.ProgrammingError: column tenants_tenant.slug does not exist
LINE 1: ...enants_tenant"."name", "tenants_tenant"."domain", "tenants_t...
                                                             ^
ERROR 2025-10-03 11:38:35,467 basehttp 59931 140047207622336 "GET / HTTP/1.1" 500 142520
INFO 2025-10-03 11:51:05,322 autoreload 60873 140566943983040 Watching for file changes with StatReloader
ERROR 2025-10-03 11:51:11,000 log 60873 140566845187776 Internal Server Error: /
Traceback (most recent call last):
  File "/home/pete/DjangoDev/django_bp_start/.venv/lib/python3.13/site-packages/django/db/backends/utils.py", line 105, in _execute
    return self.cursor.execute(sql, params)
           ~~~~~~~~~~~~~~~~~~~^^^^^^^^^^^^^
  File "/home/pete/DjangoDev/django_bp_start/.venv/lib/python3.13/site-packages/psycopg/cursor.py", line 97, in execute
    raise ex.with_traceback(None)
psycopg.errors.UndefinedTable: relation "tenants_tenant" does not exist
LINE 1: ...ts_tenant"."domain", "tenants_tenant"."slug" FROM "tenants_t...
                                                             ^

The above exception was the direct cause of the following exception:

Traceback (most recent call last):
  File "/home/pete/DjangoDev/django_bp_start/.venv/lib/python3.13/site-packages/django/core/handlers/exception.py", line 55, in inner
    response = get_response(request)
  File "/home/pete/DjangoDev/django_bp_start/config/middleware.py", line 16, in __call__
    request.tenant = Tenant.objects.get(name="makeitexist.net")
                     ~~~~~~~~~~~~~~~~~~^^^^^^^^^^^^^^^^^^^^^^^^
  File "/home/pete/DjangoDev/django_bp_start/.venv/lib/python3.13/site-packages/django/db/models/manager.py", line 87, in manager_method
    return getattr(self.get_queryset(), name)(*args, **kwargs)
           ~~~~~~~~~~~~~~~~~~~~~~~~~~~~~~~~~~^^^^^^^^^^^^^^^^^
  File "/home/pete/DjangoDev/django_bp_start/.venv/lib/python3.13/site-packages/django/db/models/query.py", line 629, in get
    num = len(clone)
  File "/home/pete/DjangoDev/django_bp_start/.venv/lib/python3.13/site-packages/django/db/models/query.py", line 366, in __len__
    self._fetch_all()
    ~~~~~~~~~~~~~~~^^
  File "/home/pete/DjangoDev/django_bp_start/.venv/lib/python3.13/site-packages/django/db/models/query.py", line 1949, in _fetch_all
    self._result_cache = list(self._iterable_class(self))
                         ~~~~^^^^^^^^^^^^^^^^^^^^^^^^^^^^
  File "/home/pete/DjangoDev/django_bp_start/.venv/lib/python3.13/site-packages/django/db/models/query.py", line 91, in __iter__
    results = compiler.execute_sql(
        chunked_fetch=self.chunked_fetch, chunk_size=self.chunk_size
    )
  File "/home/pete/DjangoDev/django_bp_start/.venv/lib/python3.13/site-packages/django/db/models/sql/compiler.py", line 1623, in execute_sql
    cursor.execute(sql, params)
    ~~~~~~~~~~~~~~^^^^^^^^^^^^^
  File "/home/pete/DjangoDev/django_bp_start/.venv/lib/python3.13/site-packages/django/db/backends/utils.py", line 122, in execute
    return super().execute(sql, params)
           ~~~~~~~~~~~~~~~^^^^^^^^^^^^^
  File "/home/pete/DjangoDev/django_bp_start/.venv/lib/python3.13/site-packages/django/db/backends/utils.py", line 79, in execute
    return self._execute_with_wrappers(
           ~~~~~~~~~~~~~~~~~~~~~~~~~~~^
        sql, params, many=False, executor=self._execute
        ^^^^^^^^^^^^^^^^^^^^^^^^^^^^^^^^^^^^^^^^^^^^^^^
    )
    ^
  File "/home/pete/DjangoDev/django_bp_start/.venv/lib/python3.13/site-packages/django/db/backends/utils.py", line 92, in _execute_with_wrappers
    return executor(sql, params, many, context)
  File "/home/pete/DjangoDev/django_bp_start/.venv/lib/python3.13/site-packages/django/db/backends/utils.py", line 100, in _execute
    with self.db.wrap_database_errors:
         ^^^^^^^^^^^^^^^^^^^^^^^^^^^^
  File "/home/pete/DjangoDev/django_bp_start/.venv/lib/python3.13/site-packages/django/db/utils.py", line 91, in __exit__
    raise dj_exc_value.with_traceback(traceback) from exc_value
  File "/home/pete/DjangoDev/django_bp_start/.venv/lib/python3.13/site-packages/django/db/backends/utils.py", line 105, in _execute
    return self.cursor.execute(sql, params)
           ~~~~~~~~~~~~~~~~~~~^^^^^^^^^^^^^
  File "/home/pete/DjangoDev/django_bp_start/.venv/lib/python3.13/site-packages/psycopg/cursor.py", line 97, in execute
    raise ex.with_traceback(None)
django.db.utils.ProgrammingError: relation "tenants_tenant" does not exist
LINE 1: ...ts_tenant"."domain", "tenants_tenant"."slug" FROM "tenants_t...
                                                             ^
ERROR 2025-10-03 11:51:11,003 basehttp 60873 140566845187776 "GET / HTTP/1.1" 500 142635
INFO 2025-10-03 12:07:52,450 autoreload 62076 140358619547072 Watching for file changes with StatReloader
WARNING 2025-10-03 12:08:12,384 log 62076 140358520399552 Not Found: /
WARNING 2025-10-03 12:08:12,384 basehttp 62076 140358520399552 "GET / HTTP/1.1" 404 1794
WARNING 2025-10-03 12:08:12,428 log 62076 140358520399552 Not Found: /favicon.ico
WARNING 2025-10-03 12:08:12,428 basehttp 62076 140358520399552 "GET /favicon.ico HTTP/1.1" 404 1816
WARNING 2025-10-03 12:08:24,778 log 62076 140358520399552 Not Found: /admin
WARNING 2025-10-03 12:08:24,778 basehttp 62076 140358520399552 "GET /admin HTTP/1.1" 404 1804
INFO 2025-10-03 12:11:33,767 autoreload 62076 140358619547072 /home/pete/DjangoDev/django_bp_start/config/middleware.py changed, reloading.
INFO 2025-10-03 12:11:34,078 autoreload 62249 140469263037888 Watching for file changes with StatReloader
INFO 2025-10-03 12:11:36,225 autoreload 62249 140469263037888 /home/pete/DjangoDev/django_bp_start/config/middleware.py changed, reloading.
INFO 2025-10-03 12:11:36,536 autoreload 62256 140619197109696 Watching for file changes with StatReloader
INFO 2025-10-03 12:11:40,893 autoreload 62286 140284309231040 Watching for file changes with StatReloader
ERROR 2025-10-03 12:11:46,155 log 62286 140284208867008 Internal Server Error: /admin
Traceback (most recent call last):
  File "/home/pete/DjangoDev/django_bp_start/.venv/lib/python3.13/site-packages/django/core/handlers/exception.py", line 55, in inner
    response = get_response(request)
  File "/home/pete/DjangoDev/django_bp_start/config/middleware.py", line 26, in __call__
    raise NotFound(
        detail="No tenants found. Please create the first tenant."
    )
rest_framework.exceptions.NotFound: No tenants found. Please create the first tenant.
ERROR 2025-10-03 12:11:46,155 basehttp 62286 140284208867008 "GET /admin HTTP/1.1" 500 68089
INFO 2025-10-03 12:13:15,268 autoreload 62380 140356688152000 Watching for file changes with StatReloader
ERROR 2025-10-03 12:13:19,942 log 62380 140356588922560 Internal Server Error: /admin
Traceback (most recent call last):
  File "/home/pete/DjangoDev/django_bp_start/.venv/lib/python3.13/site-packages/django/core/handlers/exception.py", line 55, in inner
    response = get_response(request)
  File "/home/pete/DjangoDev/django_bp_start/config/middleware.py", line 29, in __call__
    raise NotFound(
        detail="No tenants found. Please create the first tenant."
    )
rest_framework.exceptions.NotFound: No tenants found. Please create the first tenant.
ERROR 2025-10-03 12:13:19,943 basehttp 62380 140356588922560 "GET /admin HTTP/1.1" 500 68089
ERROR 2025-10-03 12:13:24,945 log 62380 140356588922560 Internal Server Error: /admin
Traceback (most recent call last):
  File "/home/pete/DjangoDev/django_bp_start/.venv/lib/python3.13/site-packages/django/core/handlers/exception.py", line 55, in inner
    response = get_response(request)
  File "/home/pete/DjangoDev/django_bp_start/config/middleware.py", line 29, in __call__
    raise NotFound(
        detail="No tenants found. Please create the first tenant."
    )
rest_framework.exceptions.NotFound: No tenants found. Please create the first tenant.
ERROR 2025-10-03 12:13:24,945 basehttp 62380 140356588922560 "GET /admin HTTP/1.1" 500 68354
ERROR 2025-10-03 12:13:25,000 log 62380 140356588922560 Internal Server Error: /favicon.ico
Traceback (most recent call last):
  File "/home/pete/DjangoDev/django_bp_start/.venv/lib/python3.13/site-packages/django/core/handlers/exception.py", line 55, in inner
    response = get_response(request)
  File "/home/pete/DjangoDev/django_bp_start/config/middleware.py", line 29, in __call__
    raise NotFound(
        detail="No tenants found. Please create the first tenant."
    )
rest_framework.exceptions.NotFound: No tenants found. Please create the first tenant.
ERROR 2025-10-03 12:13:25,001 basehttp 62380 140356588922560 "GET /favicon.ico HTTP/1.1" 500 68291
INFO 2025-10-03 12:14:53,665 autoreload 62512 140085203420608 Watching for file changes with StatReloader
ERROR 2025-10-03 12:15:00,427 log 62512 140085103158976 Internal Server Error: /admin
Traceback (most recent call last):
  File "/home/pete/DjangoDev/django_bp_start/.venv/lib/python3.13/site-packages/django/core/handlers/exception.py", line 55, in inner
    response = get_response(request)
  File "/home/pete/DjangoDev/django_bp_start/config/middleware.py", line 29, in __call__
    raise NotFound(
        detail="No tenants found. Please create the first tenant."
    )
rest_framework.exceptions.NotFound: No tenants found. Please create the first tenant.
ERROR 2025-10-03 12:15:00,427 basehttp 62512 140085103158976 "GET /admin HTTP/1.1" 500 68089
ERROR 2025-10-03 12:15:09,745 log 62512 140085103158976 Internal Server Error: /admin
Traceback (most recent call last):
  File "/home/pete/DjangoDev/django_bp_start/.venv/lib/python3.13/site-packages/django/core/handlers/exception.py", line 55, in inner
    response = get_response(request)
  File "/home/pete/DjangoDev/django_bp_start/config/middleware.py", line 29, in __call__
    raise NotFound(
        detail="No tenants found. Please create the first tenant."
    )
rest_framework.exceptions.NotFound: No tenants found. Please create the first tenant.
ERROR 2025-10-03 12:15:09,745 basehttp 62512 140085103158976 "GET /admin HTTP/1.1" 500 68354
ERROR 2025-10-03 12:15:09,799 log 62512 140085103158976 Internal Server Error: /favicon.ico
Traceback (most recent call last):
  File "/home/pete/DjangoDev/django_bp_start/.venv/lib/python3.13/site-packages/django/core/handlers/exception.py", line 55, in inner
    response = get_response(request)
  File "/home/pete/DjangoDev/django_bp_start/config/middleware.py", line 29, in __call__
    raise NotFound(
        detail="No tenants found. Please create the first tenant."
    )
rest_framework.exceptions.NotFound: No tenants found. Please create the first tenant.
ERROR 2025-10-03 12:15:09,800 basehttp 62512 140085103158976 "GET /favicon.ico HTTP/1.1" 500 68291
INFO 2025-10-03 12:16:02,506 autoreload 62512 140085203420608 /home/pete/DjangoDev/django_bp_start/config/middleware.py changed, reloading.
INFO 2025-10-03 12:16:02,817 autoreload 62571 140360249566656 Watching for file changes with StatReloader
INFO 2025-10-03 12:16:05,970 autoreload 62571 140360249566656 /home/pete/DjangoDev/django_bp_start/config/middleware.py changed, reloading.
INFO 2025-10-03 12:16:13,747 autoreload 62608 140469963482560 Watching for file changes with StatReloader
ERROR 2025-10-03 12:16:18,718 log 62608 140469791094464 Internal Server Error: /admin
Traceback (most recent call last):
  File "/home/pete/DjangoDev/django_bp_start/.venv/lib/python3.13/site-packages/django/core/handlers/exception.py", line 55, in inner
    response = get_response(request)
  File "/home/pete/DjangoDev/django_bp_start/config/middleware.py", line 24, in __call__
    dev_tenant_domain = settings.DEV_TENANT_DOMAIN
                        ^^^^^^^^
NameError: name 'settings' is not defined
ERROR 2025-10-03 12:16:18,719 basehttp 62608 140469791094464 "GET /admin HTTP/1.1" 500 68411
ERROR 2025-10-03 12:16:18,743 log 62608 140469791094464 Internal Server Error: /favicon.ico
Traceback (most recent call last):
  File "/home/pete/DjangoDev/django_bp_start/.venv/lib/python3.13/site-packages/django/core/handlers/exception.py", line 55, in inner
    response = get_response(request)
  File "/home/pete/DjangoDev/django_bp_start/config/middleware.py", line 24, in __call__
    dev_tenant_domain = settings.DEV_TENANT_DOMAIN
                        ^^^^^^^^
NameError: name 'settings' is not defined
INFO 2025-10-03 12:18:45,391 autoreload 62608 140469963482560 /home/pete/DjangoDev/django_bp_start/config/middleware.py changed, reloading.
INFO 2025-10-03 12:18:45,705 autoreload 62803 139939362743744 Watching for file changes with StatReloader
ERROR 2025-10-03 12:18:52,123 log 62803 139939263014592 Internal Server Error: /admin
Traceback (most recent call last):
  File "/home/pete/DjangoDev/django_bp_start/.venv/lib/python3.13/site-packages/django/core/handlers/exception.py", line 55, in inner
    response = get_response(request)
  File "/home/pete/DjangoDev/django_bp_start/config/middleware.py", line 25, in __call__
    dev_tenant_domain = settings.DEV_TENANT_DOMAIN
                        ^^^^^^^^^^^^^^^^^^^^^^^^^^
  File "/home/pete/DjangoDev/django_bp_start/.venv/lib/python3.13/site-packages/django/conf/__init__.py", line 83, in __getattr__
    val = getattr(_wrapped, name)
AttributeError: 'Settings' object has no attribute 'DEV_TENANT_DOMAIN'
ERROR 2025-10-03 12:18:52,124 basehttp 62803 139939263014592 "GET /admin HTTP/1.1" 500 72962
INFO 2025-10-03 12:19:47,473 autoreload 62803 139939362743744 /home/pete/DjangoDev/django_bp_start/config/settings.py changed, reloading.
INFO 2025-10-03 12:19:47,777 autoreload 62858 140651006301632 Watching for file changes with StatReloader
ERROR 2025-10-03 12:19:52,433 log 62858 140650906379968 Internal Server Error: /admin
Traceback (most recent call last):
  File "/home/pete/DjangoDev/django_bp_start/config/middleware.py", line 26, in __call__
    request.tenant = Tenant.objects.get(domain=dev_tenant_domain)
                     ~~~~~~~~~~~~~~~~~~^^^^^^^^^^^^^^^^^^^^^^^^^^
  File "/home/pete/DjangoDev/django_bp_start/.venv/lib/python3.13/site-packages/django/db/models/manager.py", line 87, in manager_method
    return getattr(self.get_queryset(), name)(*args, **kwargs)
           ~~~~~~~~~~~~~~~~~~~~~~~~~~~~~~~~~~^^^^^^^^^^^^^^^^^
  File "/home/pete/DjangoDev/django_bp_start/.venv/lib/python3.13/site-packages/django/db/models/query.py", line 633, in get
    raise self.model.DoesNotExist(
        "%s matching query does not exist." % self.model._meta.object_name
    )
apps.tenants.models.Tenant.DoesNotExist: Tenant matching query does not exist.

During handling of the above exception, another exception occurred:

Traceback (most recent call last):
  File "/home/pete/DjangoDev/django_bp_start/.venv/lib/python3.13/site-packages/django/core/handlers/exception.py", line 55, in inner
    response = get_response(request)
  File "/home/pete/DjangoDev/django_bp_start/config/middleware.py", line 30, in __call__
    raise NotFound(detail="Tenant not found for this domain.")
rest_framework.exceptions.NotFound: Tenant not found for this domain.
ERROR 2025-10-03 12:19:52,435 basehttp 62858 140650906379968 "GET /admin HTTP/1.1" 500 82961
INFO 2025-10-03 12:21:06,720 autoreload 62858 140651006301632 /home/pete/DjangoDev/django_bp_start/config/middleware.py changed, reloading.
INFO 2025-10-03 12:21:07,030 autoreload 62914 139998534444480 Watching for file changes with StatReloader
INFO 2025-10-03 12:21:08,167 autoreload 62914 139998534444480 /home/pete/DjangoDev/django_bp_start/config/middleware.py changed, reloading.
INFO 2025-10-03 12:21:08,494 autoreload 62922 140337371723200 Watching for file changes with StatReloader
INFO 2025-10-03 12:21:11,486 autoreload 62951 140124369581504 Watching for file changes with StatReloader
ERROR 2025-10-03 12:21:31,424 log 62951 140124270618304 Internal Server Error: /admin
Traceback (most recent call last):
  File "/home/pete/DjangoDev/django_bp_start/config/middleware.py", line 25, in __call__
    request.tenant = Tenant.objects.get(domain=dev_tenant_domain)
                     ~~~~~~~~~~~~~~~~~~^^^^^^^^^^^^^^^^^^^^^^^^^^
  File "/home/pete/DjangoDev/django_bp_start/.venv/lib/python3.13/site-packages/django/db/models/manager.py", line 87, in manager_method
    return getattr(self.get_queryset(), name)(*args, **kwargs)
           ~~~~~~~~~~~~~~~~~~~~~~~~~~~~~~~~~~^^^^^^^^^^^^^^^^^
  File "/home/pete/DjangoDev/django_bp_start/.venv/lib/python3.13/site-packages/django/db/models/query.py", line 633, in get
    raise self.model.DoesNotExist(
        "%s matching query does not exist." % self.model._meta.object_name
    )
apps.tenants.models.Tenant.DoesNotExist: Tenant matching query does not exist.

During handling of the above exception, another exception occurred:

Traceback (most recent call last):
  File "/home/pete/DjangoDev/django_bp_start/.venv/lib/python3.13/site-packages/django/core/handlers/exception.py", line 55, in inner
    response = get_response(request)
  File "/home/pete/DjangoDev/django_bp_start/config/middleware.py", line 29, in __call__
    raise NotFound(detail="Tenant not found for this domain.")
rest_framework.exceptions.NotFound: Tenant not found for this domain.
ERROR 2025-10-03 12:21:31,426 basehttp 62951 140124270618304 "GET /admin HTTP/1.1" 500 82629
ERROR 2025-10-03 12:21:37,086 log 62951 140124270618304 Internal Server Error: /admin
Traceback (most recent call last):
  File "/home/pete/DjangoDev/django_bp_start/config/middleware.py", line 25, in __call__
    request.tenant = Tenant.objects.get(domain=dev_tenant_domain)
                     ~~~~~~~~~~~~~~~~~~^^^^^^^^^^^^^^^^^^^^^^^^^^
  File "/home/pete/DjangoDev/django_bp_start/.venv/lib/python3.13/site-packages/django/db/models/manager.py", line 87, in manager_method
    return getattr(self.get_queryset(), name)(*args, **kwargs)
           ~~~~~~~~~~~~~~~~~~~~~~~~~~~~~~~~~~^^^^^^^^^^^^^^^^^
  File "/home/pete/DjangoDev/django_bp_start/.venv/lib/python3.13/site-packages/django/db/models/query.py", line 633, in get
    raise self.model.DoesNotExist(
        "%s matching query does not exist." % self.model._meta.object_name
    )
apps.tenants.models.Tenant.DoesNotExist: Tenant matching query does not exist.

During handling of the above exception, another exception occurred:

Traceback (most recent call last):
  File "/home/pete/DjangoDev/django_bp_start/.venv/lib/python3.13/site-packages/django/core/handlers/exception.py", line 55, in inner
    response = get_response(request)
  File "/home/pete/DjangoDev/django_bp_start/config/middleware.py", line 29, in __call__
    raise NotFound(detail="Tenant not found for this domain.")
rest_framework.exceptions.NotFound: Tenant not found for this domain.
ERROR 2025-10-03 12:21:37,087 basehttp 62951 140124270618304 "GET /admin HTTP/1.1" 500 82894
ERROR 2025-10-03 12:21:37,143 log 62951 140124270618304 Internal Server Error: /favicon.ico
Traceback (most recent call last):
  File "/home/pete/DjangoDev/django_bp_start/config/middleware.py", line 25, in __call__
    request.tenant = Tenant.objects.get(domain=dev_tenant_domain)
                     ~~~~~~~~~~~~~~~~~~^^^^^^^^^^^^^^^^^^^^^^^^^^
  File "/home/pete/DjangoDev/django_bp_start/.venv/lib/python3.13/site-packages/django/db/models/manager.py", line 87, in manager_method
    return getattr(self.get_queryset(), name)(*args, **kwargs)
           ~~~~~~~~~~~~~~~~~~~~~~~~~~~~~~~~~~^^^^^^^^^^^^^^^^^
  File "/home/pete/DjangoDev/django_bp_start/.venv/lib/python3.13/site-packages/django/db/models/query.py", line 633, in get
    raise self.model.DoesNotExist(
        "%s matching query does not exist." % self.model._meta.object_name
    )
apps.tenants.models.Tenant.DoesNotExist: Tenant matching query does not exist.

During handling of the above exception, another exception occurred:

Traceback (most recent call last):
  File "/home/pete/DjangoDev/django_bp_start/.venv/lib/python3.13/site-packages/django/core/handlers/exception.py", line 55, in inner
    response = get_response(request)
  File "/home/pete/DjangoDev/django_bp_start/config/middleware.py", line 29, in __call__
    raise NotFound(detail="Tenant not found for this domain.")
rest_framework.exceptions.NotFound: Tenant not found for this domain.
ERROR 2025-10-03 12:21:37,143 basehttp 62951 140124270618304 "GET /favicon.ico HTTP/1.1" 500 82837
ERROR 2025-10-03 12:21:37,976 log 62951 140124270618304 Internal Server Error: /admin
Traceback (most recent call last):
  File "/home/pete/DjangoDev/django_bp_start/config/middleware.py", line 25, in __call__
    request.tenant = Tenant.objects.get(domain=dev_tenant_domain)
                     ~~~~~~~~~~~~~~~~~~^^^^^^^^^^^^^^^^^^^^^^^^^^
  File "/home/pete/DjangoDev/django_bp_start/.venv/lib/python3.13/site-packages/django/db/models/manager.py", line 87, in manager_method
    return getattr(self.get_queryset(), name)(*args, **kwargs)
           ~~~~~~~~~~~~~~~~~~~~~~~~~~~~~~~~~~^^^^^^^^^^^^^^^^^
  File "/home/pete/DjangoDev/django_bp_start/.venv/lib/python3.13/site-packages/django/db/models/query.py", line 633, in get
    raise self.model.DoesNotExist(
        "%s matching query does not exist." % self.model._meta.object_name
    )
apps.tenants.models.Tenant.DoesNotExist: Tenant matching query does not exist.

During handling of the above exception, another exception occurred:

Traceback (most recent call last):
  File "/home/pete/DjangoDev/django_bp_start/.venv/lib/python3.13/site-packages/django/core/handlers/exception.py", line 55, in inner
    response = get_response(request)
  File "/home/pete/DjangoDev/django_bp_start/config/middleware.py", line 29, in __call__
    raise NotFound(detail="Tenant not found for this domain.")
rest_framework.exceptions.NotFound: Tenant not found for this domain.
ERROR 2025-10-03 12:21:37,977 basehttp 62951 140124270618304 "GET /admin HTTP/1.1" 500 82894
ERROR 2025-10-03 12:21:38,033 log 62951 140124270618304 Internal Server Error: /favicon.ico
Traceback (most recent call last):
  File "/home/pete/DjangoDev/django_bp_start/config/middleware.py", line 25, in __call__
    request.tenant = Tenant.objects.get(domain=dev_tenant_domain)
                     ~~~~~~~~~~~~~~~~~~^^^^^^^^^^^^^^^^^^^^^^^^^^
  File "/home/pete/DjangoDev/django_bp_start/.venv/lib/python3.13/site-packages/django/db/models/manager.py", line 87, in manager_method
    return getattr(self.get_queryset(), name)(*args, **kwargs)
           ~~~~~~~~~~~~~~~~~~~~~~~~~~~~~~~~~~^^^^^^^^^^^^^^^^^
  File "/home/pete/DjangoDev/django_bp_start/.venv/lib/python3.13/site-packages/django/db/models/query.py", line 633, in get
    raise self.model.DoesNotExist(
        "%s matching query does not exist." % self.model._meta.object_name
    )
apps.tenants.models.Tenant.DoesNotExist: Tenant matching query does not exist.

During handling of the above exception, another exception occurred:

Traceback (most recent call last):
  File "/home/pete/DjangoDev/django_bp_start/.venv/lib/python3.13/site-packages/django/core/handlers/exception.py", line 55, in inner
    response = get_response(request)
  File "/home/pete/DjangoDev/django_bp_start/config/middleware.py", line 29, in __call__
    raise NotFound(detail="Tenant not found for this domain.")
rest_framework.exceptions.NotFound: Tenant not found for this domain.
ERROR 2025-10-03 12:21:38,034 basehttp 62951 140124270618304 "GET /favicon.ico HTTP/1.1" 500 82837
INFO 2025-10-03 12:23:52,746 autoreload 63081 140581618103744 Watching for file changes with StatReloader
INFO 2025-10-03 12:23:57,772 basehttp 63081 140581518960320 "GET /admin HTTP/1.1" 301 0
INFO 2025-10-03 12:23:57,810 basehttp 63081 140581518960320 "GET /admin/ HTTP/1.1" 302 0
INFO 2025-10-03 12:23:57,854 basehttp 63081 140581518960320 "GET /admin/login/?next=/admin/ HTTP/1.1" 200 4173
INFO 2025-10-03 12:23:57,906 basehttp 63081 140581518960320 "GET /static/admin/css/base.css HTTP/1.1" 200 22120
INFO 2025-10-03 12:23:57,907 basehttp 63081 140581501126336 "GET /static/admin/js/theme.js HTTP/1.1" 200 1653
INFO 2025-10-03 12:23:57,907 basehttp 63081 140581509519040 "GET /static/admin/css/dark_mode.css HTTP/1.1" 200 2808
INFO 2025-10-03 12:23:57,908 basehttp 63081 140581492733632 "GET /static/admin/css/nav_sidebar.css HTTP/1.1" 200 2810
INFO 2025-10-03 12:23:57,908 basehttp 63081 140581475948224 "GET /static/admin/css/login.css HTTP/1.1" 200 951
INFO 2025-10-03 12:23:57,908 basehttp 63081 140581484340928 "GET /static/admin/js/nav_sidebar.js HTTP/1.1" 200 3063
INFO 2025-10-03 12:23:57,909 basehttp 63081 140581509519040 "GET /static/admin/css/responsive.css HTTP/1.1" 200 16565
INFO 2025-10-03 12:24:08,471 basehttp 63081 140581518960320 "POST /admin/login/?next=/admin/ HTTP/1.1" 302 0
INFO 2025-10-03 12:24:08,515 basehttp 63081 140581518960320 "GET /admin/ HTTP/1.1" 200 8744
INFO 2025-10-03 12:24:08,569 basehttp 63081 140581509519040 "GET /static/admin/css/dashboard.css HTTP/1.1" 200 441
INFO 2025-10-03 12:24:08,573 basehttp 63081 140581509519040 "GET /static/admin/img/icon-addlink.svg HTTP/1.1" 200 331
INFO 2025-10-03 12:24:08,573 basehttp 63081 140581484340928 "GET /static/admin/img/icon-changelink.svg HTTP/1.1" 200 380
INFO 2025-10-03 12:24:13,683 basehttp 63081 140581518960320 "GET /admin/tenants/tenant/ HTTP/1.1" 200 11474
INFO 2025-10-03 12:24:13,696 basehttp 63081 140581518960320 "GET /static/admin/js/admin/RelatedObjectLookups.js HTTP/1.1" 200 9777
INFO 2025-10-03 12:24:13,697 basehttp 63081 140581509519040 "GET /static/admin/css/changelists.css HTTP/1.1" 200 6878
INFO 2025-10-03 12:24:13,697 basehttp 63081 140581475948224 "GET /static/admin/js/core.js HTTP/1.1" 200 6208
INFO 2025-10-03 12:24:13,697 basehttp 63081 140581501126336 "GET /static/admin/js/jquery.init.js HTTP/1.1" 200 347
INFO 2025-10-03 12:24:13,698 basehttp 63081 140581509519040 "GET /static/admin/js/actions.js HTTP/1.1" 200 8076
INFO 2025-10-03 12:24:13,699 basehttp 63081 140581475948224 "GET /static/admin/js/urlify.js HTTP/1.1" 200 7887
INFO 2025-10-03 12:24:13,699 basehttp 63081 140581501126336 "GET /static/admin/js/prepopulate.js HTTP/1.1" 200 1531
INFO 2025-10-03 12:24:13,700 basehttp 63081 140581492733632 "GET /static/admin/js/vendor/jquery/jquery.js HTTP/1.1" 200 285314
INFO 2025-10-03 12:24:13,701 basehttp 63081 140581492733632 "GET /static/admin/js/vendor/xregexp/xregexp.js HTTP/1.1" 200 325171
INFO 2025-10-03 12:24:13,729 basehttp 63081 140581484340928 "GET /admin/jsi18n/ HTTP/1.1" 200 3342
INFO 2025-10-03 12:24:13,730 basehttp 63081 140581484340928 "GET /static/admin/js/filters.js HTTP/1.1" 200 978
INFO 2025-10-03 12:24:13,743 basehttp 63081 140581509519040 "GET /static/admin/img/search.svg HTTP/1.1" 200 458
INFO 2025-10-03 12:24:13,763 basehttp 63081 140581492733632 "GET /static/admin/img/tooltag-add.svg HTTP/1.1" 200 331
INFO 2025-10-03 12:24:15,594 basehttp 63081 140581492733632 "GET /admin/tenants/tenant/1/change/ HTTP/1.1" 200 11353
INFO 2025-10-03 12:24:15,608 basehttp 63081 140581492733632 "GET /static/admin/css/forms.css HTTP/1.1" 200 8525
INFO 2025-10-03 12:24:15,609 basehttp 63081 140581475948224 "GET /static/admin/js/change_form.js HTTP/1.1" 200 606
INFO 2025-10-03 12:24:15,609 basehttp 63081 140581484340928 "GET /static/admin/js/prepopulate_init.js HTTP/1.1" 200 586
INFO 2025-10-03 12:24:15,643 basehttp 63081 140581509519040 "GET /admin/jsi18n/ HTTP/1.1" 200 3342
INFO 2025-10-03 12:24:15,649 basehttp 63081 140581492733632 "GET /static/admin/css/widgets.css HTTP/1.1" 200 11973
INFO 2025-10-03 12:24:26,265 basehttp 63081 140581492733632 "POST /admin/tenants/tenant/1/change/ HTTP/1.1" 302 0
INFO 2025-10-03 12:24:26,307 basehttp 63081 140581492733632 "GET /admin/tenants/tenant/ HTTP/1.1" 200 11686
INFO 2025-10-03 12:24:26,393 basehttp 63081 140581492733632 "GET /admin/jsi18n/ HTTP/1.1" 200 3342
INFO 2025-10-03 12:24:26,447 basehttp 63081 140581492733632 "GET /static/admin/img/icon-yes.svg HTTP/1.1" 200 436
INFO 2025-10-03 12:24:45,147 basehttp 63081 140581492733632 "GET /api HTTP/1.1" 301 0
INFO 2025-10-03 12:24:45,189 basehttp 63081 140581518960320 "GET /api/ HTTP/1.1" 200 5588
INFO 2025-10-03 12:24:45,202 basehttp 63081 140581484340928 "GET /static/rest_framework/css/prettify.css HTTP/1.1" 200 817
INFO 2025-10-03 12:24:45,203 basehttp 63081 140581475948224 "GET /static/rest_framework/css/bootstrap-tweaks.css HTTP/1.1" 200 3426
INFO 2025-10-03 12:24:45,203 basehttp 63081 140580990482112 "GET /static/rest_framework/js/ajax-form.js HTTP/1.1" 200 3796
INFO 2025-10-03 12:24:45,203 basehttp 63081 140581501126336 "GET /static/rest_framework/css/default.css HTTP/1.1" 200 1152
INFO 2025-10-03 12:24:45,205 basehttp 63081 140581475948224 "GET /static/rest_framework/js/csrf.js HTTP/1.1" 200 1793
INFO 2025-10-03 12:24:45,205 basehttp 63081 140581518960320 "GET /static/rest_framework/js/jquery-3.7.1.min.js HTTP/1.1" 200 87533
INFO 2025-10-03 12:24:45,205 basehttp 63081 140581509519040 "GET /static/rest_framework/css/bootstrap.min.css HTTP/1.1" 200 121457
INFO 2025-10-03 12:24:45,205 basehttp 63081 140581484340928 "GET /static/rest_framework/js/bootstrap.min.js HTTP/1.1" 200 39680
INFO 2025-10-03 12:24:45,206 basehttp 63081 140580990482112 "GET /static/rest_framework/js/prettify-min.js HTTP/1.1" 200 13632
INFO 2025-10-03 12:24:45,206 basehttp 63081 140581501126336 "GET /static/rest_framework/js/default.js HTTP/1.1" 200 1268
INFO 2025-10-03 12:24:45,244 basehttp 63081 140581518960320 "GET /static/rest_framework/js/load-ajax-form.js HTTP/1.1" 200 59
INFO 2025-10-03 12:24:45,253 basehttp 63081 140581509519040 "GET /static/rest_framework/img/grid.png HTTP/1.1" 200 1458
INFO 2025-10-03 12:24:47,878 basehttp 63081 140581509519040 "GET /api/users/ HTTP/1.1" 200 9964
INFO 2025-10-03 12:24:57,145 basehttp 63081 140581509519040 "GET /api/ HTTP/1.1" 200 5588
INFO 2025-10-03 12:24:59,276 basehttp 63081 140581509519040 "GET /api/tenants/ HTTP/1.1" 200 9105
INFO 2025-10-03 12:25:02,759 basehttp 63081 140581509519040 "GET /api/ HTTP/1.1" 200 5588
INFO 2025-10-03 12:25:04,788 basehttp 63081 140581509519040 "GET /api/products/ HTTP/1.1" 200 9243
INFO 2025-10-03 12:25:22,228 basehttp 63081 140581509519040 "GET /admin/ HTTP/1.1" 200 9136
INFO 2025-10-03 12:25:26,694 basehttp 63081 140581509519040 "GET /admin/users/customuser/ HTTP/1.1" 200 13626
INFO 2025-10-03 12:25:26,741 basehttp 63081 140581509519040 "GET /admin/jsi18n/ HTTP/1.1" 200 3342
INFO 2025-10-03 12:25:26,796 basehttp 63081 140581484340928 "GET /static/admin/img/sorting-icons.svg HTTP/1.1" 200 1097
INFO 2025-10-03 12:25:26,797 basehttp 63081 140580990482112 "GET /static/admin/img/icon-viewlink.svg HTTP/1.1" 200 581
WARNING 2025-10-03 12:25:26,831 log 63081 140581509519040 Not Found: /favicon.ico
INFO 2025-10-03 12:25:30,701 basehttp 63081 140581518960320 "GET /admin/users/customuser/1/change/ HTTP/1.1" 200 24611
INFO 2025-10-03 12:25:30,716 basehttp 63081 140580990482112 "GET /static/admin/js/calendar.js HTTP/1.1" 200 9141
INFO 2025-10-03 12:25:30,717 basehttp 63081 140581518960320 "GET /static/admin/js/SelectFilter2.js HTTP/1.1" 200 15845
INFO 2025-10-03 12:25:30,717 basehttp 63081 140581501126336 "GET /static/admin/js/SelectBox.js HTTP/1.1" 200 4530
INFO 2025-10-03 12:25:30,717 basehttp 63081 140581475948224 "GET /static/admin/js/admin/DateTimeShortcuts.js HTTP/1.1" 200 19319
INFO 2025-10-03 12:25:30,750 basehttp 63081 140581484340928 "GET /admin/jsi18n/ HTTP/1.1" 200 3342
INFO 2025-10-03 12:25:30,776 basehttp 63081 140581475948224 "GET /static/admin/img/selector-icons.svg HTTP/1.1" 200 3291
INFO 2025-10-03 12:25:30,777 basehttp 63081 140581475948224 "GET /static/admin/img/icon-calendar.svg HTTP/1.1" 200 1086
INFO 2025-10-03 12:25:30,777 basehttp 63081 140580990482112 "GET /static/admin/img/icon-clock.svg HTTP/1.1" 200 677
WARNING 2025-10-03 12:25:30,803 log 63081 140581484340928 Not Found: /favicon.ico
INFO 2025-10-03 12:27:12,926 autoreload 63081 140581618103744 /home/pete/DjangoDev/django_bp_start/apps/users/admin.py changed, reloading.
INFO 2025-10-03 12:27:13,235 autoreload 63272 140172641883584 Watching for file changes with StatReloader
INFO 2025-10-03 12:27:15,382 autoreload 63272 140172641883584 /home/pete/DjangoDev/django_bp_start/apps/users/admin.py changed, reloading.
INFO 2025-10-03 12:27:15,686 autoreload 63280 140330866398656 Watching for file changes with StatReloader
INFO 2025-10-03 12:27:21,268 basehttp 63280 140330767738560 "GET /admin/users/customuser/ HTTP/1.1" 200 13806
INFO 2025-10-03 12:27:21,280 basehttp 63280 140330767738560 "GET /static/admin/js/theme.js HTTP/1.1" 304 0
INFO 2025-10-03 12:27:21,281 basehttp 63280 140330758297280 "GET /static/admin/js/nav_sidebar.js HTTP/1.1" 304 0
INFO 2025-10-03 12:27:21,284 basehttp 63280 140330758297280 "GET /static/admin/css/dark_mode.css HTTP/1.1" 304 0
INFO 2025-10-03 12:27:21,284 basehttp 63280 140330531808960 "GET /static/admin/css/base.css HTTP/1.1" 304 0
INFO 2025-10-03 12:27:21,285 basehttp 63280 140330523416256 "GET /static/admin/css/nav_sidebar.css HTTP/1.1" 304 0
INFO 2025-10-03 12:27:21,286 basehttp 63280 140330531808960 "GET /static/admin/css/responsive.css HTTP/1.1" 304 0
INFO 2025-10-03 12:27:21,318 basehttp 63280 140330540201664 "GET /admin/jsi18n/ HTTP/1.1" 200 3342
WARNING 2025-10-03 12:27:21,378 log 63280 140330540201664 Not Found: /favicon.ico
INFO 2025-10-03 12:27:23,636 basehttp 63280 140330767738560 "GET /admin/users/customuser/1/change/ HTTP/1.1" 200 26361
INFO 2025-10-03 12:27:23,685 basehttp 63280 140330523416256 "GET /admin/jsi18n/ HTTP/1.1" 200 3342
WARNING 2025-10-03 12:27:23,742 log 63280 140330523416256 Not Found: /favicon.ico
INFO 2025-10-03 12:27:36,560 basehttp 63280 140330767738560 "POST /admin/users/customuser/1/change/ HTTP/1.1" 302 0
INFO 2025-10-03 12:27:36,606 basehttp 63280 140330767738560 "GET /admin/users/customuser/ HTTP/1.1" 200 14051
INFO 2025-10-03 12:27:36,662 basehttp 63280 140330767738560 "GET /static/admin/js/jquery.init.js HTTP/1.1" 304 0
INFO 2025-10-03 12:27:36,663 basehttp 63280 140330523416256 "GET /static/admin/js/core.js HTTP/1.1" 304 0
INFO 2025-10-03 12:27:36,663 basehttp 63280 140330540201664 "GET /static/admin/js/admin/RelatedObjectLookups.js HTTP/1.1" 304 0
INFO 2025-10-03 12:27:36,664 basehttp 63280 140330523416256 "GET /static/admin/js/urlify.js HTTP/1.1" 304 0
INFO 2025-10-03 12:27:36,664 basehttp 63280 140330531808960 "GET /static/admin/js/vendor/jquery/jquery.js HTTP/1.1" 304 0
INFO 2025-10-03 12:27:36,664 basehttp 63280 140330515023552 "GET /static/admin/js/actions.js HTTP/1.1" 304 0
INFO 2025-10-03 12:27:36,664 basehttp 63280 140330540201664 "GET /static/admin/js/vendor/xregexp/xregexp.js HTTP/1.1" 304 0
INFO 2025-10-03 12:27:36,665 basehttp 63280 140330531808960 "GET /static/admin/js/prepopulate.js HTTP/1.1" 304 0
INFO 2025-10-03 12:27:36,665 basehttp 63280 140330515023552 "GET /static/admin/js/filters.js HTTP/1.1" 304 0
INFO 2025-10-03 12:27:36,696 basehttp 63280 140330758297280 "GET /admin/jsi18n/ HTTP/1.1" 200 3342
INFO 2025-10-03 12:27:36,696 basehttp 63280 140330758297280 "GET /static/admin/css/changelists.css HTTP/1.1" 304 0
INFO 2025-10-03 12:27:36,747 basehttp 63280 140330758297280 "GET /static/admin/img/search.svg HTTP/1.1" 304 0
INFO 2025-10-03 12:27:47,253 basehttp 63280 140330767738560 "GET /api/ HTTP/1.1" 200 5594
WARNING 2025-10-03 12:27:47,317 log 63280 140330758297280 Not Found: /favicon.ico
INFO 2025-10-03 12:27:49,926 basehttp 63280 140330767738560 "GET /api/users/ HTTP/1.1" 200 9967
WARNING 2025-10-03 12:27:49,984 log 63280 140330523416256 Not Found: /favicon.ico
INFO 2025-10-03 12:29:45,345 autoreload 63280 140330866398656 /home/pete/DjangoDev/django_bp_start/apps/users/serializers.py changed, reloading.
INFO 2025-10-03 12:29:45,656 autoreload 63378 140035549050304 Watching for file changes with StatReloader
INFO 2025-10-03 12:29:47,803 autoreload 63378 140035549050304 /home/pete/DjangoDev/django_bp_start/apps/users/serializers.py changed, reloading.
INFO 2025-10-03 12:29:48,123 autoreload 63385 139651684369856 Watching for file changes with StatReloader
INFO 2025-10-03 12:29:51,748 autoreload 63420 140711450342848 Watching for file changes with StatReloader
INFO 2025-10-03 12:29:57,965 basehttp 63420 140711350494912 "GET /api/users/ HTTP/1.1" 200 9814
INFO 2025-10-03 12:29:57,977 basehttp 63420 140711341053632 "GET /static/rest_framework/css/bootstrap-tweaks.css HTTP/1.1" 200 3426
INFO 2025-10-03 12:29:57,981 basehttp 63420 140711114569408 "GET /static/rest_framework/css/default.css HTTP/1.1" 200 1152
INFO 2025-10-03 12:29:57,981 basehttp 63420 140711332660928 "GET /static/rest_framework/css/prettify.css HTTP/1.1" 200 817
INFO 2025-10-03 12:29:57,982 basehttp 63420 140711341053632 "GET /static/rest_framework/js/csrf.js HTTP/1.1" 200 1793
INFO 2025-10-03 12:29:57,983 basehttp 63420 140711350494912 "GET /static/rest_framework/css/bootstrap.min.css HTTP/1.1" 200 121457
INFO 2025-10-03 12:29:57,983 basehttp 63420 140711097784000 "GET /static/rest_framework/js/ajax-form.js HTTP/1.1" 200 3796
INFO 2025-10-03 12:29:57,983 basehttp 63420 140711332660928 "GET /static/rest_framework/js/prettify-min.js HTTP/1.1" 200 13632
INFO 2025-10-03 12:29:57,984 basehttp 63420 140711106176704 "GET /static/rest_framework/js/jquery-3.7.1.min.js HTTP/1.1" 200 87533
INFO 2025-10-03 12:29:57,985 basehttp 63420 140711114569408 "GET /static/rest_framework/js/bootstrap.min.js HTTP/1.1" 200 39680
INFO 2025-10-03 12:29:57,985 basehttp 63420 140711097784000 "GET /static/rest_framework/js/default.js HTTP/1.1" 200 1268
INFO 2025-10-03 12:29:57,985 basehttp 63420 140711106176704 "GET /static/rest_framework/js/load-ajax-form.js HTTP/1.1" 200 59
INFO 2025-10-03 12:29:58,031 basehttp 63420 140711106176704 "GET /static/rest_framework/img/grid.png HTTP/1.1" 200 1458
WARNING 2025-10-03 12:29:58,110 log 63420 140711106176704 Not Found: /favicon.ico
WARNING 2025-10-03 12:29:58,110 basehttp 63420 140711106176704 "GET /favicon.ico HTTP/1.1" 404 2508
